Workbook

Sheet IA(정보구조)
A1: Depth 1 | B1: Depth 2 | C1: Depth 3 | D1: 화면 ID | E1: 화면명 | F1: 플랫폼 | G1: 화면 URL/경로 | H1: 로그인 필요 | I1: 권한 | J1: 설명 | K1: 상태 | L1: 비고
A2: 인증 | B2: 로그인 | D2: SCR-001 | E2: 로그인 | F2: Web | G2: /login | H2: N | I2: 비회원 | J2: 이메일/비밀번호 로그인 화면. 지점 선택 포함 | K2: 개발완료 | L2: 로그인 유지 체크박스, toast 안내, 에러 자동 클리어 (2026-03-13)
A3: 대시보드 | B3: 메인 | D3: SCR-002 | E3: 대시보드 | F3: Web | G3: / | H3: Y | I3: 전체 | J3: 지점별 핵심 KPI 요약 대시보드 | K3: 개발완료 | L3: 실데이터 차트, soft delete 필터, 클릭 네비게이션 (2026-03-13)
A4: 회원관리 | B4: 회원 | D4: SCR-010 | E4: 회원 목록 | F4: Web | G4: /members | H4: Y | I4: 매니저 이상 | J4: 회원 검색/필터/목록 조회 | K4: 개발완료 | L4: 상태 변경 모달 개선, 서버사이드 페이지네이션/정렬 (2026-03-13)
A5: 회원관리 | B5: 회원 | D5: SCR-011 | E5: 회원 상세 | F5: Web | G5: /members/detail | H5: Y | I5: 매니저 이상 | J5: 회원 프로필, 이용권, 출석, 결제, 체성분, 메모 탭 | K5: 개발완료 | L5: Supabase 실데이터, 메모/목표 탭 (2026-03-13)
A6: 회원관리 | B6: 회원 | D6: SCR-012 | E6: 회원 등록 | F6: Web | G6: /members/new | H6: Y | I6: 매니저 이상 | J6: 신규 회원 등록 폼 | K6: 개발완료
A7: 회원관리 | B7: 회원 | D7: SCR-013 | E7: 회원 수정 | F7: Web | G7: /members/edit | H7: Y | I7: 매니저 이상 | J7: 기존 회원 정보 수정 폼 | K7: 개발완료
A8: 회원관리 | B8: 체성분 | D8: SCR-014 | E8: 체성분 분석 | F8: Web | G8: /body-composition | H8: Y | I8: FC 이상 | J8: 체성분 측정 기록 및 변화 추이 차트 | K8: 개발완료
A9: 출석/일정 | B9: 출석 | D9: SCR-020 | E9: 출석 기록 | F9: Web | G9: /attendance | H9: Y | I9: 스태프 이상 | J9: 회원 출석 현황 조회 (일별/주별/월별) | K9: 개발완료 | L9: 날짜 필터 DataTable 연동, 키보드 접근성 개선 (2026-03-13)
A10: 출석/일정 | B10: 일정 | D10: SCR-021 | E10: 일정 관리 | F10: Web | G10: /calendar | H10: Y | I10: 스태프 이상 | J10: PT/GX 일정 캘린더 뷰 | K10: 개발완료 | L10: FullCalendar 드래그앤드롭 리뉴얼 (2026-03-13)
A11: 매출/결제 | B11: 매출 | D11: SCR-030 | E11: 매출 조회 | F11: Web | G11: /sales | H11: Y | I11: 매니저 이상 | J11: 매출 현황 조회, 필터, 통계 요약 | K11: 개발완료
A12: 매출/결제 | B12: POS | D12: SCR-031 | E12: POS | F12: Web | G12: /pos | H12: Y | I12: 스태프 이상 | J12: POS 상품 선택 및 장바구니 | K12: 개발완료
A13: 매출/결제 | B13: POS | D13: SCR-032 | E13: POS 결제 | F13: Web | G13: /pos/payment | H13: Y | I13: 스태프 이상 | J13: 결제 수단 선택 및 결제 처리 | K13: 개발완료 | L13: window.confirm → ConfirmDialog 개선 (2026-03-13)
A14: 상품관리 | B14: 상품 | D14: SCR-040 | E14: 상품 목록 | F14: Web | G14: /products | H14: Y | I14: 매니저 이상 | J14: 이용권/PT/기타 상품 목록 | K14: 개발완료
A15: 상품관리 | B15: 상품 | D15: SCR-041 | E15: 상품 등록 | F15: Web | G15: /products/new | H15: Y | I15: 센터장 이상 | J15: 신규 상품 등록 폼 | K15: 개발완료
A16: 시설관리 | B16: 락커 | D16: SCR-050 | E16: 락커 현황 | F16: Web | G16: /locker | H16: Y | I16: 스태프 이상 | J16: 락커 구역별 배정 현황 (색상 그리드) | K16: 개발완료
A17: 시설관리 | B17: 락커 | D17: SCR-051 | E17: 락커 관리 | F17: Web | G17: /locker/management | H17: Y | I17: 매니저 이상 | J17: 락커 배정/해제/일괄 관리 | K17: 개발완료
A18: 시설관리 | B18: RFID | D18: SCR-052 | E18: RFID 관리 | F18: Web | G18: /rfid | H18: Y | I18: 매니저 이상 | J18: RFID 카드 등록/해제/이력 조회 | K18: 개발완료
A19: 시설관리 | B19: 룸 | D19: SCR-053 | E19: 룸 관리 | F19: Web | G19: /rooms | H19: Y | I19: 매니저 이상 | J19: GX룸/PT룸 관리 및 예약 설정 | K19: 개발완료
A20: 직원관리 | B20: 직원 | D20: SCR-060 | E20: 직원 목록 | F20: Web | G20: /staff | H20: Y | I20: 센터장 이상 | J20: 직원 검색/필터/목록 조회 | K20: 개발완료 | L20: 페이지네이션 동작 수정, 퇴사 ConfirmDialog (2026-03-13)
A21: 직원관리 | B21: 직원 | D21: SCR-061 | E21: 직원 등록 | F21: Web | G21: /staff/new | H21: Y | I21: 센터장 이상 | J21: 신규 직원 등록 폼 | K21: 개발완료
A22: 직원관리 | B22: 급여 | D22: SCR-062 | E22: 급여 현황 | F22: Web | G22: /payroll | H22: Y | I22: 센터장 이상 | J22: 월별 급여 현황 요약 | K22: 개발완료 | L22: 페이지네이션 동작 수정, 필터 시 페이지 리셋 (2026-03-13)
A23: 직원관리 | B23: 급여 | D23: SCR-063 | E23: 급여명세서 | F23: Web | G23: /payroll/statements | H23: Y | I23: 센터장 이상 | J23: 직원별 급여명세서 상세 | K23: 개발완료
A24: 메시지/마케팅 | B24: 메시지 | D24: SCR-070 | E24: 메시지 발송 | F24: Web | G24: /message | H24: Y | I24: 매니저 이상 | J24: SMS/카카오톡 메시지 발송 | K24: 개발완료
A25: 메시지/마케팅 | B25: 자동알림 | D25: SCR-071 | E25: 자동 알림 | F25: Web | G25: /message/auto-alarm | H25: Y | I25: 매니저 이상 | J25: 자동 알림 규칙 설정 (만료/생일 등) | K25: 개발완료
A26: 메시지/마케팅 | B26: 쿠폰 | D26: SCR-072 | E26: 쿠폰 관리 | F26: Web | G26: /message/coupon | H26: Y | I26: 매니저 이상 | J26: 쿠폰 생성/발급/이력 관리 | K26: 개발완료
A27: 메시지/마케팅 | B27: 마일리지 | D27: SCR-073 | E27: 마일리지 관리 | F27: Web | G27: /mileage | H27: Y | I27: 매니저 이상 | J27: 회원 마일리지 적립/사용 이력 | K27: 개발완료 | L27: 이력 탭 엑셀 다운로드 구현 (2026-03-13)
A28: 계약/구독 | B28: 계약 | D28: SCR-080 | E28: 계약 마법사 | F28: Web | G28: /contracts/new | H28: Y | I28: 매니저 이상 | J28: 단계별 계약 등록 위자드 | K28: 개발완료 | L28: 전자서명 (양방향) Canvas 구현 (2026-03-13)
A29: 계약/구독 | B29: 구독 | D29: SCR-081 | E29: 구독 관리 | F29: Web | G29: /subscription | H29: Y | I29: 센터장 이상 | J29: 정기 구독 상품 관리 | K29: 개발완료
A30: 설정 | B30: 설정 | D30: SCR-090 | E30: 설정 | F30: Web | G30: /settings | H30: Y | I30: 센터장 이상 | J30: 시스템 기본 설정 | K30: 개발완료
A31: 설정 | B31: 권한 | D31: SCR-091 | E31: 권한 설정 | F31: Web | G31: /settings/permissions | H31: Y | I31: 최고관리자 | J31: 역할별 메뉴/기능 권한 매트릭스 | K31: 개발완료
A32: 설정 | B32: 키오스크 | D32: SCR-092 | E32: 키오스크 설정 | F32: Web | G32: /settings/kiosk | H32: Y | I32: 센터장 이상 | J32: 키오스크 디스플레이/동작 설정 | K32: 개발완료
A33: 설정 | B33: IoT | D33: SCR-093 | E33: IoT 설정 | F33: Web | G33: /settings/iot | H33: Y | I33: 센터장 이상 | J33: 출입문/체성분 기기 연동 설정 | K33: 개발완료
A34: 설정 | B34: 지점 | D34: SCR-094 | E34: 지점 관리 | F34: Web | G34: /branches | H34: Y | I34: 최고관리자 | J34: 지점 CRUD 및 멀티테넌트 관리 | K34: 개발완료
A35: 출석/일정 | B35: GX 예약 | D35: SCR-022 | E35: GX 예약 관리 | F35: Web | G35: /schedule/gx-booking | H35: Y | I35: 매니저 이상 | J35: GX 프로그램 예약 오픈/관리. N시간 전 자동 오픈, 노쇼 페널티, 출석체크 연동 | K35: 신규 | L35: 레슨북/온핏 장점 반영
A36: 출석/일정 | B36: 좌석 예약 | D36: SCR-023 | E36: 좌석 예약 관리 | F36: Web | G36: /schedule/seat-booking | H36: Y | I36: 매니저 이상 | J36: 스피닝/GX 좌석 지정 예약. 바이크 번호별 예약/고장 관리 | K36: 신규 | L36: 판교점/용산점 요구사항
A37: 출석/일정 | B37: 레슨 관리 | D37: SCR-024 | E37: 레슨 기록/서명 | F37: Web | G37: /schedule/lesson | H37: Y | I37: 트레이너 이상 | J37: PT/골프 레슨 기록, 고객 서명 확인, 수업 진위 관리 | K37: 신규 | L37: 레슨북 장점 반영
A38: 시설관리 | B38: 타석 | D38: SCR-054 | E38: 골프 타석 관리 | F38: Web | G38: /facility/golf-bay | H38: Y | I38: 매니저 이상 | J38: 골프 타석 예약/대기/제어. 꼬리물기 예약, 시간관리 | K38: 신규 | L38: 대치점 브로제이 장점 반영
A39: 시설관리 | B39: 전원제어 | D39: SCR-055 | E39: 기기 전원 제어 | F39: Web | G39: /facility/power-control | H39: Y | I39: 매니저 이상 | J39: 키오스크/프로젝터 원격 전원 ON/OFF, 스케줄 자동 제어 | K39: 신규 | L39: 고척점/대치점 핵심 요구사항
A40: 시설관리 | B40: 수건/운동복 | D40: SCR-056 | E40: 수건/운동복 관리 | F40: Web | G40: /facility/towel | H40: Y | I40: 스태프 이상 | J40: 수건/운동복 발급 관리. QR/안면인식 연동, 수량 제한, 사용량 통계 | K40: 신규 | L40: 양천향교점 벤치마크
...

Sheet 사용자 스토리
A1: 스토리 ID | B1: 에픽 | C1: 사용자 유형 | D1: 사용자 스토리 | E1: 인수 조건 | F1: 화면 ID | G1: 우선순위 | H1: 사이즈 | I1: 담당자 | J1: 상태 | K1: [자동] 화면명 | L1: [자동] 기능 수 | M1: 비고
A2: US-001 | B2: 인증 | C2: 비회원 | D2: 비회원으로서 이메일/비밀번호로 로그인하여 시스템에 접근하고 싶다 | E2: 1) 올바른 이메일/비밀번호 입력 시 대시보드로 이동 2) 5회 실패 시 계정 잠금 3) 지점 선택 후 해당 지점 데이터만 표시 | F2: SCR-001 | G2: Critical | H2: S | I2: 개발자1 | J2: Done | K2: 로그인 | L2: 1
A3: US-002 | B3: 대시보드 | C3: 센터장 | D3: 센터장으로서 대시보드에서 지점 핵심 KPI를 한눈에 파악하고 싶다 | E3: 1) 총회원/활성/만료임박/만료 회원 수 카드 표시 2) 오늘 생일 회원 리스트 3) 미납 회원 리스트 4) 당월 매출 차트 | F3: SCR-002 | G3: Critical | H3: M | I3: 개발자1 | J3: Done | K3: 대시보드 | L3: 1
A4: US-003 | B4: 회원관리 | C4: 매니저 | D4: 매니저로서 회원을 검색/필터하여 원하는 회원을 빠르게 찾고 싶다 | E4: 1) 이름/연락처/회원번호로 검색 2) 상태/성별/담당자 필터 3) 엑셀 다운로드 가능 | F4: SCR-010 | G4: Critical | H4: M | I4: 개발자1 | J4: Done | K4: 회원 목록 | L4: 2
A5: US-004 | B5: 회원관리 | C5: 매니저 | D5: 매니저로서 신규 회원을 등록하고 싶다 | E5: 1) 필수 항목(이름/연락처/성별) 입력 2) 담당 FC 배정 3) 등록 완료 시 회원 상세로 이동 | F5: SCR-012 | G5: Critical | H5: M | I5: 개발자1 | J5: Done | K5: 회원 등록 | L5: 0
A6: US-005 | B6: 회원관리 | C6: 매니저 | D6: 매니저로서 회원 상세 정보와 이용 이력을 확인하고 싶다 | E6: 1) 프로필/이용권/출석/결제/체성분/메모 탭 구성 2) 이용권 만료일 강조 표시 3) 출석 히트맵 | F6: SCR-011 | G6: High | H6: L | I6: 개발자1 | J6: Done | K6: 회원 상세 | L6: 2
A7: US-006 | B7: 회원관리 | C7: 매니저 | D7: 매니저로서 회원 정보를 수정하고 싶다 | E7: 1) 기존 정보 프리필 2) 변경 이력 자동 기록 3) 담당자 변경 가능 | F7: SCR-013 | G7: High | H7: S | I7: 개발자1 | J7: Done | K7: 회원 수정 | L7: 0
A8: US-007 | B8: 회원관리 | C8: FC | D8: FC로서 회원의 체성분 측정 결과를 기록하고 변화 추이를 분석하고 싶다 | E8: 1) 체중/골격근/체지방률 등 입력 2) 측정일 기준 변화 차트 3) 목표 대비 달성률 표시 | F8: SCR-014 | G8: High | H8: M | I8: 개발자2 | J8: Done | K8: 체성분 분석 | L8: 1
A9: US-008 | B9: 출석관리 | C9: 스태프 | D9: 스태프로서 회원의 출석 현황을 조회하고 싶다 | E9: 1) 일별/주별/월별 출석 조회 2) 출석 유형(일반/PT/GX) 구분 3) 타지점 출석 표시 | F9: SCR-020 | G9: High | H9: M | I9: 개발자2 | J9: Done | K9: 출석 기록 | L9: 1
A10: US-009 | B10: 출석관리 | C10: 스태프 | D10: 스태프로서 PT/GX 일정을 캘린더로 관리하고 싶다 | E10: 1) 월/주/일 캘린더 뷰 2) 드래그앤드롭 일정 변경 3) 트레이너별 필터 | F10: SCR-021 | G10: High | H10: L | I10: 개발자2 | J10: Done | K10: 일정 관리 | L10: 1
A11: US-010 | B11: 매출관리 | C11: 매니저 | D11: 매니저로서 매출 현황을 조회하고 통계를 확인하고 싶다 | E11: 1) 기간별 매출 필터 2) 유형별(이용권/PT/상품) 분류 3) 총매출/현금/카드/마일리지 요약 4) 엑셀 다운로드 | F11: SCR-030 | G11: Critical | H11: L | I11: 개발자1 | J11: Done | K11: 매출 조회 | L11: 2
A12: US-011 | B12: 매출관리 | C12: 스태프 | D12: 스태프로서 POS에서 상품을 선택하고 결제를 처리하고 싶다 | E12: 1) 카테고리별 상품 그리드 2) 장바구니 담기/수량 변경 3) 현금/카드/마일리지 복합결제 4) 영수증 출력 | F12: SCR-031 | G12: Critical | H12: XL | I12: 개발자1 | J12: Done | K12: POS | L12: 0
A13: US-012 | B13: 상품관리 | C13: 매니저 | D13: 매니저로서 상품 목록을 조회하고 관리하고 싶다 | E13: 1) 카테고리별 필터 2) 키오스크 노출 여부 토글 3) 상품 상태(판매중/중지) 관리 | F13: SCR-040 | G13: High | H13: M | I13: 개발자2 | J13: Done | K13: 상품 목록 | L13: 2
... A31: US-030 | B31: 설정/권한 | C31: 최고관리자 | D31: 최고관리자로서 지점을 추가/관리하고 싶다 | E31: 1) 지점 CRUD 2) 지점별 독립 데이터 3) 지점 간 회원 이동 처리 | F31: SCR-094 | G31: Critical | H31: L | I31: 개발자1 | J31: Done | K31: 지점 관리 | L31: 0
A32: US-031 | B32: 출석관리 | C32: 매니저 | D32: 매니저로서 GX 수업 예약을 N시간 전 자동 오픈 설정하여 수작업을 줄이고 싶다 | E32: 1) 수업별 예약 오픈 시간(N시간 전) 설정 가능 2) 일괄 오픈(매주 특정 요일/시간) 설정 가능 3) 강사 변경 시 기간 지정 일괄 변경 가능 4) 예약 오픈 시 회원 앱 알림 발송 | F32: SCR-022 | G32: Critical | H32: L | J32: To Do | K32: GX 예약 관리 | L32: 3
A33: US-032 | B33: 출석관리 | C33: 매니저 | D33: 매니저로서 GX 출석을 QR/NFC로 자동 체크하여 노쇼를 정확히 파악하고 싶다 | E33: 1) QR/NFC 스캔으로 출석 자동 기록 2) 센터 입장 + 프로그램 예약 매칭 자동 출석 3) 노쇼 자동 감지 및 페널티 처리 4) 비예약자 참석 시 FC 알림 | F33: SCR-022 | G33: Critical | H33: L | J33: To Do | K33: GX 예약 관리 | L33: 3
A34: US-033 | B34: 출석관리 | C34: 회원 | D34: 회원으로서 스피닝 수업 예약 시 원하는 바이크 좌석을 선택하고 싶다 | E34: 1) 바이크 배치도에서 원하는 좌석 선택 가능 2) 고장 좌석 비활성화 표시(선택 불가) 3) 예약 순서에 따른 좌석 선택 우선권 | F34: SCR-023 | G34: High | H34: M | J34: To Do | K34: 좌석 예약 관리 | L34: 2
A35: US-034 | B35: 출석관리 | C35: 트레이너 | D35: 트레이너로서 레슨 완료 후 고객 서명을 받아 수업 진위를 증명하고 싶다 | E35: 1) 수업 내용 기록 + 고객 터치 서명 2) 서명 완료 시 수업 확정 3) 모바일에서도 서명 가능 4) 서명 이력 조회 가능 | F35: SCR-024 | G35: High | H35: M | J35: To Do | K35: 레슨 기록/서명 | L35: 2
A36: US-035 | B36: 시설관리 | C36: 센터장 | D36: 센터장으로서 30개 이상의 키오스크/프로젝터를 원격으로 일괄 ON/OFF하여 오픈/마감 시간을 절약하고 싶다 | E36: 1) 관리 PC에서 전체/개별 전원 ON/OFF 2) 오픈/마감 스케줄 자동 제어 설정 3) 기기 상태 실시간 모니터링 4) 미응답 기기 알림 | F36: SCR-055 | G36: Critical | H36: L | J36: To Do | K36: 기기 전원 제어 | L36: 1
A37: US-036 | B37: 시설관리 | C37: 매니저 | D37: 매니저로서 수건/운동복 발급을 자동화하여 과다 사용을 줄이고 세탁비를 관리하고 싶다 | E37: 1) 회원별 1일 발급 수량 제한 2) QR/안면인식 발급 기록 자동화 3) 월간 사용량 통계 + 세탁비 추정 4) 과다 발급 알림 | F37: SCR-056 | G37: High | H37: M | J37: To Do | K37: 수건/운동복 관리 | L37: 1
A38: US-037 | B38: 회원관리 | C38: FC | D38: FC로서 담당 회원이 센터에 방문하면 즉시 알림을 받아 재등록 상담 타이밍을 놓치지 않고 싶다 | E38: 1) 즐겨찾기 회원 입장 시 핸드폰 푸시 알림 2) 알림에 잔여일수/미납 여부 표시 3) 이용권 만료 임박 회원 자동 즐겨찾기 4) 방문 이력 기반 상담 포인트 제공 | F38: SCR-015 | G38: Critical | H38: M | J38: Done | K38: FC 즐겨찾기/알림 | L38: 1
A39: US-038 | B39: 상품관리 | C39: 매니저 | D39: 매니저로서 상품을 한 화면에서 요일별/시간별/횟수별/기간별 세팅을 완료하고 싶다 | E39: 1) 팝업 없이 한 화면에서 전체 속성 설정 2) 주중권/주말권 분기 설정 3) 횟수제/기간제/혼합 선택 4) 상품 클릭 시 구매 회원 바로 확인 | F39: SCR-041 | G39: Critical | H39: L | J39: To Do | K39: 상품 등록 | L39: 2
A40: US-039 | B40: 설정 | C40: 센터장 | D40: 센터장으로서 키오스크 타입(결제형/비결제형)을 지점별로 설정하고 싶다 | E40: 1) 타입A(입퇴장 전용)/타입B(결제 포함) 선택 2) 선택에 따라 키오스크 UI 자동 분기 3) 타입B 시 1일권 현장 결제 가능 | F40: SCR-095 | G40: High | H40: M | J40: Done | K40: 키오스크 타입 설정 | L40: 1
A41: US-040 | B41: 설정 | C41: 센터장 | D41: 센터장으로서 네트워크 장애 시에도 출입/라커 기본 기능이 동작하여 영업 중단을 방지하고 싶다 | E41: 1) 네트워크 끊김 시 자동 로컬 모드 전환 2) 출입/라커/출석 오프라인 동작 3) 네트워크 복구 시 자동 동기화 4) 오프라인 상태 표시 배너 | F41: SCR-096 | G41: Critical | H41: XL | J41: Done | K41: 오프라인 모드 설정 | L41: 1
A42: US-041 | B42: 시설관리 | C42: 매니저 | D42: 매니저로서 라커 자동 배정 시 상단/홀수 우선 배정 규칙을 적용하여 회원 불만을 줄이고 싶다 | E42: 1) 상단>하단, 홀수>짝수 우선 배정 2) 고장/점유 라커 자동 스킵 3) 마감 시 전체 라커 일괄 해제 4) 잔류물 체크리스트 제공 | F42: SCR-050 | G42: High | H42: S | J42: To Do | K42: 락커 현황 | L42: 3
A43: US-042 | B43: 매출관리 | C43: FC | D43: FC로서 최초 상담한 회원의 실적이 정확히 나에게 귀속되길 원한다 | E43: 1) 최초 상담자 자동 실적 귀속 2) 귀속 유효기간(N일) 설정 3) 계약 처리자와 실적 담당자 분리 가능 4) 상담 이력 자동 기록 | F43: SCR-030 | G43: High | H43: M | J43: To Do | K43: 매출 조회 | L43: 3
... A57: US-056 | B57: FC앱 | C57: FC | D57: FC로서 앱에서 상담 이력을 기록하고 실적 귀속 잔여일을 확인하고 싶다 | E57: 1) 상담 내용/결과 기록 2) 실적 귀속 잔여일 표시(D-N) 3) 상담 → 계약 전환율 확인 4) 타 FC 상담 이력 참조 | F57: SCR-F03 | G57: High | H57: M | J57: To Do | K57: FC 회원 상담 기록 | L57: 1

Sheet 화면설계서
A1: 화면 ID | B1: 화면명 | C1: 플랫폼 | D1: 화면 경로 | E1: 화면 설명 | F1: [자동] UI 요소 목록 | G1: 인터랙션 정의 | H1: Web 특이사항 | I1: App 특이사항 | J1: 진입 경로 | K1: 이동 가능 화면 | L1: 에러 화면 정의 | M1: 접근성 체크 | N1: 반응형 체크 (Web) | O1: 가로/세로 모드 (App) | P1: 디자인 시안 링크 | Q1: 상태 | R1: 담당자 | S1: [자동] 관련 기능 수 | T1: [자동] 관련 TC 수 | U1: [자동] 관련 API 수 | V1: 비고 | W1: [자동] UI 요소 수 | X1: 레이아웃 구조 | Y1: 섹션 순서 | Z1: 화면 유형 | AA1: 진입 트리거 | AB1: Loading 상태 | AC1: Empty 상태 | AD1: 반응형 상세 | AE1: 고정 요소
A2: SCR-001 | B2: 로그인 | C2: Web | D2: /login | E2: 이메일/비밀번호 기반 로그인 화면. 지점 선택 드롭다운 포함 | F2: UI-001, UI-002, UI-003, UI-004, UI-005 | G2: 비밀번호 마스킹 토글, Enter키 로그인, 지점 선택 시 로고 변경 | H2: JWT 토큰 기반 세션 관리 | J2: URL 직접 접근, 세션 만료 시 리다이렉트 | K2: SCR-002 (대시보드) | L2: 이메일 미입력: '이메일을 입력하세요' 비밀번호 오류: '비밀번호가 올바르지 않습니다' 계정 잠금: '5회 실패로 잠금됨' | M2: Tab 이동 순서, aria-label | N2: 1024px 이상 중앙 정렬 | Q2: 확정 | R2: 개발팀 | S2: 1 | T2: 6 | U2: 1 | V2: 비밀번호 변경 모달 AppHeader에 구현. 로그인 유지 체크박스 추가 (2026-03-13) | W2: 5 | X2: [배경] min-h-screen 중앙정렬 그라데이션 [메인카드] max-w-[400px] 흰색 박스 중앙 - 로고 영역 (S배지 + 텍스트) - 지점선택 드롭다운 (MapPin 아이콘) - 아이디 입력 (User 아이콘) - 비밀번호 입력 (Lock 아이콘) + Eye토글 - 로그인유지 체크 + 비밀번호찾기 링크 - 에러메시지 (조건부, 빨간배경) - 로그인 버튼 [푸터] 절대위치 하단 | Y2: 1:로고 → 2:지점선택 → 3:아이디 → 4:비밀번호 → 5:옵션(유지+찾기) → 6:에러메시지 → 7:로그인버튼 | Z2: page (전체화면, 사이드바 없음) | AA2: URL 직접접근 / 세션만료 시 리다이렉트 / 로그아웃 후 | AB2: 지점목록: Loader2 스핀 아이콘 로그인 버튼: Loader2 스핀 + '로그인 중...' 텍스트 지점 로딩 중 드롭다운 비활성 | AC2: 지점 목록 없음: 드롭다운 '지점 없음' 표시 에러: 빨간 배경 박스에 에러 메시지 | AD2: ≥1024px: 중앙정렬 카드 <1024px: 카드 max-w-[400px] 유지, padding 축소 모바일: gap-sm, p-md | AE2: 없음 (단일 스크롤 없는 화면)
A3: SCR-002 | B3: 대시보드 | C3: Web | D3: / | E3: 지점별 핵심 KPI 대시보드. 회원/매출/출석 통계 카드 + 알림 리스트 | F3: UI-006, UI-007, UI-008, UI-009, UI-010, UI-011, UI-012, UI-013 | G3: 통계 카드 클릭 시 상세 이동, 차트 호버 툴팁, 기간 필터 | H3: 반응형 그리드 (2열→1열) | J3: SCR-001 (로그인 후) | K3: SCR-010, SCR-030, SCR-020 | L3: 데이터 로딩 실패: '데이터를 불러올 수 없습니다' + 재시도 버튼 | M3: 차트 alt-text | N3: 1280px 이상 4열 카드 | Q3: 확정 | R3: 개발팀 | S3: 1 | T3: 3 | U3: 5 | V3: Supabase 실데이터 차트 연동. 통계 카드 클릭→상세 이동 (2026-03-13) | W3: 8 | X3: [공지배너] 닫기 가능, 아이콘+텍스트+버튼 (조건부) [헤더] 제목/설명 + 새로고침 + 회원등록 버튼 [섹션1: 통계카드] 6개 StatCard 그리드 [섹션2: 운영현황] 기간필터(오늘/이번주/이번달/분기) + 3개 차트(회원분포 원형/주간출석 라인/매출추이 막대) [섹션3: 리스트] 4개 DataTable 카드 (생일자/미수금/홀딩/만료임박) 2x2 그리드 [섹션4: 프로모션] 2개 배너 카드 | Y3: 1:공지배너 → 2:헤더 → 3:통계카드6개 → 4:운영현황차트3개 → 5:리스트카드4개 → 6:프로모션배너2개 | Z3: page | AA3: 로그인 성공 후 자동이동 / GNB '대시보드' 클릭 | AB3: 통계카드: 숫자 부분 스켈레톤 차트: 로딩 스핀 표시 리스트: 3줄 스켈레톤 행 새로고침: RefreshCw 아이콘 회전(animate-spin) | AC3: 통계카드: 0 표시 생일자: '오늘 생일인 회원이 없습니다' 미수금: '미수금 회원이 없습니다' 홀딩: '홀딩 중인 회원이 없습니다' 만료임박: '만료 임박 회원이 없습니다' | AD3: ≥1280px(xl): 카드6열 + 차트3열 + 리스트2열 + 프로모션2열 768~1279px(md): 카드3열 + 차트2열 + 리스트1열 + 프로모션1열 <768px: 카드2열 + 차트1열 + 리스트1열 + 프로모션1열 | AE3: GNB 상단 고정 사이드바 좌측 고정
A4: SCR-010 | B4: 회원 목록 | C4: Web | D4: /members | E4: 회원 검색, 필터, 페이지네이션이 포함된 목록 화면 | F4: UI-014, UI-015, UI-016, UI-017, UI-018, UI-019, UI-020, UI-021 | G4: 실시간 검색, 필터 조합, 정렬, 페이지네이션, 엑셀 다운로드 | H4: 테이블 가로스크롤 (좁은 화면) | J4: GNB 메뉴, SCR-002 바로가기 | K4: SCR-011, SCR-012 | L4: 검색 결과 없음: '조건에 맞는 회원이 없습니다' 로딩 실패: 스켈레톤 + 재시도 | M4: 테이블 aria-label, 스크린리더 페이지 안내 | N4: 테이블 반응형 스크롤 | Q4: 확정 | R4: 개발팀 | S4: 2 | T4: 4 | U4: 2 | V4: window.prompt→상태 선택 모달 전환. DataTable 키보드 접근성 (2026-03-13) | W4: 8 | X4: [헤더] 제목/설명 + 엑셀다운로드 + 회원추가 버튼 [섹션1: 통계카드] 4개 StatCard [섹션2: 메인탭] TabNav 6개(회원/회원권/수강권/락커/운동복/상품별) [섹션3: 테이블영역] 흰색박스 - 상태필터탭 6개(전체/활성/만료/미등록/홀딩/정지) - SearchFilter(검색+5개필터) - 벌크액션바 (선택 시 조건부) - DataTable (8컬럼, 선택/정렬/페이지네이션) | Y4: 1:헤더 → 2:통계카드4개 → 3:메인탭 → 4:상태필터 → 5:검색/필터 → 6:벌크액션 → 7:테이블 | Z4: page | AA4: GNB '회원 목록' 클릭 / 대시보드 통계카드 클릭 | AB4: 통계카드: 숫자 스켈레톤 테이블: 행 스켈레톤 (5줄) 검색: 300ms debounce 후 조회 | AC4: 통계카드: 0 표시 검색결과 없음: '조건에 맞는 회원이 없습니다' EmptyState 필터 초기화 안내 | AD4: ≥1024px(lg): 통계카드4열 768~1023px(md): 통계카드2열 <768px: 통계카드1열 테이블: 가로스크롤 | AE4: GNB 상단고정 벌크액션바: 선택 시 테이블 상단 고정
A5: SCR-011 | B5: 회원 상세 | C5: Web | D5: /members/detail | E5: 회원 프로필 + 탭(이용권/출석/결제/체성분/메모) 구성 | F5: UI-022, UI-023, UI-024, UI-025, UI-026, UI-027 | G5: 탭 전환, 이용권 만료일 강조, 출석 히트맵, 결제 내역 페이지네이션 | H5: 탭 URL 파라미터 유지 | J5: SCR-010 회원 클릭 | K5: SCR-013, SCR-014, SCR-010 | L5: 회원 미존재: 404 페이지 데이터 로딩 실패: 탭별 에러 표시 | M5: 탭 키보드 네비게이션 | N5: 탭 세로 배치 (좁은 화면) | Q5: 확정 | R5: 개발팀 | S5: 2 | T5: 1 | U5: 2 | W5: 6 | X5: [헤더] 뒤로가기 + 회원 프로필카드(사진/이름/상태/기본정보) [액션바] 수정/삭제/메시지 등 버튼 [탭영역] TabNav 7개(기본정보/계약현황/출석/체성분/결제/커뮤니케이션/기타) [탭콘텐츠] 탭별 상세정보 (lazy 로드) | Y5: 1:프로필카드 → 2:액션버튼 → 3:탭네비 → 4:탭콘텐츠 | Z5: page | AA5: SCR-010 회원명 클릭 / 다른 페이지에서 moveToPage(985, {id}) | AB5: 프로필: 스켈레톤 카드 각 탭: 개별 로딩 스피너 탭 전환 시 lazy load | AC5: 회원 미존재: 404 페이지 데이터 없는 탭: 탭별 개별 empty 메시지 이용권 없음: '등록된 이용권이 없습니다' | AD5: ≥1280px: 프로필+탭 풀너비 <768px: 탭 세로배치, 프로필 축소 탭 URL 파라미터 유지 | AE5: GNB 상단고정 탭네비 스크롤 시 sticky
A6: SCR-012 | B6: 회원 등록 | C6: Web | D6: /members/new | E6: 신규 회원 등록 폼. 필수/선택 항목 구분 | F6: UI-028, UI-029, UI-030, UI-031, UI-032, UI-033, UI-034, UI-035, UI-036, UI-037 | G6: 실시간 유효성 검사, 연락처 자동 포맷, 주소 검색 API 연동 | H6: 폼 상태 유지 (뒤로가기 시) | J6: SCR-010 '회원등록' 버튼 | K6: SCR-011 (등록 완료 후) | L6: 필수 항목 미입력: 필드 하단 에러 메시지 중복 연락처: '이미 등록된 연락처입니다' 서버 오류: 토스트 알림 | M6: 필수 항목 aria-required | N6: 폼 1열 배치 | Q6: 확정 | R6: 개발팀 | S6: 0 | T6: 4 | U6: 1 | W6: 10 | X6: [헤더] 제목(등록/수정모드) + 초기화/취소 버튼 [스텝네비] TabNav 2단계 (필수정보/추가정보) [Step1: 필수정보] - 프로필이미지 드래그영역 - FormSection '기본 인적사항' 2열 (이름/성별/생년월일/연락처/회원구분) - FormSection '관리 정보' 2열 (담당FC/트레이너/방문경로/운동목적) [Step2: 추가정보] - FormSection '추가 연락' 2열 (별칭/이메일/주소검색/회사명/출석번호) - FormSection '기타 설정' (광고수신/메모 textarea 500자) [하단] 이전/다음(또는 저장) 버튼 고정 | Y6: 1:헤더 → 2:스텝표시 → 3:폼섹션들 → 4:하단버튼 | Z6: page (2-step wizard) | AA6: SCR-010 '회원등록' 버튼 클릭 | AB6: 저장 버튼: Loader2 스핀 + '저장 중...' | AC6: 담당FC/트레이너 목록 없음: '등록된 직원이 없습니다' 주소검색 결과 없음: '검색 결과가 없습니다' | AD6: ≥768px(md): FormSection 2열 <768px: FormSection 1열 하단 버튼: 모바일 전체너비 | AE6: 하단 액션버튼 고정
A7: SCR-013 | B7: 회원 수정 | C7: Web | D7: /members/edit | E7: 기존 회원 정보 수정 폼. 기존 데이터 프리필 | F7: UI-119, UI-120 | G7: 변경사항 비교 표시, 저장 전 확인 모달 | H7: 변경 이력 자동 기록 | J7: SCR-011 '수정' 버튼 | K7: SCR-011 (저장 후) | L7: 변경 없이 저장: '변경된 내용이 없습니다' 서버 오류: 토스트 알림 | M7: 폼 접근성 동일 | N7: 폼 1열 배치 | Q7: 확정 | R7: 개발팀 | S7: 0 | T7: 1 | U7: 1 | W7: 2 | X7: [헤더] 제목 + 취소/저장 버튼 [FormSection '기본 정보'] 이름/연락처/성별/생년월일/가입일/담당직원 [FormSection '이용권 정보'] 기존 이용권 리스트 + 새 이용권 추가 버튼 [FormSection '상세 정보'] 주소/유입경로/운동목적/메모 [취소확인 다이얼로그] | Y7: 1:헤더 → 2:기본정보 → 3:이용권정보 → 4:상세정보 | Z7: page | AA7: SCR-011 '수정' 버튼 클릭 | AB7: 기존 데이터 프리필 중: 전체 스켈레톤 저장: 버튼 로딩 | AC7: 이용권 없음: '등록된 이용권이 없습니다' + 안내메시지 | AD7: 폼 1열 배치 (max-width 제한) | AE7: 없음
A8: SCR-014 | B8: 체성분 분석 | C8: Web | D8: /body-composition | E8: 회원별 체성분 측정 기록 입력 및 변화 추이 차트 | F8: UI-121, UI-122 | G8: 측정값 입력 폼, 날짜별 라인 차트, 목표 대비 게이지 | H8: 차트 라이브러리 (Recharts) | J8: SCR-011 '체성분' 탭 | K8: SCR-011 | L8: 측정 데이터 없음: '아직 측정 기록이 없습니다' 입력 범위 초과: 경고 토스트 | M8: 차트 alt-text, 데이터 테이블 대체 | N8: 차트 반응형 | Q8: 확정 | R8: 개발팀 | S8: 1 | T8: 0 | U8: 0 | W8: 2 | X8: [뒤로가기 버튼] [헤더] 회원명+최근측정일 + 전체추출/새측정추가 버튼 [섹션1: 통계카드] 3개 (현재체중/골격근량/체지방률) [섹션2: 탭] 기록목록/변화그래프/목표관리 - 기록목록: DataTable - 변화그래프: SVG LineChart + 메트릭토글 + 호버툴팁 + 변화요약 - 목표관리: GoalGauge 2개 (목표체중/목표체지방) [섹션3: 분석] 2칸 그리드 - 비만분석 (BMI/체지방률 AnalysisRow 범위바) - 에너지/대사 (BMR/제지방량/권장열량) [모달] 측정추가(날짜/체중/골격근/체지방+BMI자동) / 목표수정 | Y8: 1:뒤로가기 → 2:헤더 → 3:통계카드3개 → 4:탭(기록/그래프/목표) → 5:분석그리드 | Z8: page | AA8: SCR-011 '체성분' 탭 클릭 | AB8: 데이터 로딩: 통계카드 스켈레톤 + 차트 로딩스핀 | AC8: 측정데이터 없음: '아직 측정 기록이 없습니다' 목표 미설정: '목표를 설정해주세요' | AD8: ≥768px: 분석 2열 <768px: 분석 1열 차트 반응형 (SVG viewBox) | AE8: GNB 상단고정
A9: SCR-020 | B9: 출석 기록 | C9: Web | D9: /attendance | E9: 회원 출석 현황 조회. 일별/주별/월별 뷰 전환 | F9: UI-123, UI-124 | G9: 날짜 필터, 출석 유형 필터, 타지점 출석 표시 | H9: 캘린더 컴포넌트 | J9: GNB 메뉴 | K9: SCR-011 (회원 클릭) | L9: 데이터 없음: '해당 기간 출석 기록이 없습니다' | M9: 날짜 선택 키보드 접근 | N9: 테이블 반응형 | Q9: 확정 | R9: 개발팀 | S9: 1 | T9: 1 | U9: 2 | V9: 날짜 필터 DataTable 적용. 실시간 출석 통계 (2026-03-13) | W9: 2 | X9: [헤더] 제목/설명 + 날짜네비(◀ 날짜 ▶) + 뷰전환(일/주/월) + 실시간토글 + 수동출석버튼 [일별뷰] - 통계카드 4개 (오늘출석/PT/GX/신규방문) - 출석유형 범례 (색상코딩) - SearchFilter + DataTable (10컬럼) [주별뷰] 통계카드3개 + WeeklyView(7일 막대차트) [월별뷰] 통계카드3개 + MonthlyView(28일 히트맵) [실시간팝업] 우측하단 슬라이드인, AI음성메시지 (자동사라짐) [모달] 수동출석(회원검색+유형4버튼+시간) | Y9: 1:헤더+날짜+뷰전환 → 2:통계카드 → 3:범례 → 4:검색/필터 → 5:테이블/차트 | Z9: page | AA9: GNB '출석 관리' 클릭 / 대시보드 출석카드 클릭 | AB9: 통계카드: 숫자 스켈레톤 테이블: 행 스켈레톤 뷰 전환: 데이터 재조회 로딩 | AC9: 출석기록 없음: '해당 기간 출석 기록이 없습니다' 검색결과 없음: 빈 테이블 | AD9: ≥768px(md): 통계카드4열 <768px: 통계카드2열 히트맵/차트: 가로스크롤 | AE9: GNB 상단고정 날짜네비+뷰전환: 헤더영역 고정
A10: SCR-021 | B10: 일정 관리 | C10: Web | D10: /calendar | E10: PT/GX 일정 캘린더. 월/주/일 뷰 전환 | F10: UI-125, UI-126 | G10: 드래그앤드롭 일정 이동, 클릭 상세 모달, 트레이너 필터 | H10: FullCalendar 라이브러리 | J10: GNB 메뉴 | K10: SCR-011 (회원 연결) | L10: 일정 충돌: '해당 시간에 이미 예약이 있습니다' 과거 일정 수정 불가 | M10: 캘린더 키보드 네비게이션 | N10: 뷰 자동 전환 (주→일) | Q10: 확정 | R10: 개발팀 | S10: 1 | T10: 1 | U10: 0 | V10: FullCalendar 라이브러리 전환. 드래그앤드롭 일정 이동/리사이즈 (2026-03-13) | W10: 2 | X10: [헤더] 제목/설명 + 스케줄일괄변경 + 수업등록 버튼 [탭] 5개 (일정표/수업관리/횟수관리/페널티/유효수업) [일정표탭] - 컨트롤바: 뷰전환(월/주/일) + 날짜네비 + 트레이너필터 - 범례 (강사+수업유형 색상) - MonthView(7x5 그리드, 셀당3이벤트+'+N개') - WeekView(8x14 타임테이블) - DayView(시간x슬롯) [수업관리탭] SearchFilter + DataTable [페널티탭] 필터 + DataTable [유효수업탭] DataTable [모달] EventDetail(수업상세, 수정/삭제) / EventAdd(등록/수정폼, 반복설정) | Y10: 1:헤더 → 2:탭 → 3:컨트롤바 → 4:범례 → 5:캘린더뷰(월/주/일) | Z10: page | AA10: GNB '수업/캘린더' 클릭 | AB10: 캘린더: 이벤트 스켈레톤 수업관리: 테이블 스켈레톤 | AC10: 이벤트 없음: 빈 캘린더 셀 수업 없음: '등록된 수업이 없습니다' 횟수관리: '준비 중' 안내 | AD10: ≥1280px: 캘린더 풀너비 <768px: 주→일뷰 자동전환 권장 타임테이블: 가로스크롤 | AE10: GNB 상단고정 컨트롤바 sticky
A11: SCR-030 | B11: 매출 조회 | C11: Web | D11: /sales | E11: 매출 현황 조회. 기간/유형/상태 필터 + 통계 요약 카드 | F11: UI-038, UI-039, UI-040, UI-041, UI-042, UI-043, UI-044 | G11: 날짜 범위 선택, 유형 필터, 상태 필터, 통계 카드 갱신, 엑셀 다운로드 | H11: 금액 포맷 (천단위 콤마) | J11: GNB 메뉴, SCR-002 매출 카드 | K11: SCR-031 (POS 이동) | L11: 데이터 없음: '해당 기간 매출이 없습니다' 다운로드 실패: 재시도 안내 | M11: 금액 스크린리더 읽기 | N11: 통계 카드 2열→1열 | Q11: 확정 | R11: 개발팀 | S11: 2 | T11: 2 | U11: 2 | W11: 7 | X11: [헤더] 제목/설명 + 신규결제(POS) + 엑셀다운로드 버튼 [섹션1: 요약카드] 4개 (순매출/카드/현금/미수금) [섹션2: 필터] 기간프리셋(오늘/이번주/이번달) + SearchFilter(날짜범위/유형/상태) [섹션3: 탭+테이블] TabNav 7개(매출내역/기간별/상품별/결제수단별/담당자별/환불/미납) + DataTable 13컬럼 [섹션4: 하단요약바] 총/순/현금/카드/마일리지/환불/미납 합계 | Y11: 1:헤더 → 2:요약카드4개 → 3:기간프리셋+필터 → 4:탭7개 → 5:테이블 → 6:하단합계바 | Z11: page | AA11: GNB '매출 현황' 클릭 / 대시보드 매출카드 클릭 | AB11: 요약카드: 숫자 스켈레톤 테이블: 행 스켈레톤 기간변경: 카드+테이블 동시 갱신 | AC11: 매출 없음: '해당 기간 매출이 없습니다' 다운로드 실패: 재시도 안내 toast | AD11: ≥768px(md): 요약카드4열 <768px: 요약카드2열 하단합계: flex-wrap 테이블: 가로스크롤 | AE11: GNB 상단고정 하단합계바 sticky bottom
A12: SCR-031 | B12: POS | C12: Web | D12: /pos | E12: POS 상품 선택 화면. 카테고리 탭 + 상품 그리드 + 장바구니 | F12: UI-045, UI-046, UI-047, UI-048 | G12: 카테고리 탭 전환, 상품 클릭 시 장바구니 추가, 수량 조절, 삭제 | H12: 2컬럼 레이아웃 (상품 | 장바구니) | J12: GNB 메뉴, SCR-030 | K12: SCR-032 (결제 진행) | L12: 장바구니 비어있음: '상품을 선택해주세요' 재고 없음: 상품 비활성화 | M12: 상품 그리드 키보드 선택 | N12: 장바구니 하단 고정 | Q12: 확정 | R12: 개발팀 | S12: 0 | T12: 1 | U12: 1 | W12: 4 | X12: [헤더] 제목/설명 + 상품등록 버튼 [2열 레이아웃] - [좌측: 상품그리드] - 카테고리탭 4개(이용권/PT/GX/기타) + 검색 - ProductCard 그리드 (재고배지/상품명/기간·횟수/현금가·카드가/호버+버튼) - [우측: 장바구니 사이드바 360px 고정] - 헤더(카운트, 전체삭제) - 아이템목록(상품명/수량−+/가격타입토글/소계) - 하단(총합 + 결제하기버튼) | Y12: 1:헤더 → 2좌:카테고리탭+검색 → 3좌:상품그리드 → 2우:장바구니헤더 → 3우:아이템목록 → 4우:합계+결제 | Z12: page (2-column layout) | AA12: GNB 'POS 결제' 클릭 / SCR-030 '신규 결제' 버튼 | AB12: 상품목록: 카드 스켈레톤 그리드 장바구니: 빈 상태 | AC12: 상품 없음: '등록된 상품이 없습니다' 장바구니 비어있음: ShoppingCart 아이콘 + '상품을 선택해주세요' 검색결과 없음: '검색 결과가 없습니다' | AD12: ≥1024px(lg): 2열(상품+장바구니) <1024px: 1열(상품→장바구니 순서) 상품그리드: xl:4열→md:3열→2열 장바구니: 모바일 전체너비 | AE12: 장바구니 사이드바: lg에서 우측 고정 모바일: 하단 고정 없음
A13: SCR-032 | B13: POS 결제 | C13: Web | D13: /pos/payment | E13: 결제 수단 선택 및 결제 처리. 복합결제 지원 | F13: UI-049, UI-050, UI-051, UI-052 | G13: 결제수단 선택, 금액 입력, 마일리지 사용, 결제 확인 모달 | H13: 결제 API 연동 | J13: SCR-031 '결제' 버튼 | K13: SCR-030 (결제 완료 후) | L13: 결제 실패: '결제에 실패했습니다. 다시 시도해주세요' 잔액 부족: 안내 메시지 | M13: 금액 입력 접근성 | N13: 모달 팝업 | Q13: 확정 | R13: 개발팀 | S13: 1 | T13: 3 | U13: 1 | V13: window.confirm→ConfirmDialog 컴포넌트 전환 (2026-03-13) | W13: 4 | X13: [헤더] 제목 + 초기화 버튼 [2열 레이아웃] - [좌측: 결제요약] - 주문 상품 리스트 (StatusBadge 카테고리) - 회원검색 (SearchFilter, 드롭다운) - 선택된 회원 정보 카드 - [우측: 결제수단 380px] - 4개 결제수단 버튼 (카드/현금/마일리지/복합) - 복합결제 금액분배 입력 (조건부) - 마일리지 잔액 안내 (조건부) - 결제확인 버튼 [결제완료화면] 전체페이지 교체 (체크아이콘+요약+계속판매버튼) [모달] 결제확인 (주문요약표시) | Y13: 1:헤더 → 2좌:주문리스트 → 3좌:회원검색 → 2우:결제수단4버튼 → 3우:금액입력 → 4우:결제버튼 | Z13: page (2-column layout) → 결제완료 시 전체 교체 | AA13: SCR-031 '결제하기' 버튼 클릭 | AB13: 회원검색: 드롭다운 로딩 결제처리: 버튼 로딩스핀 | AC13: 장바구니 비어있음: '상품을 먼저 선택해주세요' 안내 회원 미선택: 비회원 결제 가능 표시 | AD13: ≥1024px(lg): 2열(요약+결제) <1024px: 1열 우측패널: lg에서 w-[380px] 고정 | AE13: 없음
A14: SCR-040 | B14: 상품 목록 | C14: Web | D14: /products | E14: 이용권/PT/기타 상품 목록. 카테고리 필터 | F14: UI-082, UI-083, UI-084 | G14: 카테고리 필터, 상태 토글, 정렬 | H14: 테이블 레이아웃 | J14: GNB 메뉴 | K14: SCR-041 (등록), SCR-040 (수정 모달) | L14: 상품 없음: '등록된 상품이 없습니다' | M14: 테이블 접근성 | N14: 테이블 반응형 | Q14: 확정 | R14: 개발팀 | S14: 2 | T14: 3 | U14: 1 | W14: 3 | X14: [헤더] 제목/설명 + 상품등록 버튼 [섹션1: 통계카드] 4개 (전체/활성/비활성/카테고리수) [섹션2: 탭] 5개(전체/이용권/PT/GX/기타) + 개수표시 [섹션3: 검색] SearchFilter (상품명) [섹션4: DataTable] 7컬럼 (카테고리/상품명/가격/이용기간/세션/상태/액션) - 정렬: name,price,category (ArrowUp/Down/UpDown 아이콘) - 액션: 수정/삭제 버튼 [다이얼로그] 삭제확인 (danger) | Y14: 1:헤더 → 2:통계카드4개 → 3:탭5개 → 4:검색 → 5:테이블 | Z14: page | AA14: GNB '상품 관리' 클릭 | AB14: 통계카드: 숫자 스켈레톤 테이블: 행 스켈레톤 | AC14: 상품 없음: '등록된 상품이 없습니다' | AD14: ≥1024px(lg): 통계카드4열 <768px: 통계카드1열 테이블: 가로스크롤 | AE14: GNB 상단고정
A15: SCR-041 | B15: 상품 등록 | C15: Web | D15: /products/new | E15: 신규 상품 등록 폼. 카테고리/이름/가격/기간 설정 | F15: UI-085, UI-086, UI-087, UI-088 | G15: 카테고리 선택 시 하위 필드 변경, 가격 입력 포맷 | H15: 폼 유효성 검사 | J15: SCR-040 '등록' 버튼 | K15: SCR-040 (저장 후) | L15: 필수 미입력: 필드별 에러 중복 상품명: 경고 | M15: 폼 접근성 | N15: 폼 1열 | Q15: 확정 | R15: 개발팀 | S15: 2 | T15: 1 | U15: 1 | W15: 4 | X15: [초기: 유형선택화면] - 중앙정렬 텍스트 - 4개 유형카드 그리드 (이용권/PT/GX/기타) - 취소 링크 [메인폼] - [헤더] 동적 제목 + 액션 - [FormSection1: 기본정보 2열] 카테고리/상품명(중복체크)/현금가(콤마)/카드가/설명(2열span)/태그 - [FormSection2: 이용기간/횟수 2열] 이용기간/횟수(PT·GX만)/요일안내(GX만) - [FormSection3: 추가설정 접기가능] 홀딩설정(토글+세부)/이용시간(범위추가삭제)/판매노출(토글2개) - [하단고정바] 상태배지+카테고리 + 취소/등록버튼 | Y15: 1:유형선택 → 2:헤더 → 3:기본정보 → 4:기간/횟수 → 5:추가설정 → 6:하단고정바 | Z15: page (유형선택 → 폼 2-step) | AA15: SCR-040 '등록' 버튼 또는 수정 클릭 | AB15: 저장: 버튼 로딩스핀 상품명 중복체크: 실시간 검증 | AC15: 없음 (폼 페이지) | AD15: ≥768px(md): FormSection 2열 <768px: FormSection 1열 하단바: 모바일 전체너비, md에서 자동크기 | AE15: 하단 액션바 sticky bottom
A16: SCR-050 | B16: 락커 현황 | C16: Web | D16: /locker | E16: 구역별 락커 그리드. 색상으로 상태 구분 (사용중/빈/만료임박) | F16: UI-053, UI-054, UI-055, UI-056 | G16: 구역 탭 전환, 락커 클릭 시 상세 모달, 범례 표시 | H16: CSS Grid 레이아웃 | J16: GNB 메뉴 | K16: SCR-051 (관리 이동) | L16: 락커 없음: '등록된 락커가 없습니다' | M16: 색상 + 패턴으로 상태 구분 (색약 대응) | N16: 그리드 반응형 | Q16: 확정 | R16: 개발팀 | S16: 2 | T16: 1 | U16: 1 | W16: 4 | X16: [헤더] 제목 + 새로고침/엑셀/락커추가 버튼 [섹션1: 통계카드] 4개 (전체/사용중/만료임박/고장) [섹션2: 구역탭+검색] TabNav(A/B/C구역) + 검색input + 범례 [섹션3: 락커그리드] 4x8=32개 셀 (aspect-square, 색상으로 상태구분) - 셀내용: 번호/회원명/D-Day/고장표시 - 일괄선택모드: 체크아이콘 [모달] 락커상세(배정회원/만료일/이력테이블/배정해제) [다이얼로그] 일괄해제확인 | Y16: 1:헤더 → 2:통계카드4개 → 3:구역탭+검색+범례 → 4:락커그리드 | Z16: page | AA16: GNB '락커 관리' 클릭 | AB16: 그리드: 전체 스켈레톤 모달: 이력 로딩 | AC16: 락커 없음: '등록된 락커가 없습니다' 빈 락커: '비어있음' 표시 검색 없음: '결과가 없습니다' | AD16: ≥768px(md): 그리드8열 640~767px(sm): 6열 <640px: 4열 | AE16: GNB 상단고정
A17: SCR-051 | B17: 락커 관리 | C17: Web | D17: /locker/management | E17: 락커 배정/해제/일괄 관리 | F17: UI-089, UI-090, UI-091, UI-092 | G17: 회원 검색 → 빈 락커 선택 → 배정, 일괄 선택 해제 | H17: 배정 모달 | J17: SCR-050, GNB | K17: SCR-050 | L17: 이미 배정된 락커: '이미 사용중인 락커입니다' | M17: 모달 접근성 | N17: 모달 반응형 | Q17: 확정 | R17: 개발팀 | S17: 0 | T17: 1 | U17: 1 | W17: 4 | X17: [헤더] 밴드/카드관리 + 상태동기화/엑셀 버튼 [섹션1: 통계카드] 5개 (총/가능/사용중/시간초과/비정상) [섹션2: 탭] 3개(일일/개인/골프) [섹션3: 배정패널] 3열그리드(회원검색AutoComplete + 선택락커확인 + 배정버튼) [일괄해제경고] 시간초과 시 amber배너 [빈사물함그리드] 12열 그리드, 선택토글 [전체현황] 남자/여자 섹션별 그리드 (시간초과: pulse아이콘) [범례] 5가지 상태색상 | Y17: 1:헤더 → 2:통계카드5개 → 3:탭 → 4:배정패널 → 5:경고배너 → 6:빈사물함 → 7:전체현황 → 8:범례 | Z17: page | AA17: GNB '사물함 관리' 클릭 | AB17: 사물함 데이터: 그리드 스켈레톤 배정처리: 버튼 로딩 | AC17: 빈 사물함 없음: '모든 사물함이 사용 중입니다' | AD17: ≥1024px(lg): 그리드12열 768~1023px(md): 10열 640~767px(sm): 8열 <640px: 5열 | AE17: GNB 상단고정
A18: SCR-052 | B18: RFID 관리 | C18: Web | D18: /rfid | E18: RFID 카드 등록/해제/이력 조회 | F18: UI-108, UI-109, UI-110 | G18: 카드 번호 스캔 입력, 회원 매핑, 분실 처리 버튼 | H18: RFID 리더기 연동 | J18: GNB 메뉴 | K18: SCR-011 (회원 연결) | L18: 미등록 카드: '등록되지 않은 카드입니다' 이미 매핑: '다른 회원에게 배정된 카드' | M18: 폼 접근성 | N18: 테이블 반응형 | Q18: 확정 | R18: 개발팀 | S18: 1 | T18: 1 | U18: 3 | W18: 3 | Y18: 카드 목록 → 카드 등록/해제
A19: SCR-053 | B19: 룸 관리 | C19: Web | D19: /rooms | E19: GX룸/PT룸 등록/수정/삭제. 예약 시간대 설정 | F19: UI-111, UI-112 | G19: 룸 카드 뷰, 수용인원 설정, 시간대 슬롯 설정 | H19: 카드 레이아웃 | J19: GNB 메뉴 | K19: SCR-021 (일정 연결) | L19: 룸 삭제 시 예약 존재: '기존 예약이 있어 삭제할 수 없습니다' | M19: 카드 접근성 | N19: 카드 반응형 | Q19: 확정 | R19: 개발팀 | S19: 1 | T19: 1 | U19: 1 | W19: 2 | Y19: 시설 목록 → 시설 상태 → 관리
A20: SCR-060 | B20: 직원 목록 | C20: Web | D20: /staff | E20: 직원 검색/필터/목록 조회 | F20: UI-057, UI-058, UI-059, UI-060, UI-061 | G20: 역할 필터, 상태 필터, 검색, 테이블 정렬 | H20: 테이블 레이아웃 | J20: GNB 메뉴 | K20: SCR-061 (등록), 직원 상세 모달 | L20: 검색 결과 없음: '조건에 맞는 직원이 없습니다' | M20: 테이블 접근성 | N20: 테이블 반응형 | Q20: 확정 | R20: 개발팀 | S20: 2 | T20: 1 | U20: 3 | V20: 페이지네이션 상태 관리 구현. 퇴사 처리 ConfirmDialog (2026-03-13) | W20: 5 | X20: [헤더] 제목 + 직원등록 버튼 [섹션1: 통계카드] 4개 (전체/재직/휴직/퇴사) [섹션2: SearchFilter] 직원명/연락처 검색 + role/status 필터 [섹션3: 액션버튼] 4개 (메시지/상태변경/퇴사/다운로드) [섹션4: DataTable] 8컬럼 (No/이름/역할배지/연락처/입사일/상태/메모/메뉴) - 선택가능, 3방향정렬 [다이얼로그] 퇴사확인 (danger) | Y20: 1:헤더 → 2:통계카드4개 → 3:검색/필터 → 4:액션버튼 → 5:테이블 | Z20: page | AA20: GNB '직원 관리' 클릭 | AB20: 통계카드: 숫자 스켈레톤 테이블: 행 스켈레톤 | AC20: 직원 없음: '등록된 직원이 없습니다' | AD20: ≥1024px(lg): 통계카드4열 <768px: 통계카드1열 | AE20: GNB 상단고정
A21: SCR-061 | B21: 직원 등록 | C21: Web | D21: /staff/new | E21: 신규 직원 등록 폼 | F21: UI-093, UI-094, UI-095, UI-096, UI-097 | G21: 역할 선택 시 권한 미리보기, 관리자 계정 자동 생성 옵션 | H21: 폼 레이아웃 | J21: SCR-060 '등록' 버튼 | K21: SCR-060 (저장 후) | L21: 필수 미입력: 필드별 에러 중복 이메일: 경고 | M21: 폼 접근성 | N21: 폼 1열 | Q21: 확정 | R21: 개발팀 | S21: 0 | T21: 1 | U21: 1 | W21: 5 | X21: [헤더] 제목 + 취소/저장 버튼 [FormSection1: 기본정보] 이름(필수)/역할(select+권한미리보기)/연락처(자동하이픈)/입사일(date) [FormSection2: 추가정보] 이메일/메모(textarea) [다이얼로그] 등록취소확인 | Y21: 1:헤더 → 2:기본정보폼 → 3:추가정보폼 | Z21: page | AA21: SCR-060 '직원 등록' 버튼 | AB21: 저장: 버튼 로딩 | AC21: 없음 (폼 페이지) | AD21: max-w-[860px] 모든 필드 전체너비 | AE21: 없음
A22: SCR-062 | B22: 급여 현황 | C22: Web | D22: /payroll | E22: 월별 급여 현황 테이블. 합계/평균 요약 | F22: UI-098, UI-099, UI-100 | G22: 월 선택, 지급상태 필터, 합계 행 | H22: 테이블 + 요약 카드 | J22: GNB 메뉴 | K22: SCR-063 (명세서) | L22: 데이터 없음: '해당 월 급여 데이터가 없습니다' | M22: 테이블 접근성 | N22: 테이블 반응형 | Q22: 확정 | R22: 개발팀 | S22: 2 | T22: 1 | U22: 1 | V22: 페이지네이션 상태 관리 구현. 필터 변경 시 1페이지 리셋 (2026-03-13) | W22: 3 | Y22: 월 선택 → 급여 테이블 → 합계/액션
A23: SCR-063 | B23: 급여명세서 | C23: Web | D23: /payroll/statements | E23: 직원별 급여명세서 상세. PDF 다운로드 | F23: UI-127, UI-128, UI-129 | G23: 직원 선택, 월 선택, 명세서 상세 표시, PDF 다운로드 | H23: PDF 생성 (html2pdf) | J23: SCR-062 직원 클릭 | K23: SCR-062 | L23: 명세서 없음: '해당 월 명세서가 없습니다' | M23: 명세서 접근성 | N23: A4 레이아웃 | Q23: 확정 | R23: 개발팀 | S23: 0 | T23: 1 | U23: 1 | W23: 3 | Y23: 월 선택 → 급여 테이블 → 합계/액션
A24: SCR-070 | B24: 메시지 발송 | C24: Web | D24: /message | E24: SMS/카카오톡 메시지 발송. 수신자 선택 + 본문 편집 | F24: UI-062, UI-063, UI-064, UI-065, UI-066 | G24: 수신자 검색/그룹 선택, 메시지 유형 탭, 미리보기, 발송 이력 테이블 | H24: 메시지 API 연동 | J24: GNB 메뉴 | K24: 발송 이력 상세 모달 | L24: 수신자 미선택: '수신자를 선택해주세요' 발송 실패: 실패 건 재발송 옵션 | M24: 폼 접근성 | N24: 2컬럼→1컬럼 | Q24: 확정 | R24: 개발팀 | S24: 2 | T24: 2 | U24: 0 | W24: 5 | X24: [헤더] 월선택(최근12개월 드롭다운) + 내보내기 버튼 [섹션1: 통계카드] 4개 (총지급대상/총실지급액/지급완료/미지급보류) [섹션2: SearchFilter] 직원명/역할 + status 필터 [섹션3: DataTable] 7컬럼 (이름/역할/기본급/인센티브(녹색+)/공제(빨강-)/실지급액(파란굵음)/지급상태) - 정렬 지원 [합계행] 기본급/인센티브/공제합계+평균, 실지급액 강조 [바로가기배너] 급여명세서 링크 (FileText + 파란배경) | Y24: 1:헤더+월선택 → 2:통계카드4개 → 3:검색/필터 → 4:테이블 → 5:합계행 → 6:명세서배너 | Z24: page | AA24: GNB '급여 관리' 클릭 | AB24: 통계카드: 숫자 스켈레톤 테이블: 행 스켈레톤 월 변경: 전체 재조회 | AC24: 데이터 없음: '해당 월 급여 데이터가 없습니다' | AD24: ≥1024px(lg): 통계카드4열 <768px: 통계카드2열 | AE24: GNB 상단고정
A25: SCR-071 | B25: 자동 알림 | C25: Web | D25: /message/auto-alarm | E25: 자동 알림 규칙 설정 (만료/생일/미출석 등) | F25: UI-101, UI-102 | G25: 규칙 토글 ON/OFF, 발송 시점 설정, 메시지 템플릿 편집 | H25: 규칙 엔진 설정 UI | J25: SCR-070, GNB | K25: SCR-070 (발송 이력) | L25: 템플릿 미입력: '메시지 내용을 입력해주세요' | M25: 토글 접근성 | N25: 폼 1열 | Q25: 확정 | R25: 개발팀 | S25: 0 | T25: 0 | U25: 0 | W25: 2 | X25: [헤더] 일괄인쇄 버튼 [통계카드] 3개 (총실지급액/지급완료건/미지급건) [2열 레이아웃 xl기준] - [좌측: 선택패널 sticky] - 직원선택(select) + 월선택(select) - 명세서상세: 직원정보헤더(primary-light) + 지급항목(Plus녹색) + 공제항목(Minus빨강) + 실지급액(accent-light 강조) - 이메일/PDF 버튼 - [우측: 전체현황] - DataTable 7컬럼 [모달] 명세서상세 (스크롤, max-h-[65vh]) | Y25: 1:헤더 → 2:통계카드3개 → 3좌:직원/월선택+명세서상세 → 3우:전체현황테이블 | Z25: page (2-column layout) | AA25: SCR-070 '명세서 바로가기' 클릭 / GNB | AB25: 데이터 로딩: 전체 스켈레톤 직원변경: 명세서 갱신 | AC25: 명세서 없음: '해당 월 명세서가 없습니다' | AD25: ≥1280px(xl): 2열(선택+현황) <1280px: 1열(상하스택) 좌측패널: xl에서 sticky | AE25: 좌측패널 xl에서 sticky
A26: SCR-072 | B26: 쿠폰 관리 | C26: Web | D26: /message/coupon | E26: 쿠폰 생성/발급/이력 관리 | F26: UI-103, UI-104 | G26: 쿠폰 생성 모달, 발급 대상 선택, 사용 이력 테이블 | H26: 모달 + 테이블 | J26: GNB 메뉴 | K26: 쿠폰 상세 모달 | L26: 유효기간 만료: '만료된 쿠폰입니다' 사용 한도 초과: 비활성화 | M26: 모달 접근성 | N26: 테이블 반응형 | Q26: 확정 | R26: 개발팀 | S26: 2 | T26: 1 | U26: 0 | W26: 2 | Y26: 쿠폰 목록 → 쿠폰 생성/발급
A27: SCR-073 | B27: 마일리지 관리 | C27: Web | D27: /mileage | E27: 회원 마일리지 적립/사용 이력 조회 및 관리 | F27: UI-105, UI-106, UI-107 | G27: 회원 검색, 적립/차감 모달, 이력 테이블 | H27: 모달 + 테이블 | J27: GNB 메뉴 | K27: SCR-011 (회원 연결) | L27: 잔액 부족 차감: '마일리지가 부족합니다' | M27: 테이블 접근성 | N27: 테이블 반응형 | Q27: 확정 | R27: 개발팀 | S27: 0 | T27: 1 | U27: 0 | V27: 마일리지 이력 탭 엑셀 다운로드 실제 구현 (2026-03-13) | W27: 3 | Y27: 회원 검색 → 마일리지 현황 → 적립/차감
A28: SCR-080 | B28: 계약 마법사 | C28: Web | D28: /contracts/new | E28: 단계별 계약 등록 위자드 (회원→상품→기간→결제→확인) | F28: UI-067, UI-068, UI-069, UI-070, UI-071, UI-072 | G28: 스텝 인디케이터, 이전/다음 버튼, 단계별 유효성 검사 | H28: 위자드 컴포넌트 | J28: SCR-011, SCR-031 | K28: SCR-011 (완료 후) | L28: 필수 단계 미완료: '이전 단계를 완료해주세요' 결제 실패: 재시도 옵션 | M28: 스텝 접근성 | N28: 스텝 세로 배치 | Q28: 확정 | R28: 개발팀 | S28: 2 | T28: 2 | U28: 2 | V28: 전자서명 Canvas (센터측+고객측 양방향) 구현 (2026-03-13) | W28: 6 | X28: [헤더] 제목 [탭] 2개 (발송/이력) [포인트현황카드] 3열(잔여포인트/사용량/발신설정) [발송탭: 2열 xl기준] - [좌측: 수동발송폼] - 수신자선택: 그룹빠른선택5버튼 + 선택배지 + 대상검색모달 - 발송채널: 3라디오(알림톡8원/SMS·LMS/앱푸시무료) + 글자제한안내 - 예상비용: 단가×수신자 계산 - 메시지내용: textarea + 글자수게이지 + 변수삽입5버튼 - 예약발송: checkbox + datetime - [우측: 자동알림설정] - 고객관련 5토글 + 상품관련 4토글 [이력탭] DataTable 8컬럼 [모달] 수신자검색(체크리스트) / 미리보기(채널+내용+발송버튼) | Y28: 1:헤더 → 2:탭 → 3:포인트현황 → 4좌:수신자+채널+비용+메시지+예약 → 4우:자동알림 | Z28: page (2-column layout on send tab) | AA28: GNB '메시지 발송' 클릭 | AB28: 이력: 테이블 스켈레톤 발송처리: 버튼 로딩 | AC28: 수신자 없음: '검색 결과가 없습니다' 이력 없음: '발송 이력이 없습니다' | AD28: ≥1280px(xl): 발송2열 <1280px: 발송1열(폼→자동알림 순서) 포인트: md에서 col-span-2 | AE28: GNB 상단고정
A29: SCR-081 | B29: 구독 관리 | C29: Web | D29: /subscription | E29: 정기 구독 상품 관리. 자동 결제 현황 | F29: UI-113, UI-114 | G29: 구독 상품 목록, 결제 현황 대시보드, 구독 상세 모달 | H29: 테이블 + 카드 | J29: GNB 메뉴 | K29: 구독 상세 모달 | L29: 결제 실패 구독: 경고 배지 표시 | M29: 테이블 접근성 | N29: 카드 반응형 | Q29: 확정 | R29: 개발팀 | S29: 0 | T29: 2 | U29: 4 | W29: 2 | Y29: 현재 플랜 → 플랜 비교 → 결제 정보
A30: SCR-090 | B30: 설정 | C30: Web | D30: /settings | E30: 시스템 기본 설정. 센터 정보/영업시간/알림 등 | F30: UI-073, UI-074, UI-075 | G30: 탭 구성 (기본/알림/테마), 저장 버튼 | H30: 탭 + 폼 | J30: GNB 메뉴 | K30: SCR-091, SCR-092, SCR-093 | L30: 저장 실패: 토스트 에러 | M30: 탭 접근성 | N30: 폼 1열 | Q30: 확정 | R30: 개발팀 | S30: 5 | T30: 1 | U30: 0 | W30: 3 | X30: [헤더] 제목 + 취소 버튼 [Step Indicator] 5단계 프로그레스바 (원형번호/CheckCircle, 색상변화) [Step1: 회원선택] 검색input + DataTable(4컬럼) + 선택확인배지 [Step2: 상품선택] 2열(좌:탭4개+상품카드그리드 / 우:장바구니sticky) [Step3: 기간/금액] FormSection3개(계약기간2열/할인설정2열+미리보기/특약메모) + 안내배너 [Step4: 결제] 2열(좌:결제수단4버튼+금액요약 / 우:결제실행버튼) [Step5: 확인] 안내배너 + 계약요약카드(회원/조건/상품/금액) [하단] 이전/다음(또는 완료) 버튼 | Y30: 1:헤더 → 2:스텝인디케이터 → 3:스텝콘텐츠(1~5) → 4:이전/다음버튼 | Z30: page (5-step wizard) | AA30: GNB '전자계약' 클릭 | AB30: 회원/상품 조회: 테이블/카드 스켈레톤 Step전환: 애니메이션(animate-in) | AC30: 회원 없음: '검색 결과가 없습니다' 상품 없음: '등록된 상품이 없습니다' 장바구니 비어있음: '상품을 선택해주세요' | AD30: Step Indicator: min-w-[600px] 가로스크롤 메인: max-w-[1200px] Step2,4: lg에서 2열 | AE30: 하단 이전/다음 버튼 고정
A31: SCR-091 | B31: 권한 설정 | C31: Web | D31: /settings/permissions | E31: 역할별 메뉴/기능 권한 매트릭스 | F31: UI-076, UI-077, UI-078 | G31: 역할 탭, 권한 체크박스 매트릭스, 일괄 설정 | H31: 매트릭스 테이블 | J31: SCR-090, GNB | K31: SCR-090 | L31: 권한 충돌: 경고 표시 | M31: 체크박스 접근성 | N31: 테이블 가로스크롤 | Q31: 확정 | R31: 개발팀 | S31: 0 | T31: 2 | U31: 0 | W31: 3 | X31: [헤더] 제목 + 신규쿠폰생성 버튼 [섹션1: 통계카드] 4개 (전체/활성/총발급/사용완료) [탭] 2개 (쿠폰목록/발급이력) [쿠폰목록탭] SearchFilter(상태/유형) + DataTable 8컬럼(쿠폰명+코드배지/유형/할인값/사용현황 프로그레스바/유효기간+D-day/상태/등록일/메뉴) [발급이력탭] SearchFilter(발급일/쿠폰/상태) + DataTable 8컬럼 [모달] 쿠폰생성폼(쿠폰명/코드자동생성/유형라디오/한도/할인방식/유효기간/조건/메모) / 쿠폰발급(개인·그룹토글/수신자검색태그/수량/알림메시지) [다이얼로그] 삭제확인 | Y31: 1:헤더 → 2:통계카드4개 → 3:탭 → 4:검색/필터 → 5:테이블 | Z31: page | AA31: GNB '쿠폰 관리' 클릭 | AB31: 통계카드: 스켈레톤 테이블: 행 스켈레톤 | AC31: 쿠폰 없음: '등록된 쿠폰이 없습니다' 발급이력 없음: '발급 이력이 없습니다' | AD31: ≥768px(md): 통계카드4열 <768px: 통계카드1열 모달: max-w-2xl | AE31: GNB 상단고정
A32: SCR-092 | B32: 키오스크 설정 | C32: Web | D32: /settings/kiosk | E32: 키오스크 디스플레이/동작 설정 | F32: UI-115, UI-116 | G32: 미리보기, 로고 업로드, 동작 시나리오 설정 | H32: 미리보기 컴포넌트 | J32: SCR-090, GNB | K32: SCR-090 | L32: 이미지 용량 초과: '5MB 이하 파일만 업로드 가능합니다' | M32: 폼 접근성 | N32: 폼 1열 | Q32: 확정 | R32: 개발팀 | S32: 0 | T32: 1 | U32: 0 | V32: placeholder URL 제거, 빈 상태 UI 구현 (2026-03-13) | W32: 2 | X32: [헤더] 제목 + 엑셀다운로드 버튼 [섹션1: 통계카드] 4개 (발행/사용/잔여/이번달적립) [탭] 3개 (현황/이력/정책) [현황탭] SearchFilter(회원명/연락처+정렬/만료임박) + DataTable 9컬럼(아바타+회원명링크/연락처/적립/사용/잔여(bold)/최근적립일/만료예정일+D-day/메뉴) [이력탭] SearchFilter(회원명+기간/처리유형) + DataTable 8컬럼 [정책탭] 변경감지배너(amber) + FormSection3개(기본적립/사용제한/대상상품) + 저장버튼(isDirty) [모달] 수동조정(적립·차감토글/금액/사유/메모) [다이얼로그] 정책변경확인 | Y32: 1:헤더 → 2:통계카드4개 → 3:탭 → 4:탭콘텐츠 | Z32: page | AA32: GNB '마일리지 관리' 클릭 | AB32: 통계카드: 스켈레톤 테이블: 행 스켈레톤 | AC32: 현황 없음: '마일리지 데이터가 없습니다' 이력 없음: '이력이 없습니다' | AD32: ≥1024px(lg): 통계카드4열 <768px: 통계카드2열 정책탭: max-w-4xl | AE32: GNB 상단고정
A33: SCR-093 | B33: IoT 설정 | C33: Web | D33: /settings/iot | E33: 출입문/체성분 기기 연동 설정 | F33: UI-117, UI-118 | G33: 기기 목록, 연결 상태 표시, 테스트 버튼 | H33: 기기 연동 API | J33: SCR-090, GNB | K33: SCR-090 | L33: 연결 실패: '기기와 연결할 수 없습니다' + 재시도 | M33: 상태 아이콘 alt-text | N33: 테이블 반응형 | Q33: 확정 | R33: 개발팀 | S33: 0 | T33: 1 | U33: 0 | W33: 2 | X33: [헤더] 제목 + 신규등록 버튼 [섹션1: 통계카드] 3개 (전체/활성/미사용·해제·분실) [섹션2: SearchFilter] 카드번호/회원명 + 상태필터 [섹션3: DataTable] 9컬럼 (등록일/카드번호(mono)/회원명링크/유형배지/상태(dot)/발급일/사물함/메뉴) [모달] 카드등록(스캔UI pulse애니메이션 + 카드입력 + 사용자유형라디오 + 회원검색드롭다운 + 매핑확인카드 + 락커번호) / 이력조회(날짜범위+테이블) [다이얼로그] 삭제확인 | Y33: 1:헤더 → 2:통계카드3개 → 3:검색/필터 → 4:테이블 | Z33: page | AA33: GNB '밴드/카드' 클릭 | AB33: 통계카드: 스켈레톤 테이블: 행 스켈레톤 카드스캔: pulse 애니메이션 | AC33: 카드 없음: '등록된 카드가 없습니다' 이력 없음: '이력이 없습니다' | AD33: ≥768px(md): 통계카드3열 <768px: 통계카드1열 모달: max-w-[560px] | AE33: GNB 상단고정
A34: SCR-094 | B34: 지점 관리 | C34: Web | D34: /branches | E34: 지점 CRUD. 멀티테넌트 관리 | F34: UI-079, UI-080, UI-081 | G34: 지점 카드/테이블 뷰 전환, 지점 추가 모달, 데이터 초기화 | H34: 카드/테이블 토글 | J34: GNB 메뉴 (최고관리자만) | K34: 지점 상세 모달 | L34: 지점 삭제 시 데이터 존재: '소속 데이터가 있어 삭제 불가' | M34: 카드/테이블 접근성 | N34: 카드 반응형 | Q34: 확정 | R34: 개발팀 | S34: 0 | T34: 2 | U34: 1 | W34: 3 | X34: [헤더] 제목 + 연결상태배지(Wifi아이콘) + 설정저장 버튼 [에러배너] 오프라인 시 (조건부) [탭] 4개 (기본설정/화면설정/TTS설정/출입규칙) [기본설정탭] 2열(좌:FormSection(키오스크타입/입장방식/시스템설정) / 우:KioskPreview 폰프레임목업) [화면설정탭] FormSection(로고/배경/테마색상/환영문구/공지·날씨/광고배너) [TTS설정탭] FormSection(안내메시지) + 테이블(이벤트/메시지/Play재생버튼) [출입규칙탭] FormSection(출입시간/만료회원/중복체크인) | Y34: 1:헤더+상태 → 2:에러배너(조건부) → 3:탭 → 4:탭콘텐츠 | Z34: page | AA34: GNB '키오스크' 클릭 | AB34: 설정 로딩: 전체 스켈레톤 저장: 버튼 로딩 + toast | AC34: 없음 (설정 페이지, 기본값 존재) | AD34: 기본설정: lg에서 3열(좌2:우1 preview) <1024px: 1열(preview 아래로) 모바일: 체크인방식 숨김 | AE34: GNB 상단고정
A35: SCR-000 | B35: 공통 레이아웃 | C35: Web | D35: / | E35: 전체 화면 공통 레이아웃. AppHeader(GNB) + AppSidebar + 콘텐츠 영역. 사이드바 접기/펼치기, 반응형 | F35: UI-201,UI-202,UI-203 | G35: 사이드바 접기/펼치기 시 콘텐츠 영역 자동 조정, 반응형 브레이크포인트(1024px/768px) | Q35: 확정 | R35: 개발팀 | S35: 0 | T35: 0 | U35: 0 | W35: 0 | X35: [GNB] 상단 고정 헤더 (h:56px) [Sidebar] 좌측 사이드바 (w:240px, 접힌 상태 60px) [Content] 우측 메인 콘텐츠 영역 (flex-1, p-6) | Y35: 1:GNB → 2:Sidebar → 3:Content | Z35: layout (모든 페이지 공통 래퍼) | AA35: 로그인 성공 후 | AB35: N/A | AC35: N/A | AD35: ≥1024px: 사이드바 240px + 콘텐츠 768~1023px: 사이드바 60px(아이콘만) <768px: 사이드바 숨김, 햄버거 메뉴 | AE35: GNB 상단 고정, Sidebar 좌측 고정
A36: SCR-ERR | B36: 404 에러 | C36: Web | D36: /* | E36: 존재하지 않는 경로 접근 시 표시. 메인으로 돌아가기 버튼 | F36: (없음) | G36: 메인으로 돌아가기 버튼 클릭→대시보드(/)로 이동 | Q36: 확정 | R36: 개발팀 | S36: 0 | T36: 2 | U36: 0 | W36: 0 | X36: [중앙] 404 아이콘 + "페이지를 찾을 수 없습니다" 메시지 + 홈으로 돌아가기 버튼 | Y36: 1:404 아이콘 → 2:에러 메시지 → 3:돌아가기 버튼 | Z36: page (사이드바 없음) | AA36: 잘못된 URL 직접 접근 | AB36: N/A | AC36: N/A | AD36: 반응형 중앙 정렬 | AE36: 없음
A37: SCR-001-E | B37: 로그인 - 에러 상태 | C37: Web | D37: /login | E37: 로그인 실패 시 에러 메시지 표시 상태. 빨간 배경 에러 박스 활성 | F37: (해당 없음) | G37: 에러 메시지 닫기, 재입력 시 에러 초기화 | J37: SCR-001 로그인 실패 시 | L37: 계정 잠금: '5회 실패로 잠겼습니다. 30분 후 다시 시도하세요' | Q37: 확정 | S37: 0 | T37: 0 | U37: 0 | W37: 0 | X37: SCR-001과 동일 | Y37: 로고 → 이메일 입력 → 비밀번호 입력 → 로그인 버튼 | Z37: state (에러 상태) | AA37: 로그인 실패 시 | AB37: 없음 | AC37: 없음 | AD37: SCR-001과 동일 | AE37: 없음
A38: SCR-001-L | B38: 로그인 - 로딩 상태 | C38: Web | D38: /login | E38: 로그인 버튼 클릭 후 인증 처리 중 상태. 버튼 비활성 + Loader2 스핀 | F38: (해당 없음) | G38: 로딩 중 입력 비활성, ESC 취소 불가 | J38: SCR-001 로그인 버튼 클릭 | L38: 타임아웃: 10초 후 자동 실패 처리 | Q38: 확정 | S38: 0 | T38: 0 | U38: 0 | W38: 0 | X38: SCR-001과 동일 | Y38: 스켈레톤 UI | Z38: state (로딩 상태) | AA38: 로그인 버튼 클릭 | AB38: 로그인 버튼: Loader2 스핀 + '로그인 중...' | AC38: 없음 | AD38: SCR-001과 동일 | AE38: 없음
A39: SCR-001-M | B39: 로그인 - 모바일 뷰 | C39: Mobile | D39: /login | E39: 모바일 브라우저에서의 로그인 화면. 풀스크린 카드, 키보드 대응 | F39: (해당 없음) | G39: 키보드 올라올 때 뷰포트 조정 | I39: 키보드 올라올 때 스크롤 가능 | J39: URL 직접 접근 | L39: SCR-001과 동일 | M39: 터치 대상 44px 이상 | N39: <768px 풀너비 | Q39: 확정 | S39: 0 | T39: 0 | U39: 0 | W39: 0 | X39: 풀스크린 카드, padding 축소 | Y39: 로고 → 이메일 입력 → 비밀번호 입력 → 로그인 버튼 | Z39: page (모바일) | AA39: URL 직접접근 | AB39: SCR-001과 동일 | AC39: SCR-001과 동일 | AD39: 풀너비, gap 축소, 로고 축소 | AE39: 없음
A40: SCR-002-L | B40: 대시보드 - 로딩 상태 | C40: Web | D40: / | E40: 대시보드 초기 로딩 시 스켈레톤 UI 표시 상태 | F40: (해당 없음) | G40: 스켈레톤 애니메이션, 수동 갱신 버튼 비활성 | J40: SCR-001 로그인 성공 후 | L40: 5초 후 로딩 실패 시 에러 전환 | Q40: 확정 | S40: 0 | T40: 0 | U40: 0 | W40: 0 | X40: SCR-002와 동일 (스켈레톤) | Y40: 스켈레톤 UI | Z40: state (로딩) | AA40: 페이지 진입 | AB40: 통계카드 스켈레톤 + 차트 스피너 + 리스트 행 스켈레톤 | AC40: 없음 | AD40: SCR-002와 동일 | AE40: GNB 상단고정
...

Sheet UI 요소 상세
A1: 요소 ID | B1: 화면 ID | C1: 요소명 | D1: 요소 유형 | E1: 요소 설명 | F1: 인터랙션 정의 | G1: 기능 ID | H1: API ID | I1: Web 구현 | J1: App 구현 | K1: 유효성 검사 | L1: 에러 메시지 | M1: 접근성 | N1: 상태 | O1: 담당자 | P1: [자동] 화면명 | Q1: [자동] 기능명 | R1: [자동] API 엔드포인트 | S1: 비고 | T1: 내부 구성 | U1: 크기/간격 | V1: 상태 목록 | W1: 호버/클릭 피드백 | X1: 소속 섹션 | Y1: 정렬 순서 | Z1: 조건부 표시 | AA1: 관련 디자인토큰
A2: ▼ SCR-001 | B2: 로그인 (5개 요소) | C2: 5개 요소
A3: UI-001 | B3: SCR-001 | C3: 이메일 입력 | D3: Input | E3: 로그인 이메일 주소 입력 필드 | F3: 포커스 시 라벨 상단 이동, 실시간 이메일 형식 검증 | G3: FN-001 | H3: API-001 | I3: <input type='email'> + 실시간 validation | K3: 이메일 형식 검증 (regex) | L3: 올바른 이메일 주소를 입력하세요 | M3: aria-label='이메일' | N3: 설계중 | P3: 로그인 | Q3: 로그인 | R3: /api/v1/auth/login | T3: 라벨('이메일') 상단 + input(type=email) + 실시간 형식검증 | U3: w:100%, h:40px, padding:12px, label:14px gray-500 | V3: default / focus(border-primary) / error(border-red + 에러텍스트) / filled | W3: focus: 라벨 상단이동 + border-primary blur: 에러 시 border-red | X3: 폼 영역 | Y3: 1 | Z3: 항상 | AA3: TK-304(input radius), TK-206(높이), TK-024(라벨색)
A4: UI-002 | B4: SCR-001 | C4: 비밀번호 입력 | D4: Input | E4: 로그인 비밀번호 입력 필드 | F4: 마스킹 토글 버튼, Enter키 로그인 트리거 | G4: FN-001 | H4: API-001 | I4: <input type='password'> + visibility toggle | K4: 최소 1자 이상 | L4: 비밀번호를 입력하세요 | M4: aria-label='비밀번호' | N4: 설계중 | P4: 로그인 | Q4: 로그인 | R4: /api/v1/auth/login | T4: 라벨('비밀번호') + input(type=password) + Eye/EyeOff 토글버튼 | U4: w:100%, h:40px, 토글버튼:24px 우측 | V4: default / focus / error / masked / visible | W4: Eye클릭: password↔text 전환 Enter: 로그인 트리거 | X4: 폼 영역 | Y4: 2 | Z4: 항상 | AA4: TK-304, TK-206
A5: UI-003 | B5: SCR-001 | C5: 지점 선택 | D5: Select | E5: 로그인 시 접근할 지점 선택 드롭다운 | F5: 선택 시 지점 로고/색상 변경 | G5: FN-001 | H5: API-001 | I5: <select> 커스텀 드롭다운 | K5: 필수 선택 | L5: 지점을 선택하세요 | M5: aria-label='지점 선택' | N5: 설계중 | P5: 로그인 | Q5: 로그인 | R5: /api/v1/auth/login | T5: MapPin아이콘 + select 드롭다운 + 옵션리스트 | U5: w:100%, h:40px | V5: default / loading(Loader2) / open(드롭다운펼침) / selected / error | W5: click: 드롭다운 열기 선택: 지점 로고/색상 변경 | X5: 폼 영역 | Y5: 0 (폼 최상단) | Z5: 항상 | AA5: TK-304, TK-206, TK-036(선택됨)
A6: UI-004 | B6: SCR-001 | C6: 로그인 버튼 | D6: Button | E6: 로그인 실행 버튼 | F6: 클릭/Enter 시 로그인 API 호출, 로딩 스피너 | G6: FN-001 | H6: API-001 | I6: <button> + loading state | K6: 이메일/비밀번호/지점 모두 입력 시 활성화 | L6: 로그인에 실패했습니다 | M6: aria-label='로그인' | N6: 설계중 | P6: 로그인 | Q6: 로그인 | R6: /api/v1/auth/login | T6: 텍스트('로그인') + 조건부 Loader2 스핀 | U6: w:100%, h:48px, font:16px bold white | V6: default(비활성, gray) / active(primary) / loading(스핀+'로그인 중...') / disabled | W6: hover: primary-600 click: scale(0.98) loading: 클릭 불가 | X6: 폼 영역 | Y6: 5 (폼 하단) | Z6: 이메일/비밀번호/지점 모두 입력 시 활성 | AA6: TK-004(bg), TK-209(높이), TK-604(press)
A7: UI-005 | B7: SCR-001 | C7: 비밀번호 찾기 링크 | D7: Link | E7: 비밀번호 재설정 페이지 이동 링크 | F7: 클릭 시 비밀번호 찾기 모달 오픈 | I7: <a> + 모달 트리거 | M7: aria-label='비밀번호 찾기' | N7: 설계중 | P7: 로그인 | Q7: =IFERROR(VLOOKUP(G7,기능명세서!A:B,2,FALSE()),"") | R7: =IFERROR(VLOOKUP(H7,API명세서!A:D,4,FALSE()),"") | T7: 텍스트 링크('비밀번호 찾기') | U7: font:13px, color:gray-500 | V7: default / hover(underline) | W7: click: 비밀번호 찾기 모달 오픈 | X7: 옵션 영역 | Y7: 4 | Z7: 항상 | AA7: TK-024(색상)
A8: ▼ SCR-002 | B8: 대시보드 (8개 요소) | C8: 8개 요소
A9: UI-006 | B9: SCR-002 | C9: 총회원 통계 카드 | D9: Card | E9: 전체 회원 수 표시 카드 | F9: 클릭 시 SCR-010 이동, 전일 대비 증감 표시 | G9: FN-002 | H9: API-003 | I9: Card 컴포넌트 + 숫자 애니메이션 | M9: aria-label='총 회원 수' | N9: 설계중 | P9: 대시보드 | Q9: 대시보드 통계 조회 | R9: /api/v1/dashboard/stats | T9: [좌] Users아이콘(24px) + [중앙] 라벨('총 회원') 위 + 수치('450명') 아래 + [우하단] 증감배지('+3 ▲' 초록) | U9: w:카드1/6, h:auto, p:24px, 라벨:14px gray-500, 수치:32px bold | V9: default / hover(shadow-md) / loading(숫자 스켈레톤) / zero(수치0) | W9: hover: shadow-md + cursor-pointer click: 회원목록 이동 | X9: 섹션1: 통계카드 영역 | Y9: 1 (6개 중 첫째) | Z9: 항상 | AA9: TK-108(숫자), TK-024(라벨), TK-030(증가), TK-032(감소)
A10: UI-007 | B10: SCR-002 | C10: 활성회원 통계 카드 | D10: Card | E10: 활성(이용중) 회원 수 카드 | F10: 클릭 시 SCR-010 활성 필터 이동 | G10: FN-002 | H10: API-003 | I10: Card 컴포넌트 | M10: aria-label='활성 회원 수' | N10: 설계중 | P10: 대시보드 | Q10: 대시보드 통계 조회 | R10: /api/v1/dashboard/stats | T10: [좌] UserCheck아이콘 + [중앙] '활성회원' + 수치 + 증감 | U10: 동일 StatCard 규격 | V10: default / hover / loading / zero | W10: hover: shadow-md click: 회원목록(활성필터) 이동 | X10: 섹션1: 통계카드 영역 | Y10: 2 | Z10: 항상 | AA10: TK-108, TK-030
A11: UI-008 | B11: SCR-002 | C11: 만료임박 통계 카드 | D11: Card | E11: 7일 내 만료 예정 회원 수 카드 | F11: 클릭 시 SCR-010 만료임박 필터 이동, 경고 색상 | G11: FN-002 | H11: API-006 | I11: Card 컴포넌트 + 경고 스타일 | M11: aria-label='만료 임박 회원' | N11: 설계중 | P11: 대시보드 | Q11: 대시보드 통계 조회 | R11: /api/v1/dashboard/expiring-members | T11: [좌] AlertTriangle아이콘 + [중앙] '만료임박' + 수치 + 경고스타일 | U11: 동일 StatCard, 경고색상 | V11: default / hover / loading / zero / warning(>0일때 amber) | W11: hover: shadow-md click: 회원목록(만료임박필터) 이동 | X11: 섹션1: 통계카드 영역 | Y11: 3 | Z11: 항상 | AA11: TK-034(경고), TK-108
A12: UI-009 | B12: SCR-002 | C12: 만료회원 통계 카드 | D12: Card | E12: 이용권 만료된 회원 수 카드 | F12: 클릭 시 SCR-010 만료 필터 이동 | G12: FN-002 | H12: API-003 | I12: Card 컴포넌트 | M12: aria-label='만료 회원 수' | N12: 설계중 | P12: 대시보드 | Q12: 대시보드 통계 조회 | R12: /api/v1/dashboard/stats | T12: [좌] UserX아이콘 + [중앙] '만료회원' + 수치 | U12: 동일 StatCard 규격 | V12: default / hover / loading / zero | W12: hover: shadow-md click: 회원목록(만료필터) 이동 | X12: 섹션1: 통계카드 영역 | Y12: 4 | Z12: 항상 | AA12: TK-108
A13: UI-010 | B13: SCR-002 | C13: 생일회원 리스트 | D13: List | E13: 오늘 생일인 회원 목록 | F13: 회원명 클릭 시 SCR-011 이동 | G13: FN-002 | H13: API-004 | I13: 리스트 컴포넌트 (최대 5명) | M13: aria-label='오늘 생일 회원' | N13: 설계중 | P13: 대시보드 | Q13: 대시보드 통계 조회 | R13: /api/v1/dashboard/birthday-members | T13: 리스트: 회원명(링크) + 연락처 + 생일일자, 최대5명 | U13: w:카드1/2, max-h:300px | V13: default / empty('오늘 생일인 회원이 없습니다') / loading(3줄 스켈레톤) | W13: 회원명 click: 회원상세 이동 | X13: 섹션3: 리스트 카드 | Y13: 1 (4개 중) | Z13: 항상 | AA13: TK-004(링크)
A14: UI-011 | B14: SCR-002 | C14: 미납회원 리스트 | D14: List | E14: 미납 내역이 있는 회원 목록 | F14: 회원명 클릭 시 SCR-011 이동, 미납 금액 표시 | G14: FN-002 | H14: API-005 | I14: 리스트 컴포넌트 + 금액 강조 | M14: aria-label='미납 회원' | N14: 설계중 | P14: 대시보드 | Q14: 대시보드 통계 조회 | R14: /api/v1/dashboard/unpaid-members | T14: 리스트: 회원명(링크) + 미납금액(빨간) + 결제버튼 | U14: w:카드1/2, 금액:빨간bold | V14: default / empty / loading | W14: 회원명 click: 회원상세 결제 click: POS 이동 | X14: 섹션3: 리스트 카드 | Y14: 2 | Z14: 항상 | AA14: TK-032(미납금액)
A15: UI-012 | B15: SCR-002 | C15: 만료예정 리스트 | D15: List | E15: 7일 내 만료 예정 회원 목록 | F15: 회원명 클릭 시 SCR-011 이동, D-day 표시 | G15: FN-002 | H15: API-006 | I15: 리스트 컴포넌트 + D-day 배지 | M15: aria-label='만료 예정 회원' | N15: 설계중 | P15: 대시보드 | Q15: 대시보드 통계 조회 | R15: /api/v1/dashboard/expiring-members
A16: UI-013 | B16: SCR-002 | C16: 매출 차트 | D16: Card | E16: 당월 매출 추이 라인 차트 | F16: 호버 시 일별 금액 툴팁, 기간 필터 | G16: FN-002 | H16: API-003 | I16: Recharts LineChart | M16: 차트 데이터 테이블 대체 제공 | N16: 설계중 | P16: 대시보드 | Q16: 대시보드 통계 조회 | R16: /api/v1/dashboard/stats
A17: ▼ SCR-010 | B17: 회원 목록 (8개 요소) | C17: 8개 요소
A18: UI-014 | B18: SCR-010 | C18: 검색바 | D18: Input | E18: 회원 이름/연락처/번호 검색 입력 | F18: 실시간 검색 (300ms debounce), 검색 아이콘 | G18: FN-003 | H18: API-007 | I18: SearchInput 컴포넌트 | K18: 최소 2자 이상 | L18: 검색어를 입력하세요 | M18: aria-label='회원 검색' | N18: 설계중 | P18: 회원 목록 | Q18: 회원 목록 조회/검색/필터 | R18: /api/v1/members
A19: UI-015 | B19: SCR-010 | C19: 상태 필터 | D19: Select | E19: 회원 상태(활성/만료/휴회/탈퇴) 필터 | F19: 멀티 선택 가능, 선택 시 즉시 필터 적용 | G19: FN-003 | H19: API-007 | I19: MultiSelect 컴포넌트 | K19: 1개 이상 선택 필수 | L19: 상태 필터을(를) 선택하세요 | M19: aria-label='상태 필터' | N19: 설계중 | P19: 회원 목록 | Q19: 회원 목록 조회/검색/필터 | R19: /api/v1/members
A20: UI-016 | B20: SCR-010 | C20: 성별 필터 | D20: Select | E20: 성별(전체/남/여) 필터 | F20: 단일 선택, 즉시 적용 | G20: FN-003 | H20: API-007 | I20: Select 컴포넌트 | K20: 1개 이상 선택 필수 | L20: 성별 필터을(를) 선택하세요 | M20: aria-label='성별 필터' | N20: 설계중 | P20: 회원 목록 | Q20: 회원 목록 조회/검색/필터 | R20: /api/v1/members
A21: UI-017 | B21: SCR-010 | C21: 담당자 필터 | D21: Select | E21: 담당 FC 필터 | F21: 단일 선택, 즉시 적용 | G21: FN-003 | H21: API-007 | I21: Select 컴포넌트 | K21: 1개 이상 선택 필수 | L21: 담당자 필터을(를) 선택하세요 | M21: aria-label='담당자 필터' | N21: 설계중 | P21: 회원 목록 | Q21: 회원 목록 조회/검색/필터 | R21: /api/v1/members
A22: UI-018 | B22: SCR-010 | C22: 회원 테이블 | D22: List | E22: 회원 목록 데이터 테이블 | F22: 행 클릭 시 SCR-011 이동, 컬럼 정렬, 행 호버 | G22: FN-003 | H22: API-007 | I22: DataTable 컴포넌트 + 정렬/페이지네이션 | M22: aria-label='회원 목록 테이블' | N22: 설계중 | P22: 회원 목록 | Q22: 회원 목록 조회/검색/필터 | R22: /api/v1/members
A23: UI-019 | B23: SCR-010 | C23: 페이지네이션 | D23: Nav | E23: 테이블 하단 페이지 네비게이션 | F23: 페이지 이동, 페이지당 행 수 선택 | G23: FN-003 | H23: API-007 | I23: Pagination 컴포넌트 | M23: aria-label='페이지 이동' | N23: 설계중 | P23: 회원 목록 | Q23: 회원 목록 조회/검색/필터 | R23: /api/v1/members
A24: UI-020 | B24: SCR-010 | C24: 엑셀 다운로드 | D24: Button | E24: 현재 필터 결과 엑셀 다운로드 | F24: 클릭 시 xlsx 파일 다운로드, 로딩 표시 | G24: FN-003 | H24: API-007 | I24: 다운로드 버튼 + 로딩 스피너 | M24: aria-label='엑셀 다운로드' | N24: 설계중 | P24: 회원 목록 | Q24: 회원 목록 조회/검색/필터 | R24: /api/v1/members
A25: UI-021 | B25: SCR-010 | C25: 회원등록 버튼 | D25: Button | E25: 신규 회원 등록 페이지 이동 버튼 | F25: 클릭 시 SCR-012 이동 | G25: FN-004 | I25: Primary Button | M25: aria-label='회원 등록' | N25: 설계중 | P25: 회원 목록 | Q25: 회원 등록 | R25: =IFERROR(VLOOKUP(H25,API명세서!A:D,4,FALSE()),"")
A26: ▼ SCR-011 | B26: 회원 상세 (6개 요소) | C26: 6개 요소
A27: UI-022 | B27: SCR-011 | C27: 프로필 영역 | D27: Card | E27: 회원 기본 정보 카드 (사진/이름/연락처/상태) | F27: 수정 버튼 → SCR-013 이동 | G27: FN-006 | H27: API-008 | I27: 프로필 Card 컴포넌트 | M27: aria-label='회원 프로필' | N27: 설계중 | P27: 회원 상세 | Q27: 회원 상세 조회 | R27: /api/v1/members/:id
A28: UI-023 | B28: SCR-011 | C28: 이용권 탭 | D28: Tab | E28: 보유 이용권 목록 탭 | F28: 만료일 강조, 잔여 횟수 표시 | G28: FN-006 | H28: API-008 | I28: Tab + 이용권 리스트 | M28: aria-label='이용권 탭' | N28: 설계중 | P28: 회원 상세 | Q28: 회원 상세 조회 | R28: /api/v1/members/:id
A29: UI-024 | B29: SCR-011 | C29: 출석 탭 | D29: Tab | E29: 출석 이력 탭 (히트맵 + 리스트) | F29: 히트맵 날짜 클릭 시 상세, 타지점 출석 구분 | G29: FN-006 | H29: API-013 | I29: Tab + 히트맵 + 테이블 | M29: aria-label='출석 탭' | N29: 설계중 | P29: 회원 상세 | Q29: 회원 상세 조회 | R29: /api/v1/attendance
A30: UI-025 | B30: SCR-011 | C30: 결제 탭 | D30: Tab | E30: 결제/매출 이력 탭 | F30: 결제 상세 모달, 환불 처리 | G30: FN-006 | H30: API-015 | I30: Tab + 결제 테이블 | M30: aria-label='결제 탭' | N30: 설계중 | P30: 회원 상세 | Q30: 회원 상세 조회 | R30: /api/v1/sales
A31: UI-026 | B31: SCR-011 | C31: 체성분 탭 | D31: Tab | E31: 체성분 측정 이력 + 차트 탭 | F31: 측정 추가, 변화 추이 차트 | G31: FN-007 | H31: API-008 | I31: Tab + 차트 + 입력 폼 | M31: aria-label='체성분 탭' | N31: 설계중 | P31: 회원 상세 | Q31: 체성분 기록/분석 | R31: /api/v1/members/:id
A32: UI-027 | B32: SCR-011 | C32: 메모 탭 | D32: Tab | E32: 상담/메모 기록 탭 | F32: 메모 추가/수정/삭제, 시간순 정렬 | G32: FN-006 | H32: API-008 | I32: Tab + 메모 리스트 + 에디터 | M32: aria-label='메모 탭' | N32: 설계중 | P32: 회원 상세 | Q32: 회원 상세 조회 | R32: /api/v1/members/:id
A33: ▼ SCR-012 | B33: 회원 등록 (10개 요소) | C33: 10개 요소
A34: UI-028 | B34: SCR-012 | C34: 이름 입력 | D34: Input | E34: 회원 이름 입력 필드 | F34: 필수 항목, 한글 2~20자 | G34: FN-004 | H34: API-009 | I34: <input> + validation | K34: 한글 2~20자 | L34: 이름을 입력하세요 | M34: aria-required='true' | N34: 설계중 | P34: 회원 등록 | Q34: 회원 등록 | R34: /api/v1/members
A35: UI-029 | B35: SCR-012 | C35: 성별 선택 | D35: Radio | E35: 성별 선택 (남/여) | F35: 라디오 버튼 2개 | G35: FN-004 | H35: API-009 | I35: RadioGroup 컴포넌트 | K35: 필수 선택 | L35: 성별을 선택하세요 | M35: role='radiogroup' | N35: 설계중 | P35: 회원 등록 | Q35: 회원 등록 | R35: /api/v1/members
A36: UI-030 | B36: SCR-012 | C36: 생년월일 | D36: Input | E36: 생년월일 입력 (date picker) | F36: 달력 팝업 또는 직접 입력 | G36: FN-004 | H36: API-009 | I36: DatePicker 컴포넌트 | K36: 미래 날짜 불가 | L36: 올바른 날짜를 입력하세요 | M36: aria-label='생년월일' | N36: 설계중 | P36: 회원 등록 | Q36: 회원 등록 | R36: /api/v1/members
A37: UI-031 | B37: SCR-012 | C37: 연락처 입력 | D37: Input | E37: 연락처 입력 (자동 하이픈) | F37: 입력 시 자동 포맷 (010-xxxx-xxxx) | G37: FN-004 | H37: API-009 | I37: PhoneInput 컴포넌트 | K37: 전화번호 형식 검증, 중복 체크 | L37: 올바른 연락처를 입력하세요 | M37: aria-label='연락처' | N37: 설계중 | P37: 회원 등록 | Q37: 회원 등록 | R37: /api/v1/members
A38: UI-032 | B38: SCR-012 | C38: 이메일 입력 | D38: Input | E38: 이메일 주소 입력 | F38: 선택 항목 | G38: FN-004 | H38: API-009 | I38: <input type='email'> | K38: 이메일 형식 검증 | L38: 올바른 이메일을 입력하세요 | M38: aria-label='이메일' | N38: 설계중 | P38: 회원 등록 | Q38: 회원 등록 | R38: /api/v1/members
A39: UI-033 | B39: SCR-012 | C39: 주소 입력 | D39: Input | E39: 주소 검색 및 입력 | F39: 다음 주소 API 연동 | G39: FN-004 | H39: API-009 | I39: AddressSearch 컴포넌트 | K39: 최소 5자 이상 | L39: 주소를 입력하세요 | M39: aria-label='주소' | N39: 설계중 | P39: 회원 등록 | Q39: 회원 등록 | R39: /api/v1/members
A40: UI-034 | B40: SCR-012 | C40: 메모 입력 | D40: Textarea | E40: 관리자 메모 입력 | F40: 최대 500자, 글자수 카운터 | G40: FN-004 | H40: API-009 | I40: <textarea> + counter | K40: 최대 500자 | L40: 메모 입력을(를) 입력하세요 | M40: aria-label='메모' | N40: 설계중 | P40: 회원 등록 | Q40: 회원 등록 | R40: /api/v1/members
...

Sheet 기능명세서
A1: 기능 ID | B1: 기능명 | C1: 기능 분류 | D1: 플랫폼 | E1: 우선순위 | F1: 기능 설명 | G1: 상세 요구사항 | H1: 화면 ID | I1: 입력 항목 | J1: 출력 항목 | K1: 비즈니스 규칙 | L1: 예외 처리 | M1: Web 구현 사항 | N1: App 구현 사항 | O1: 관련 API ID | P1: 상태 | Q1: 담당자 | R1: [자동] 화면명 | S1: [자동] API 엔드포인트 | T1: 비고 | U1: [자동] 관련 UI 요소
A2: ▼ SCR-001 | B2: 로그인 (1개 기능)
A3: FN-001 | B3: 로그인 | C3: 인증 | D3: Web | E3: Critical | F3: Supabase Auth 기반 로그인 (signInWithPassword) + 평문 비밀번호 fallback. 지점 선택 포함. | G3: 1) Supabase Auth signInWithPassword({email}@spogym.local, password) 1차 시도 2) Auth 실패 시 기존 평문 비밀번호 fallback (마이그레이션 호환) 3) 지점 선택 필수 4) 로그인 유지 체크 시 localStorage 아이디 저장 5) onAuthStateChange 리스너로 세션 자동 관리 6) TOKEN_REFRESHED 시 토큰 자동 갱신, SIGNED_OUT 시 자동 로그아웃 | H3: SCR-001 | I3: 이메일, 비밀번호, 지점ID | J3: JWT 토큰, 사용자 정보, 권한 목록 | K3: 1) 5회 연속 실패 시 30분 계정 잠금 2) 비밀번호: 최소 8자, 영문+숫자+특수문자 조합 필수 3) 이전 3개 비밀번호 재사용 금지 4) 90일 경과 시 비밀번호 변경 권장 팝업 (강제 변경 or 건너뛰기) 5) 동시 세션 1개 제한 – 신규 로그인 시 기존 세션 강제 종료 6) 토큰 만료: 기본 2시간 / 로그인 유지 체크 시 7일 (refresh token) 7) 로그인 시 선택한 지점만 데이터 접근 허용 8) 탈퇴·비활성 계정 접근 불가 | L3: 계정 잠금: '5회 실패로 잠금. 30분 후 재시도 또는 비밀번호 찾기' 서버 오류: '일시적 오류. 잠시 후 다시 시도하세요' 탈퇴 계정: '탈퇴 처리된 계정입니다' 네트워크 오류: '인터넷 연결을 확인하세요' 지점 미선택: '지점을 선택해주세요' 잘못된 자격증명: '이메일 또는 비밀번호를 확인하세요' | M3: Supabase Auth + React Zustand 스토어 authStore.ts: initAuthListener() 세션 관리 비밀번호 변경: AppHeader 모달 → supabase.auth.updateUser() 감사로그: 로그인 실패/로그아웃 시 자동 기록 | O3: API-001 | P3: 개발완료 | R3: 로그인 | S3: /api/v1/auth/login | T3: Supabase Auth 전환 완료 (2026-03-12). 비밀번호 변경 모달 구현 (2026-03-13). 로그인 유지 + 세션 자동관리 + 감사로그 연동 | U3: 5
A4: ▼ SCR-002 | B4: 대시보드 (1개 기능)
A5: FN-002 | B5: 대시보드 통계 조회 | C5: 대시보드 | D5: Web | E5: Critical | F5: 지점별 핵심 KPI 대시보드 (회원/매출/출석 요약) | G5: 1) 총회원/활성/만료임박/만료 카운트 2) 오늘 생일 회원 리스트 3) 미납 회원 리스트 4) 만료 예정 회원 5) 당월 매출 차트 | H5: SCR-002 | I5: 지점ID (JWT에서 추출) | J5: 통계 데이터, 리스트, 차트 데이터 | K5: 1) 통계 카드: 페이지 진입 시 + 5분 주기 자동 갱신 2) 만료임박: D-7 이내 카운트, D-3 이내 긴급(빨간색), D-0 만료 처리 3) 미납: 결제예정일 초과 + 미결제 → 미납, 30일 초과 시 장기미납 표시 4) 차트: 페이지 진입 시 1회 조회 (BarChart/PieChart/LineChart) 5) 통계 카드 클릭 시 해당 목록으로 이동 (status 필터 자동 적용) 6) 지점별 데이터 격리 – branch_id 기준 필터 필수 7) 알림 리스트: 실시간 polling 30초 주기 | L5: 데이터 로드 실패: 각 섹션 독립 에러 표시 + 재시도 버튼 빈 데이터: '아직 데이터가 없습니다' Empty State UI 지점 미설정: '지점 정보를 설정하세요' 안내 네트워크 단절: 마지막 갱신 시각 표시 + 수동 갱신 버튼 | M5: TanStack Query (5분 refetchInterval, staleTime 설정) Recharts – BarChart, PieChart, LineChart useNavigate() + query string으로 필터 목록 이동 Skeleton 로딩 UI (카드/차트 영역) RefreshCw 아이콘 수동 갱신 버튼 date-fns 날짜 계산 (D-day) | O5: API-003 | P5: 개발완료 | R5: 대시보드 | S5: /api/v1/dashboard/stats | T5: 실 데이터 차트 연동 완료. soft delete 필터 적용. 클릭 네비게이션 구현 (2026-03-13) | U5: 8
A6: ▼ SCR-010 | B6: 회원 목록 (2개 기능)
A7: FN-003 | B7: 회원 목록 조회/검색/필터 | C7: 회원관리 | D7: Web | E7: Critical | F7: 회원 검색, 필터, 페이지네이션 목록 조회 | G7: 1) 이름/연락처/회원번호 검색 (300ms debounce) 2) 상태/성별/담당자 필터 조합 3) 컬럼 정렬 4) 페이지당 20/50/100건 5) 엑셀 다운로드 | H7: SCR-010 | I7: 검색어, 필터 조건, 페이지 번호, 정렬 기준 | J7: 회원 목록 (이름/연락처/상태/이용권/담당자) | K7: 1) 검색: 이름 부분일치(2자 이상), 연락처 숫자만 추출 후 부분일치, 회원번호 완전일치 2) 검색 debounce 300ms 적용 3) 모든 필터는 AND 조합, 탭 필터와 상세 필터 동시 적용 4) 회원 상태: 활성/만료/예정/임박(D-30 이내)/홀딩/미등록 정의 5) 일괄 처리 최대 100명 동시 선택 6) 삭제 회원 기본 미표시, 옵션으로 표시 전환 가능 7) 권한별 조회 범위 제한 (FC: 담당 회원만, 스태프: 조회만) | L7: 검색 결과 없음: '조건에 맞는 회원이 없습니다' Empty State 필터 오류: 필터 초기화 버튼 항상 노출 API 오류: '회원 목록을 불러오지 못했습니다. 재시도' 버튼 일괄 처리 100명 초과: '최대 100명까지 선택 가능합니다' 권한 없음: 해당 기능 버튼 비활성화 처리 | M7: TanStack Query – GET /api/v1/members (캐싱) useDebounce() 훅 (300ms) DataTable 컴포넌트 (정렬/페이지네이션/다중선택) URL 쿼리 파라미터로 필터 상태 동기화 xlsx 라이브러리 – 엑셀 다운로드 Checkbox 다중선택 + 일괄 처리 드롭다운 | O7: API-007 | P7: 개발완료 | R7: 회원 목록 | S7: /api/v1/members | T7: 서버사이드 페이지네이션/정렬/필터 완료. 상태 변경 모달 (window.prompt→셀렉트) 개선 (2026-03-13) | U7: 8
A8: FN-004 | B8: 회원 등록 | C8: 회원관리 | D8: Web | E8: Critical | F8: 신규 회원 등록 | G8: 1) 필수: 이름, 성별, 연락처 2) 선택: 이메일, 주소, 생년월일, 메모 3) 담당 FC 배정 4) 연락처 중복 체크 | H8: SCR-010 | I8: 이름, 성별, 생년월일, 연락처, 이메일, 주소, 메모, 담당자ID | J8: 등록된 회원 정보 | K8: 1) 필수 입력: 이름(2~20자, 한글/영문), 성별, 연락처(010-XXXX-XXXX), 회원구분 2) 연락처: 동일 지점 내 중복 불가 (API 중복확인) 3) 회원번호 자동 생성: 지점코드-YYMMDD-순번 4) 출석번호 자동 생성: 4자리 랜덤 (중복 체크) 5) 기본 상태: '미등록' (이용권 구매 시 '활성'으로 자동 전환) 6) 프로필 사진: JPG/PNG, 5MB 이하 7) 생년월일: 미래 날짜 입력 불가 8) 이메일: RFC 5322 형식 검증 | L8: 연락처 중복: '이미 등록된 연락처입니다 (지점 내)' 이름 형식 오류: '이름은 2~20자 한글 또는 영문으로 입력하세요' 연락처 형식 오류: '010-XXXX-XXXX 형식으로 입력하세요' 파일 크기 초과: '이미지 파일은 5MB 이하만 업로드 가능합니다' 저장 실패: '회원 등록에 실패했습니다. 다시 시도하세요' 취소 시: '변경사항이 있습니다. 정말 나가시겠습니까?' 확인 다이얼로그 | M8: React Hook Form + Zod 스키마 (2단계 폼) useMutation – POST /api/v1/members Kakao 주소 API 연동 (주소 검색 버튼) 이미지 업로드 – FileReader + presigned URL 연락처 입력 자동 하이픈 포맷팅 취소 확인 useBlocker() (React Router v6) | O8: API-009 | P8: 개발완료 | R8: 회원 목록 | S8: /api/v1/members | U8: 8
A9: ▼ SCR-011 | B9: 회원 상세 (2개 기능)
