Workbook

Sheet IA(정보구조)
A1: Depth 1 | B1: Depth 2 | C1: Depth 3 | D1: 화면 ID | E1: 화면명 | F1: 플랫폼 | G1: 화면 URL/경로 | H1: 로그인 필요 | I1: 권한 | J1: 설명 | K1: 상태 | L1: 비고
A2: 인증 | B2: 로그인 | D2: SCR-001 | E2: 로그인 | F2: Web | G2: /login | H2: N | I2: 비회원 | J2: 이메일/비밀번호 로그인 화면. 지점 선택 포함 | K2: 확정
A3: 대시보드 | B3: 메인 | D3: SCR-002 | E3: 대시보드 | F3: Web | G3: / | H3: Y | I3: 전체 | J3: 지점별 핵심 KPI 요약 대시보드 | K3: 확정
A4: 회원관리 | B4: 회원 | D4: SCR-010 | E4: 회원 목록 | F4: Web | G4: /members | H4: Y | I4: 매니저 이상 | J4: 회원 검색/필터/목록 조회 | K4: 확정
A5: 회원관리 | B5: 회원 | D5: SCR-011 | E5: 회원 상세 | F5: Web | G5: /members/detail | H5: Y | I5: 매니저 이상 | J5: 회원 프로필, 이용권, 출석, 결제, 체성분, 메모 탭 | K5: 확정
A6: 회원관리 | B6: 회원 | D6: SCR-012 | E6: 회원 등록 | F6: Web | G6: /members/new | H6: Y | I6: 매니저 이상 | J6: 신규 회원 등록 폼 | K6: 확정
A7: 회원관리 | B7: 회원 | D7: SCR-013 | E7: 회원 수정 | F7: Web | G7: /members/edit | H7: Y | I7: 매니저 이상 | J7: 기존 회원 정보 수정 폼 | K7: 확정
A8: 회원관리 | B8: 체성분 | D8: SCR-014 | E8: 체성분 분석 | F8: Web | G8: /body-composition | H8: Y | I8: FC 이상 | J8: 체성분 측정 기록 및 변화 추이 차트 | K8: 확정
A9: 출석/일정 | B9: 출석 | D9: SCR-020 | E9: 출석 기록 | F9: Web | G9: /attendance | H9: Y | I9: 스태프 이상 | J9: 회원 출석 현황 조회 (일별/주별/월별) | K9: 확정
A10: 출석/일정 | B10: 일정 | D10: SCR-021 | E10: 일정 관리 | F10: Web | G10: /calendar | H10: Y | I10: 스태프 이상 | J10: PT/GX 일정 캘린더 뷰 | K10: 확정
A11: 매출/결제 | B11: 매출 | D11: SCR-030 | E11: 매출 조회 | F11: Web | G11: /sales | H11: Y | I11: 매니저 이상 | J11: 매출 현황 조회, 필터, 통계 요약 | K11: 확정
A12: 매출/결제 | B12: POS | D12: SCR-031 | E12: POS | F12: Web | G12: /pos | H12: Y | I12: 스태프 이상 | J12: POS 상품 선택 및 장바구니 | K12: 확정
A13: 매출/결제 | B13: POS | D13: SCR-032 | E13: POS 결제 | F13: Web | G13: /pos/payment | H13: Y | I13: 스태프 이상 | J13: 결제 수단 선택 및 결제 처리 | K13: 확정
... A34: 설정 | B34: 지점 | D34: SCR-094 | E34: 지점 관리 | F34: Web | G34: /branches | H34: Y | I34: 최고관리자 | J34: 지점 CRUD 및 멀티테넌트 관리 | K34: 확정

Sheet 사용자 스토리
A1: 스토리 ID | B1: 에픽 | C1: 사용자 유형 | D1: 사용자 스토리 | E1: 인수 조건 | F1: 화면 ID | G1: 우선순위 | H1: 사이즈 | I1: 담당자 | J1: 상태 | K1: [자동] 화면명 | L1: [자동] 기능 수 | M1: 비고
A2: US-001 | B2: 인증 | C2: 비회원 | D2: 비회원으로서 이메일/비밀번호로 로그인하여 시스템에 접근하고 싶다 | E2: 1) 올바른 이메일/비밀번호 입력 시 대시보드로 이동 2) 5회 실패 시 계정 잠금 3) 지점 선택 후 해당 지점 데이터만 표시 | F2: SCR-001 | G2: Critical | H2: S | I2: 개발자1 | J2: To Do | K2: 로그인 | L2: 1
A3: US-002 | B3: 대시보드 | C3: 센터장 | D3: 센터장으로서 대시보드에서 지점 핵심 KPI를 한눈에 파악하고 싶다 | E3: 1) 총회원/활성/만료임박/만료 회원 수 카드 표시 2) 오늘 생일 회원 리스트 3) 미납 회원 리스트 4) 당월 매출 차트 | F3: SCR-002 | G3: Critical | H3: M | I3: 개발자1 | J3: To Do | K3: 대시보드 | L3: 1
A4: US-003 | B4: 회원관리 | C4: 매니저 | D4: 매니저로서 회원을 검색/필터하여 원하는 회원을 빠르게 찾고 싶다 | E4: 1) 이름/연락처/회원번호로 검색 2) 상태/성별/담당자 필터 3) 엑셀 다운로드 가능 | F4: SCR-010 | G4: Critical | H4: M | I4: 개발자1 | J4: To Do | K4: 회원 목록 | L4: 2
A5: US-004 | B5: 회원관리 | C5: 매니저 | D5: 매니저로서 신규 회원을 등록하고 싶다 | E5: 1) 필수 항목(이름/연락처/성별) 입력 2) 담당 FC 배정 3) 등록 완료 시 회원 상세로 이동 | F5: SCR-012 | G5: Critical | H5: M | I5: 개발자1 | J5: To Do | K5: 회원 등록 | L5: 0
A6: US-005 | B6: 회원관리 | C6: 매니저 | D6: 매니저로서 회원 상세 정보와 이용 이력을 확인하고 싶다 | E6: 1) 프로필/이용권/출석/결제/체성분/메모 탭 구성 2) 이용권 만료일 강조 표시 3) 출석 히트맵 | F6: SCR-011 | G6: High | H6: L | I6: 개발자1 | J6: To Do | K6: 회원 상세 | L6: 2
A7: US-006 | B7: 회원관리 | C7: 매니저 | D7: 매니저로서 회원 정보를 수정하고 싶다 | E7: 1) 기존 정보 프리필 2) 변경 이력 자동 기록 3) 담당자 변경 가능 | F7: SCR-013 | G7: High | H7: S | I7: 개발자1 | J7: To Do | K7: 회원 수정 | L7: 0
A8: US-007 | B8: 회원관리 | C8: FC | D8: FC로서 회원의 체성분 측정 결과를 기록하고 변화 추이를 분석하고 싶다 | E8: 1) 체중/골격근/체지방률 등 입력 2) 측정일 기준 변화 차트 3) 목표 대비 달성률 표시 | F8: SCR-014 | G8: High | H8: M | I8: 개발자2 | J8: To Do | K8: 체성분 분석 | L8: 1
A9: US-008 | B9: 출석관리 | C9: 스태프 | D9: 스태프로서 회원의 출석 현황을 조회하고 싶다 | E9: 1) 일별/주별/월별 출석 조회 2) 출석 유형(일반/PT/GX) 구분 3) 타지점 출석 표시 | F9: SCR-020 | G9: High | H9: M | I9: 개발자2 | J9: To Do | K9: 출석 기록 | L9: 1
A10: US-009 | B10: 출석관리 | C10: 스태프 | D10: 스태프로서 PT/GX 일정을 캘린더로 관리하고 싶다 | E10: 1) 월/주/일 캘린더 뷰 2) 드래그앤드롭 일정 변경 3) 트레이너별 필터 | F10: SCR-021 | G10: High | H10: L | I10: 개발자2 | J10: To Do | K10: 일정 관리 | L10: 1
A11: US-010 | B11: 매출관리 | C11: 매니저 | D11: 매니저로서 매출 현황을 조회하고 통계를 확인하고 싶다 | E11: 1) 기간별 매출 필터 2) 유형별(이용권/PT/상품) 분류 3) 총매출/현금/카드/마일리지 요약 4) 엑셀 다운로드 | F11: SCR-030 | G11: Critical | H11: L | I11: 개발자1 | J11: To Do | K11: 매출 조회 | L11: 2
A12: US-011 | B12: 매출관리 | C12: 스태프 | D12: 스태프로서 POS에서 상품을 선택하고 결제를 처리하고 싶다 | E12: 1) 카테고리별 상품 그리드 2) 장바구니 담기/수량 변경 3) 현금/카드/마일리지 복합결제 4) 영수증 출력 | F12: SCR-031 | G12: Critical | H12: XL | I12: 개발자1 | J12: To Do | K12: POS | L12: 0
A13: US-012 | B13: 상품관리 | C13: 매니저 | D13: 매니저로서 상품 목록을 조회하고 관리하고 싶다 | E13: 1) 카테고리별 필터 2) 키오스크 노출 여부 토글 3) 상품 상태(판매중/중지) 관리 | F13: SCR-040 | G13: High | H13: M | I13: 개발자2 | J13: To Do | K13: 상품 목록 | L13: 2
... A31: US-030 | B31: 설정/권한 | C31: 최고관리자 | D31: 최고관리자로서 지점을 추가/관리하고 싶다 | E31: 1) 지점 CRUD 2) 지점별 독립 데이터 3) 지점 간 회원 이동 처리 | F31: SCR-094 | G31: Critical | H31: L | I31: 개발자1 | J31: To Do | K31: 지점 관리 | L31: 0

Sheet 화면설계서
A1: 화면 ID | B1: 화면명 | C1: 플랫폼 | D1: 화면 경로 | E1: 화면 설명 | F1: [자동] UI 요소 목록 | G1: 인터랙션 정의 | H1: Web 특이사항 | I1: App 특이사항 | J1: 진입 경로 | K1: 이동 가능 화면 | L1: 에러 화면 정의 | M1: 접근성 체크 | N1: 반응형 체크 (Web) | O1: 가로/세로 모드 (App) | P1: 디자인 시안 링크 | Q1: 상태 | R1: 담당자 | S1: [자동] 관련 기능 수 | T1: [자동] 관련 TC 수 | U1: [자동] 관련 API 수 | V1: 비고 | W1: [자동] UI 요소 수
A2: SCR-001 | B2: 로그인 | C2: Web | D2: /login | E2: 이메일/비밀번호 기반 로그인 화면. 지점 선택 드롭다운 포함 | F2: UI-001, UI-002, UI-003, UI-004, UI-005 | G2: 비밀번호 마스킹 토글, Enter키 로그인, 지점 선택 시 로고 변경 | H2: JWT 토큰 기반 세션 관리 | J2: URL 직접 접근, 세션 만료 시 리다이렉트 | K2: SCR-002 (대시보드) | L2: 이메일 미입력: '이메일을 입력하세요' 비밀번호 오류: '비밀번호가 올바르지 않습니다' 계정 잠금: '5회 실패로 잠금됨' | M2: Tab 이동 순서, aria-label | N2: 1024px 이상 중앙 정렬 | Q2: 확정 | R2: 개발팀 | S2: 1 | T2: 6 | U2: 1 | W2: 5
A3: SCR-002 | B3: 대시보드 | C3: Web | D3: / | E3: 지점별 핵심 KPI 대시보드. 회원/매출/출석 통계 카드 + 알림 리스트 | F3: UI-006, UI-007, UI-008, UI-009, UI-010, UI-011, UI-012, UI-013 | G3: 통계 카드 클릭 시 상세 이동, 차트 호버 툴팁, 기간 필터 | H3: 반응형 그리드 (2열→1열) | J3: SCR-001 (로그인 후) | K3: SCR-010, SCR-030, SCR-020 | L3: 데이터 로딩 실패: '데이터를 불러올 수 없습니다' + 재시도 버튼 | M3: 차트 alt-text | N3: 1280px 이상 4열 카드 | Q3: 확정 | R3: 개발팀 | S3: 1 | T3: 3 | U3: 5 | W3: 8
A4: SCR-010 | B4: 회원 목록 | C4: Web | D4: /members | E4: 회원 검색, 필터, 페이지네이션이 포함된 목록 화면 | F4: UI-014, UI-015, UI-016, UI-017, UI-018, UI-019, UI-020, UI-021 | G4: 실시간 검색, 필터 조합, 정렬, 페이지네이션, 엑셀 다운로드 | H4: 테이블 가로스크롤 (좁은 화면) | J4: GNB 메뉴, SCR-002 바로가기 | K4: SCR-011, SCR-012 | L4: 검색 결과 없음: '조건에 맞는 회원이 없습니다' 로딩 실패: 스켈레톤 + 재시도 | M4: 테이블 aria-label, 스크린리더 페이지 안내 | N4: 테이블 반응형 스크롤 | Q4: 확정 | R4: 개발팀 | S4: 2 | T4: 4 | U4: 2 | W4: 8
A5: SCR-011 | B5: 회원 상세 | C5: Web | D5: /members/detail | E5: 회원 프로필 + 탭(이용권/출석/결제/체성분/메모) 구성 | F5: UI-022, UI-023, UI-024, UI-025, UI-026, UI-027 | G5: 탭 전환, 이용권 만료일 강조, 출석 히트맵, 결제 내역 페이지네이션 | H5: 탭 URL 파라미터 유지 | J5: SCR-010 회원 클릭 | K5: SCR-013, SCR-014, SCR-010 | L5: 회원 미존재: 404 페이지 데이터 로딩 실패: 탭별 에러 표시 | M5: 탭 키보드 네비게이션 | N5: 탭 세로 배치 (좁은 화면) | Q5: 확정 | R5: 개발팀 | S5: 2 | T5: 1 | U5: 2 | W5: 6
A6: SCR-012 | B6: 회원 등록 | C6: Web | D6: /members/new | E6: 신규 회원 등록 폼. 필수/선택 항목 구분 | F6: UI-028, UI-029, UI-030, UI-031, UI-032, UI-033, UI-034, UI-035, UI-036, UI-037 | G6: 실시간 유효성 검사, 연락처 자동 포맷, 주소 검색 API 연동 | H6: 폼 상태 유지 (뒤로가기 시) | J6: SCR-010 '회원등록' 버튼 | K6: SCR-011 (등록 완료 후) | L6: 필수 항목 미입력: 필드 하단 에러 메시지 중복 연락처: '이미 등록된 연락처입니다' 서버 오류: 토스트 알림 | M6: 필수 항목 aria-required | N6: 폼 1열 배치 | Q6: 확정 | R6: 개발팀 | S6: 0 | T6: 4 | U6: 1 | W6: 10
A7: SCR-013 | B7: 회원 수정 | C7: Web | D7: /members/edit | E7: 기존 회원 정보 수정 폼. 기존 데이터 프리필 | F7: UI-119, UI-120 | G7: 변경사항 비교 표시, 저장 전 확인 모달 | H7: 변경 이력 자동 기록 | J7: SCR-011 '수정' 버튼 | K7: SCR-011 (저장 후) | L7: 변경 없이 저장: '변경된 내용이 없습니다' 서버 오류: 토스트 알림 | M7: 폼 접근성 동일 | N7: 폼 1열 배치 | Q7: 확정 | R7: 개발팀 | S7: 0 | T7: 1 | U7: 1 | W7: 2
A8: SCR-014 | B8: 체성분 분석 | C8: Web | D8: /body-composition | E8: 회원별 체성분 측정 기록 입력 및 변화 추이 차트 | F8: UI-121, UI-122 | G8: 측정값 입력 폼, 날짜별 라인 차트, 목표 대비 게이지 | H8: 차트 라이브러리 (Recharts) | J8: SCR-011 '체성분' 탭 | K8: SCR-011 | L8: 측정 데이터 없음: '아직 측정 기록이 없습니다' 입력 범위 초과: 경고 토스트 | M8: 차트 alt-text, 데이터 테이블 대체 | N8: 차트 반응형 | Q8: 확정 | R8: 개발팀 | S8: 1 | T8: 0 | U8: 0 | W8: 2
A9: SCR-020 | B9: 출석 기록 | C9: Web | D9: /attendance | E9: 회원 출석 현황 조회. 일별/주별/월별 뷰 전환 | F9: UI-123, UI-124 | G9: 날짜 필터, 출석 유형 필터, 타지점 출석 표시 | H9: 캘린더 컴포넌트 | J9: GNB 메뉴 | K9: SCR-011 (회원 클릭) | L9: 데이터 없음: '해당 기간 출석 기록이 없습니다' | M9: 날짜 선택 키보드 접근 | N9: 테이블 반응형 | Q9: 확정 | R9: 개발팀 | S9: 1 | T9: 1 | U9: 2 | W9: 2
A10: SCR-021 | B10: 일정 관리 | C10: Web | D10: /calendar | E10: PT/GX 일정 캘린더. 월/주/일 뷰 전환 | F10: UI-125, UI-126 | G10: 드래그앤드롭 일정 이동, 클릭 상세 모달, 트레이너 필터 | H10: FullCalendar 라이브러리 | J10: GNB 메뉴 | K10: SCR-011 (회원 연결) | L10: 일정 충돌: '해당 시간에 이미 예약이 있습니다' 과거 일정 수정 불가 | M10: 캘린더 키보드 네비게이션 | N10: 뷰 자동 전환 (주→일) | Q10: 확정 | R10: 개발팀 | S10: 1 | T10: 0 | U10: 0 | W10: 2
A11: SCR-030 | B11: 매출 조회 | C11: Web | D11: /sales | E11: 매출 현황 조회. 기간/유형/상태 필터 + 통계 요약 카드 | F11: UI-038, UI-039, UI-040, UI-041, UI-042, UI-043, UI-044 | G11: 날짜 범위 선택, 유형 필터, 상태 필터, 통계 카드 갱신, 엑셀 다운로드 | H11: 금액 포맷 (천단위 콤마) | J11: GNB 메뉴, SCR-002 매출 카드 | K11: SCR-031 (POS 이동) | L11: 데이터 없음: '해당 기간 매출이 없습니다' 다운로드 실패: 재시도 안내 | M11: 금액 스크린리더 읽기 | N11: 통계 카드 2열→1열 | Q11: 확정 | R11: 개발팀 | S11: 2 | T11: 2 | U11: 2 | W11: 7
A12: SCR-031 | B12: POS | C12: Web | D12: /pos | E12: POS 상품 선택 화면. 카테고리 탭 + 상품 그리드 + 장바구니 | F12: UI-045, UI-046, UI-047, UI-048 | G12: 카테고리 탭 전환, 상품 클릭 시 장바구니 추가, 수량 조절, 삭제 | H12: 2컬럼 레이아웃 (상품 | 장바구니) | J12: GNB 메뉴, SCR-030 | K12: SCR-032 (결제 진행) | L12: 장바구니 비어있음: '상품을 선택해주세요' 재고 없음: 상품 비활성화 | M12: 상품 그리드 키보드 선택 | N12: 장바구니 하단 고정 | Q12: 확정 | R12: 개발팀 | S12: 0 | T12: 1 | U12: 0 | W12: 4
A13: SCR-032 | B13: POS 결제 | C13: Web | D13: /pos/payment | E13: 결제 수단 선택 및 결제 처리. 복합결제 지원 | F13: UI-049, UI-050, UI-051, UI-052 | G13: 결제수단 선택, 금액 입력, 마일리지 사용, 결제 확인 모달 | H13: 결제 API 연동 | J13: SCR-031 '결제' 버튼 | K13: SCR-030 (결제 완료 후) | L13: 결제 실패: '결제에 실패했습니다. 다시 시도해주세요' 잔액 부족: 안내 메시지 | M13: 금액 입력 접근성 | N13: 모달 팝업 | Q13: 확정 | R13: 개발팀 | S13: 1 | T13: 3 | U13: 1 | W13: 4
... A34: SCR-094 | B34: 지점 관리 | C34: Web | D34: /branches | E34: 지점 CRUD. 멀티테넌트 관리 | F34: UI-079, UI-080, UI-081 | G34: 지점 카드/테이블 뷰 전환, 지점 추가 모달, 데이터 초기화 | H34: 카드/테이블 토글 | J34: GNB 메뉴 (최고관리자만) | K34: 지점 상세 모달 | L34: 지점 삭제 시 데이터 존재: '소속 데이터가 있어 삭제 불가' | M34: 카드/테이블 접근성 | N34: 카드 반응형 | Q34: 확정 | R34: 개발팀 | S34: 0 | T34: 2 | U34: 1 | W34: 3

Sheet UI 요소 상세
A1: 요소 ID | B1: 화면 ID | C1: 요소명 | D1: 요소 유형 | E1: 요소 설명 | F1: 인터랙션 정의 | G1: 기능 ID | H1: API ID | I1: Web 구현 | J1: App 구현 | K1: 유효성 검사 | L1: 에러 메시지 | M1: 접근성 | N1: 상태 | O1: 담당자 | P1: [자동] 화면명 | Q1: [자동] 기능명 | R1: [자동] API 엔드포인트 | S1: 비고
A2: ▼ SCR-001 | B2: 로그인 | C2: 5개 요소
A3: UI-001 | B3: SCR-001 | C3: 이메일 입력 | D3: Input | E3: 로그인 이메일 주소 입력 필드 | F3: 포커스 시 라벨 상단 이동, 실시간 이메일 형식 검증 | G3: FN-001 | H3: API-001 | I3: <input type='email'> + 실시간 validation | K3: 이메일 형식 검증 (regex) | L3: 올바른 이메일 주소를 입력하세요 | M3: aria-label='이메일' | N3: 설계중 | P3: 로그인 | Q3: 로그인 | R3: /api/v1/auth/login
A4: UI-002 | B4: SCR-001 | C4: 비밀번호 입력 | D4: Input | E4: 로그인 비밀번호 입력 필드 | F4: 마스킹 토글 버튼, Enter키 로그인 트리거 | G4: FN-001 | H4: API-001 | I4: <input type='password'> + visibility toggle | K4: 최소 1자 이상 | L4: 비밀번호를 입력하세요 | M4: aria-label='비밀번호' | N4: 설계중 | P4: 로그인 | Q4: 로그인 | R4: /api/v1/auth/login
A5: UI-003 | B5: SCR-001 | C5: 지점 선택 | D5: Select | E5: 로그인 시 접근할 지점 선택 드롭다운 | F5: 선택 시 지점 로고/색상 변경 | G5: FN-001 | H5: API-001 | I5: <select> 커스텀 드롭다운 | K5: 필수 선택 | L5: 지점을 선택하세요 | M5: aria-label='지점 선택' | N5: 설계중 | P5: 로그인 | Q5: 로그인 | R5: /api/v1/auth/login
A6: UI-004 | B6: SCR-001 | C6: 로그인 버튼 | D6: Button | E6: 로그인 실행 버튼 | F6: 클릭/Enter 시 로그인 API 호출, 로딩 스피너 | G6: FN-001 | H6: API-001 | I6: <button> + loading state | K6: 이메일/비밀번호/지점 모두 입력 시 활성화 | L6: 로그인에 실패했습니다 | M6: aria-label='로그인' | N6: 설계중 | P6: 로그인 | Q6: 로그인 | R6: /api/v1/auth/login
A7: UI-005 | B7: SCR-001 | C7: 비밀번호 찾기 링크 | D7: Link | E7: 비밀번호 재설정 페이지 이동 링크 | F7: 클릭 시 비밀번호 찾기 모달 오픈 | I7: <a> + 모달 트리거 | M7: aria-label='비밀번호 찾기' | N7: 설계중 | P7: 로그인 | Q7: =IFERROR(VLOOKUP(G7,기능명세서!A:B,2,FALSE()),"") | R7: =IFERROR(VLOOKUP(H7,API명세서!A:D,4,FALSE()),"")
A8: ▼ SCR-002 | B8: 대시보드 | C8: 8개 요소
A9: UI-006 | B9: SCR-002 | C9: 총회원 통계 카드 | D9: Card | E9: 전체 회원 수 표시 카드 | F9: 클릭 시 SCR-010 이동, 전일 대비 증감 표시 | G9: FN-002 | H9: API-003 | I9: Card 컴포넌트 + 숫자 애니메이션 | M9: aria-label='총 회원 수' | N9: 설계중 | P9: 대시보드 | Q9: 대시보드 통계 조회 | R9: /api/v1/dashboard/stats
A10: UI-007 | B10: SCR-002 | C10: 활성회원 통계 카드 | D10: Card | E10: 활성(이용중) 회원 수 카드 | F10: 클릭 시 SCR-010 활성 필터 이동 | G10: FN-002 | H10: API-003 | I10: Card 컴포넌트 | M10: aria-label='활성 회원 수' | N10: 설계중 | P10: 대시보드 | Q10: 대시보드 통계 조회 | R10: /api/v1/dashboard/stats
A11: UI-008 | B11: SCR-002 | C11: 만료임박 통계 카드 | D11: Card | E11: 7일 내 만료 예정 회원 수 카드 | F11: 클릭 시 SCR-010 만료임박 필터 이동, 경고 색상 | G11: FN-002 | H11: API-006 | I11: Card 컴포넌트 + 경고 스타일 | M11: aria-label='만료 임박 회원' | N11: 설계중 | P11: 대시보드 | Q11: 대시보드 통계 조회 | R11: /api/v1/dashboard/expiring-members
A12: UI-009 | B12: SCR-002 | C12: 만료회원 통계 카드 | D12: Card | E12: 이용권 만료된 회원 수 카드 | F12: 클릭 시 SCR-010 만료 필터 이동 | G12: FN-002 | H12: API-003 | I12: Card 컴포넌트 | M12: aria-label='만료 회원 수' | N12: 설계중 | P12: 대시보드 | Q12: 대시보드 통계 조회 | R12: /api/v1/dashboard/stats
A13: UI-010 | B13: SCR-002 | C13: 생일회원 리스트 | D13: List | E13: 오늘 생일인 회원 목록 | F13: 회원명 클릭 시 SCR-011 이동 | G13: FN-002 | H13: API-004 | I13: 리스트 컴포넌트 (최대 5명) | M13: aria-label='오늘 생일 회원' | N13: 설계중 | P13: 대시보드 | Q13: 대시보드 통계 조회 | R13: /api/v1/dashboard/birthday-members
A14: UI-011 | B14: SCR-002 | C14: 미납회원 리스트 | D14: List | E14: 미납 내역이 있는 회원 목록 | F14: 회원명 클릭 시 SCR-011 이동, 미납 금액 표시 | G14: FN-002 | H14: API-005 | I14: 리스트 컴포넌트 + 금액 강조 | M14: aria-label='미납 회원' | N14: 설계중 | P14: 대시보드 | Q14: 대시보드 통계 조회 | R14: /api/v1/dashboard/unpaid-members
A15: UI-012 | B15: SCR-002 | C15: 만료예정 리스트 | D15: List | E15: 7일 내 만료 예정 회원 목록 | F15: 회원명 클릭 시 SCR-011 이동, D-day 표시 | G15: FN-002 | H15: API-006 | I15: 리스트 컴포넌트 + D-day 배지 | M15: aria-label='만료 예정 회원' | N15: 설계중 | P15: 대시보드 | Q15: 대시보드 통계 조회 | R15: /api/v1/dashboard/expiring-members
A16: UI-013 | B16: SCR-002 | C16: 매출 차트 | D16: Card | E16: 당월 매출 추이 라인 차트 | F16: 호버 시 일별 금액 툴팁, 기간 필터 | G16: FN-002 | H16: API-003 | I16: Recharts LineChart | M16: 차트 데이터 테이블 대체 제공 | N16: 설계중 | P16: 대시보드 | Q16: 대시보드 통계 조회 | R16: /api/v1/dashboard/stats
A17: ▼ SCR-010 | B17: 회원 목록 | C17: 8개 요소
A18: UI-014 | B18: SCR-010 | C18: 검색바 | D18: Input | E18: 회원 이름/연락처/번호 검색 입력 | F18: 실시간 검색 (300ms debounce), 검색 아이콘 | G18: FN-003 | H18: API-007 | I18: SearchInput 컴포넌트 | K18: 최소 2자 이상 | L18: 검색어를 입력하세요 | M18: aria-label='회원 검색' | N18: 설계중 | P18: 회원 목록 | Q18: 회원 목록 조회/검색/필터 | R18: /api/v1/members
A19: UI-015 | B19: SCR-010 | C19: 상태 필터 | D19: Select | E19: 회원 상태(활성/만료/휴회/탈퇴) 필터 | F19: 멀티 선택 가능, 선택 시 즉시 필터 적용 | G19: FN-003 | H19: API-007 | I19: MultiSelect 컴포넌트 | K19: 1개 이상 선택 필수 | L19: 상태 필터을(를) 선택하세요 | M19: aria-label='상태 필터' | N19: 설계중 | P19: 회원 목록 | Q19: 회원 목록 조회/검색/필터 | R19: /api/v1/members
A20: UI-016 | B20: SCR-010 | C20: 성별 필터 | D20: Select | E20: 성별(전체/남/여) 필터 | F20: 단일 선택, 즉시 적용 | G20: FN-003 | H20: API-007 | I20: Select 컴포넌트 | K20: 1개 이상 선택 필수 | L20: 성별 필터을(를) 선택하세요 | M20: aria-label='성별 필터' | N20: 설계중 | P20: 회원 목록 | Q20: 회원 목록 조회/검색/필터 | R20: /api/v1/members
A21: UI-017 | B21: SCR-010 | C21: 담당자 필터 | D21: Select | E21: 담당 FC 필터 | F21: 단일 선택, 즉시 적용 | G21: FN-003 | H21: API-007 | I21: Select 컴포넌트 | K21: 1개 이상 선택 필수 | L21: 담당자 필터을(를) 선택하세요 | M21: aria-label='담당자 필터' | N21: 설계중 | P21: 회원 목록 | Q21: 회원 목록 조회/검색/필터 | R21: /api/v1/members
A22: UI-018 | B22: SCR-010 | C22: 회원 테이블 | D22: List | E22: 회원 목록 데이터 테이블 | F22: 행 클릭 시 SCR-011 이동, 컬럼 정렬, 행 호버 | G22: FN-003 | H22: API-007 | I22: DataTable 컴포넌트 + 정렬/페이지네이션 | M22: aria-label='회원 목록 테이블' | N22: 설계중 | P22: 회원 목록 | Q22: 회원 목록 조회/검색/필터 | R22: /api/v1/members
A23: UI-019 | B23: SCR-010 | C23: 페이지네이션 | D23: Nav | E23: 테이블 하단 페이지 네비게이션 | F23: 페이지 이동, 페이지당 행 수 선택 | G23: FN-003 | H23: API-007 | I23: Pagination 컴포넌트 | M23: aria-label='페이지 이동' | N23: 설계중 | P23: 회원 목록 | Q23: 회원 목록 조회/검색/필터 | R23: /api/v1/members
A24: UI-020 | B24: SCR-010 | C24: 엑셀 다운로드 | D24: Button | E24: 현재 필터 결과 엑셀 다운로드 | F24: 클릭 시 xlsx 파일 다운로드, 로딩 표시 | G24: FN-003 | H24: API-007 | I24: 다운로드 버튼 + 로딩 스피너 | M24: aria-label='엑셀 다운로드' | N24: 설계중 | P24: 회원 목록 | Q24: 회원 목록 조회/검색/필터 | R24: /api/v1/members
A25: UI-021 | B25: SCR-010 | C25: 회원등록 버튼 | D25: Button | E25: 신규 회원 등록 페이지 이동 버튼 | F25: 클릭 시 SCR-012 이동 | G25: FN-004 | I25: Primary Button | M25: aria-label='회원 등록' | N25: 설계중 | P25: 회원 목록 | Q25: 회원 등록 | R25: =IFERROR(VLOOKUP(H25,API명세서!A:D,4,FALSE()),"")
A26: ▼ SCR-011 | B26: 회원 상세 | C26: 6개 요소
A27: UI-022 | B27: SCR-011 | C27: 프로필 영역 | D27: Card | E27: 회원 기본 정보 카드 (사진/이름/연락처/상태) | F27: 수정 버튼 → SCR-013 이동 | G27: FN-006 | H27: API-008 | I27: 프로필 Card 컴포넌트 | M27: aria-label='회원 프로필' | N27: 설계중 | P27: 회원 상세 | Q27: 회원 상세 조회 | R27: /api/v1/members/:id
A28: UI-023 | B28: SCR-011 | C28: 이용권 탭 | D28: Tab | E28: 보유 이용권 목록 탭 | F28: 만료일 강조, 잔여 횟수 표시 | G28: FN-006 | H28: API-008 | I28: Tab + 이용권 리스트 | M28: aria-label='이용권 탭' | N28: 설계중 | P28: 회원 상세 | Q28: 회원 상세 조회 | R28: /api/v1/members/:id
A29: UI-024 | B29: SCR-011 | C29: 출석 탭 | D29: Tab | E29: 출석 이력 탭 (히트맵 + 리스트) | F29: 히트맵 날짜 클릭 시 상세, 타지점 출석 구분 | G29: FN-006 | H29: API-013 | I29: Tab + 히트맵 + 테이블 | M29: aria-label='출석 탭' | N29: 설계중 | P29: 회원 상세 | Q29: 회원 상세 조회 | R29: /api/v1/attendance
A30: UI-025 | B30: SCR-011 | C30: 결제 탭 | D30: Tab | E30: 결제/매출 이력 탭 | F30: 결제 상세 모달, 환불 처리 | G30: FN-006 | H30: API-015 | I30: Tab + 결제 테이블 | M30: aria-label='결제 탭' | N30: 설계중 | P30: 회원 상세 | Q30: 회원 상세 조회 | R30: /api/v1/sales
A31: UI-026 | B31: SCR-011 | C31: 체성분 탭 | D31: Tab | E31: 체성분 측정 이력 + 차트 탭 | F31: 측정 추가, 변화 추이 차트 | G31: FN-007 | H31: API-008 | I31: Tab + 차트 + 입력 폼 | M31: aria-label='체성분 탭' | N31: 설계중 | P31: 회원 상세 | Q31: 체성분 기록/분석 | R31: /api/v1/members/:id
A32: UI-027 | B32: SCR-011 | C32: 메모 탭 | D32: Tab | E32: 상담/메모 기록 탭 | F32: 메모 추가/수정/삭제, 시간순 정렬 | G32: FN-006 | H32: API-008 | I32: Tab + 메모 리스트 + 에디터 | M32: aria-label='메모 탭' | N32: 설계중 | P32: 회원 상세 | Q32: 회원 상세 조회 | R32: /api/v1/members/:id
A33: ▼ SCR-012 | B33: 회원 등록 | C33: 10개 요소
A34: UI-028 | B34: SCR-012 | C34: 이름 입력 | D34: Input | E34: 회원 이름 입력 필드 | F34: 필수 항목, 한글 2~20자 | G34: FN-004 | H34: API-009 | I34: <input> + validation | K34: 한글 2~20자 | L34: 이름을 입력하세요 | M34: aria-required='true' | N34: 설계중 | P34: 회원 등록 | Q34: 회원 등록 | R34: /api/v1/members
A35: UI-029 | B35: SCR-012 | C35: 성별 선택 | D35: Radio | E35: 성별 선택 (남/여) | F35: 라디오 버튼 2개 | G35: FN-004 | H35: API-009 | I35: RadioGroup 컴포넌트 | K35: 필수 선택 | L35: 성별을 선택하세요 | M35: role='radiogroup' | N35: 설계중 | P35: 회원 등록 | Q35: 회원 등록 | R35: /api/v1/members
A36: UI-030 | B36: SCR-012 | C36: 생년월일 | D36: Input | E36: 생년월일 입력 (date picker) | F36: 달력 팝업 또는 직접 입력 | G36: FN-004 | H36: API-009 | I36: DatePicker 컴포넌트 | K36: 미래 날짜 불가 | L36: 올바른 날짜를 입력하세요 | M36: aria-label='생년월일' | N36: 설계중 | P36: 회원 등록 | Q36: 회원 등록 | R36: /api/v1/members
A37: UI-031 | B37: SCR-012 | C37: 연락처 입력 | D37: Input | E37: 연락처 입력 (자동 하이픈) | F37: 입력 시 자동 포맷 (010-xxxx-xxxx) | G37: FN-004 | H37: API-009 | I37: PhoneInput 컴포넌트 | K37: 전화번호 형식 검증, 중복 체크 | L37: 올바른 연락처를 입력하세요 | M37: aria-label='연락처' | N37: 설계중 | P37: 회원 등록 | Q37: 회원 등록 | R37: /api/v1/members
A38: UI-032 | B38: SCR-012 | C38: 이메일 입력 | D38: Input | E38: 이메일 주소 입력 | F38: 선택 항목 | G38: FN-004 | H38: API-009 | I38: <input type='email'> | K38: 이메일 형식 검증 | L38: 올바른 이메일을 입력하세요 | M38: aria-label='이메일' | N38: 설계중 | P38: 회원 등록 | Q38: 회원 등록 | R38: /api/v1/members
A39: UI-033 | B39: SCR-012 | C39: 주소 입력 | D39: Input | E39: 주소 검색 및 입력 | F39: 다음 주소 API 연동 | G39: FN-004 | H39: API-009 | I39: AddressSearch 컴포넌트 | K39: 최소 5자 이상 | L39: 주소를 입력하세요 | M39: aria-label='주소' | N39: 설계중 | P39: 회원 등록 | Q39: 회원 등록 | R39: /api/v1/members
A40: UI-034 | B40: SCR-012 | C40: 메모 입력 | D40: Textarea | E40: 관리자 메모 입력 | F40: 최대 500자, 글자수 카운터 | G40: FN-004 | H40: API-009 | I40: <textarea> + counter | K40: 최대 500자 | L40: 메모 입력을(를) 입력하세요 | M40: aria-label='메모' | N40: 설계중 | P40: 회원 등록 | Q40: 회원 등록 | R40: /api/v1/members
...

Sheet 기능명세서
A1: 기능 ID | B1: 기능명 | C1: 기능 분류 | D1: 플랫폼 | E1: 우선순위 | F1: 기능 설명 | G1: 상세 요구사항 | H1: 화면 ID | I1: 입력 항목 | J1: 출력 항목 | K1: 비즈니스 규칙 | L1: 예외 처리 | M1: Web 구현 사항 | N1: App 구현 사항 | O1: 관련 API ID | P1: 상태 | Q1: 담당자 | R1: [자동] 화면명 | S1: [자동] API 엔드포인트 | T1: 비고 | U1: [자동] 관련 UI 요소
A2: ▼ SCR-001 | B2: 로그인 (1개 기능)
A3: FN-001 | B3: 로그인 | C3: 인증 | D3: Web | E3: Critical | F3: 이메일/비밀번호 기반 로그인 + 지점 선택 | G3: 1) 이메일/비밀번호 입력 2) 지점 선택 필수 3) JWT 토큰 발급 4) 로그인 실패 횟수 추적 | H3: SCR-001 | I3: 이메일, 비밀번호, 지점ID | J3: JWT 토큰, 사용자 정보, 권한 목록 | K3: 1) 5회 연속 실패 시 30분 계정 잠금 2) 비밀번호: 최소 8자, 영문+숫자+특수문자 조합 필수 3) 이전 3개 비밀번호 재사용 금지 4) 90일 경과 시 비밀번호 변경 권장 팝업 (강제 변경 or 건너뛰기) 5) 동시 세션 1개 제한 – 신규 로그인 시 기존 세션 강제 종료 6) 토큰 만료: 기본 2시간 / 로그인 유지 체크 시 7일 (refresh token) 7) 로그인 시 선택한 지점만 데이터 접근 허용 8) 탈퇴·비활성 계정 접근 불가 | L3: 계정 잠금: '5회 실패로 잠금. 30분 후 재시도 또는 비밀번호 찾기' 서버 오류: '일시적 오류. 잠시 후 다시 시도하세요' 탈퇴 계정: '탈퇴 처리된 계정입니다' 네트워크 오류: '인터넷 연결을 확인하세요' 지점 미선택: '지점을 선택해주세요' 잘못된 자격증명: '이메일 또는 비밀번호를 확인하세요' | M3: React Hook Form + Zod 스키마 검증 axios + JWT 인터셉터 (자동 토큰 첨부/갱신) Zustand authStore (token, user, branchId) 비밀번호 마스킹 토글 (Eye 아이콘) shake 애니메이션 – 에러 시 폼 흔들림 효과 sonner 토스트 알림 잠금 카운트다운 타이머 UI | O3: API-001 | P3: 확정 | R3: 로그인 | S3: /api/v1/auth/login | U3: 5
A4: ▼ SCR-002 | B4: 대시보드 (1개 기능)
A5: FN-002 | B5: 대시보드 통계 조회 | C5: 대시보드 | D5: Web | E5: Critical | F5: 지점별 핵심 KPI 대시보드 (회원/매출/출석 요약) | G5: 1) 총회원/활성/만료임박/만료 카운트 2) 오늘 생일 회원 리스트 3) 미납 회원 리스트 4) 만료 예정 회원 5) 당월 매출 차트 | H5: SCR-002 | I5: 지점ID (JWT에서 추출) | J5: 통계 데이터, 리스트, 차트 데이터 | K5: 1) 통계 카드: 페이지 진입 시 + 5분 주기 자동 갱신 2) 만료임박: D-7 이내 카운트, D-3 이내 긴급(빨간색), D-0 만료 처리 3) 미납: 결제예정일 초과 + 미결제 → 미납, 30일 초과 시 장기미납 표시 4) 차트: 페이지 진입 시 1회 조회 (BarChart/PieChart/LineChart) 5) 통계 카드 클릭 시 해당 목록으로 이동 (status 필터 자동 적용) 6) 지점별 데이터 격리 – branch_id 기준 필터 필수 7) 알림 리스트: 실시간 polling 30초 주기 | L5: 데이터 로드 실패: 각 섹션 독립 에러 표시 + 재시도 버튼 빈 데이터: '아직 데이터가 없습니다' Empty State UI 지점 미설정: '지점 정보를 설정하세요' 안내 네트워크 단절: 마지막 갱신 시각 표시 + 수동 갱신 버튼 | M5: TanStack Query (5분 refetchInterval, staleTime 설정) Recharts – BarChart, PieChart, LineChart useNavigate() + query string으로 필터 목록 이동 Skeleton 로딩 UI (카드/차트 영역) RefreshCw 아이콘 수동 갱신 버튼 date-fns 날짜 계산 (D-day) | O5: API-003 | P5: 확정 | R5: 대시보드 | S5: /api/v1/dashboard/stats | U5: 8
A6: ▼ SCR-010 | B6: 회원 목록 (2개 기능)
A7: FN-003 | B7: 회원 목록 조회/검색/필터 | C7: 회원관리 | D7: Web | E7: Critical | F7: 회원 검색, 필터, 페이지네이션 목록 조회 | G7: 1) 이름/연락처/회원번호 검색 (300ms debounce) 2) 상태/성별/담당자 필터 조합 3) 컬럼 정렬 4) 페이지당 20/50/100건 5) 엑셀 다운로드 | H7: SCR-010 | I7: 검색어, 필터 조건, 페이지 번호, 정렬 기준 | J7: 회원 목록 (이름/연락처/상태/이용권/담당자) | K7: 1) 검색: 이름 부분일치(2자 이상), 연락처 숫자만 추출 후 부분일치, 회원번호 완전일치 2) 검색 debounce 300ms 적용 3) 모든 필터는 AND 조합, 탭 필터와 상세 필터 동시 적용 4) 회원 상태: 활성/만료/예정/임박(D-30 이내)/홀딩/미등록 정의 5) 일괄 처리 최대 100명 동시 선택 6) 삭제 회원 기본 미표시, 옵션으로 표시 전환 가능 7) 권한별 조회 범위 제한 (FC: 담당 회원만, 스태프: 조회만) | L7: 검색 결과 없음: '조건에 맞는 회원이 없습니다' Empty State 필터 오류: 필터 초기화 버튼 항상 노출 API 오류: '회원 목록을 불러오지 못했습니다. 재시도' 버튼 일괄 처리 100명 초과: '최대 100명까지 선택 가능합니다' 권한 없음: 해당 기능 버튼 비활성화 처리 | M7: TanStack Query – GET /api/v1/members (캐싱) useDebounce() 훅 (300ms) DataTable 컴포넌트 (정렬/페이지네이션/다중선택) URL 쿼리 파라미터로 필터 상태 동기화 xlsx 라이브러리 – 엑셀 다운로드 Checkbox 다중선택 + 일괄 처리 드롭다운 | O7: API-007 | P7: 확정 | R7: 회원 목록 | S7: /api/v1/members | U7: 8
A8: FN-004 | B8: 회원 등록 | C8: 회원관리 | D8: Web | E8: Critical | F8: 신규 회원 등록 | G8: 1) 필수: 이름, 성별, 연락처 2) 선택: 이메일, 주소, 생년월일, 메모 3) 담당 FC 배정 4) 연락처 중복 체크 | H8: SCR-010 | I8: 이름, 성별, 생년월일, 연락처, 이메일, 주소, 메모, 담당자ID | J8: 등록된 회원 정보 | K8: 1) 필수 입력: 이름(2~20자, 한글/영문), 성별, 연락처(010-XXXX-XXXX), 회원구분 2) 연락처: 동일 지점 내 중복 불가 (API 중복확인) 3) 회원번호 자동 생성: 지점코드-YYMMDD-순번 4) 출석번호 자동 생성: 4자리 랜덤 (중복 체크) 5) 기본 상태: '미등록' (이용권 구매 시 '활성'으로 자동 전환) 6) 프로필 사진: JPG/PNG, 5MB 이하 7) 생년월일: 미래 날짜 입력 불가 8) 이메일: RFC 5322 형식 검증 | L8: 연락처 중복: '이미 등록된 연락처입니다 (지점 내)' 이름 형식 오류: '이름은 2~20자 한글 또는 영문으로 입력하세요' 연락처 형식 오류: '010-XXXX-XXXX 형식으로 입력하세요' 파일 크기 초과: '이미지 파일은 5MB 이하만 업로드 가능합니다' 저장 실패: '회원 등록에 실패했습니다. 다시 시도하세요' 취소 시: '변경사항이 있습니다. 정말 나가시겠습니까?' 확인 다이얼로그 | M8: React Hook Form + Zod 스키마 (2단계 폼) useMutation – POST /api/v1/members Kakao 주소 API 연동 (주소 검색 버튼) 이미지 업로드 – FileReader + presigned URL 연락처 입력 자동 하이픈 포맷팅 취소 확인 useBlocker() (React Router v6) | O8: API-009 | P8: 확정 | R8: 회원 목록 | S8: /api/v1/members | U8: 8
A9: ▼ SCR-011 | B9: 회원 상세 (2개 기능)
A10: FN-005 | B10: 회원 정보 수정 | C10: 회원관리 | D10: Web | E10: High | F10: 기존 회원 정보 수정 | G10: 1) 기존 데이터 프리필 2) 변경 필드 강조 3) 변경 이력 자동 기록 4) 담당자 변경 가능 | H10: SCR-011 | I10: 수정할 회원 정보 | J10: 수정된 회원 정보 | K10: 1) 수정 시 변경 전/후 값 audit log 자동 저장 2) 변경자 + 변경일시 자동 기록 3) 연락처 변경 시 재중복 체크 필수 4) 변경된 필드 강조 표시 (초록색 border) 5) 미납 건 있는 회원 삭제 불가 6) 유효 이용권 있는 회원 삭제 불가 (환불 선행 필요) 7) 소프트 삭제 (is_deleted 플래그), 삭제 후 30일 복구 가능 | L10: 수정 중 다른 관리자 수정 감지: '다른 사용자가 수정 중입니다' 미납 상태 삭제 시도: '미납 건이 있어 삭제할 수 없습니다' 유효 이용권 삭제 시도: '유효한 이용권이 있습니다. 환불 후 삭제 가능' 저장 실패: '회원 정보 수정에 실패했습니다' 연락처 중복: '이미 등록된 연락처입니다' | M10: React Hook Form + defaultValues 초기값 설정 useMutation – PATCH /api/v1/members/:id dirtyFields로 변경 필드 감지 + 강조 표시 Optimistic update (TanStack Query) 삭제 확인 AlertDialog (shadcn/ui) Kakao 주소 API 연동 | O10: API-010 | P10: 확정 | R10: 회원 상세 | S10: /api/v1/members/:id | U10: 6
A11: FN-006 | B11: 회원 상세 조회 | C11: 회원관리 | D11: Web | E11: High | F11: 회원 프로필 + 탭별 상세 정보 조회 | G11: 1) 프로필: 기본 정보 + 사진 2) 이용권 탭: 보유 이용권 목록 3) 출석 탭: 히트맵 + 리스트 4) 결제 탭: 결제 이력 5) 체성분 탭: 측정 기록 + 차트 6) 메모 탭: 상담/메모 | H11: SCR-011 | I11: 회원ID | J11: 회원 전체 정보 (프로필+이용권+출석+결제+체성분+메모) | K11: 1) 기본정보 탭: 페이지 진입 시 즉시 로드 2) 나머지 탭: 클릭 시 lazy 로드 (React.lazy + Suspense) 3) 탭 전환 시 이전 데이터 캐싱 유지 4) 탭 상태 URL 파라미터 유지 (?tab=attendance) 5) 출석 히트맵: 최근 6개월, 1회=연한색, 3회 이상=진한색 6) 이용권 유효 → 상단, 만료 → 하단 접힘, D-7 주황 경고 7) 회원 미존재 시 404 페이지 리다이렉트 | L11: 존재하지 않는 회원 ID: 404 페이지 이동 탭 데이터 로드 실패: 해당 탭 내 에러 메시지 + 재시도 버튼 네트워크 오류: 마지막 캐시 데이터 표시 + 경고 배너 권한 없는 탭 접근: 탭 비활성화 처리 | M11: TanStack Query – GET /api/v1/members/:id React.lazy() + Suspense 탭별 코드 스플리팅 useSearchParams()로 탭 URL 동기화 출석 히트맵 – react-calendar-heatmap Skeleton 로딩 UI (탭 콘텐츠 영역) date-fns – D-day, 날짜 포맷 | O11: API-008 | P11: 확정 | R11: 회원 상세 | S11: /api/v1/members/:id | U11: 6
A12: ▼ SCR-014 | B12: 체성분 (1개 기능)
A13: FN-007 | B13: 체성분 기록/분석 | C13: 회원관리 | D13: Web | E13: High | F13: 회원 체성분 측정 기록 입력 및 변화 추이 분석 | G13: 1) 체중/골격근/체지방률/BMI 등 입력 2) 측정일 기준 시계열 차트 3) 목표 대비 달성률 게이지 | H13: SCR-014 | I13: 체중, 골격근, 체지방률, 측정일 | J13: 체성분 이력, 변화 차트 | K13: 1) 체중 유효 범위: 20~300kg, 골격근량: 5~80kg, 체지방률: 3~60% 2) BMI 자동 계산: 체중(kg) / 신장(m)² 3) 범위 초과 시: 경고 후 저장 허용 (강제 차단 아님) 4) 동일 날짜 기존 기록 존재 시 '덮어쓰기' 확인 모달 5) 미래 날짜 측정 불가 6) 목표 체중/체지방률 대비 달성률 게이지 표시 7) 달성 시 축하 메시지 표시 | L13: 범위 초과 입력: '입력값이 정상 범위를 벗어났습니다. 그래도 저장하시겠습니까?' 미래 날짜: '미래 날짜에는 측정 기록을 입력할 수 없습니다' 동일 날짜 중복: '해당 날짜에 이미 기록이 있습니다. 덮어쓰시겠습니까?' 저장 실패: '체성분 기록 저장에 실패했습니다' 신장 미입력: 'BMI 계산을 위해 회원 신장을 먼저 입력하세요' | M13: React Hook Form + Zod (범위 검증 + 경고) useMutation – POST /api/v1/members/:id/body-composition Recharts LineChart – 시계열 추이 차트 진행률 게이지 – shadcn/ui Progress 확인 모달 – AlertDialog (덮어쓰기) date-fns – 날짜 비교/포맷 | O13: API-008 | P13: 확정 | R13: 체성분 분석 | S13: /api/v1/members/:id | U13: 2
A14: ▼ SCR-020 | B14: 출석 (1개 기능)
A15: FN-008 | B15: 출석 기록 조회 | C15: 출석관리 | D15: Web | E15: High | F15: 회원 출석 현황 조회 (일별/주별/월별) | G15: 1) 날짜 필터 (일/주/월 뷰) 2) 출석 유형(일반/PT/GX) 필터 3) 타지점 출석 표시 4) 키오스크/앱 체크인 구분 | H15: SCR-020 | I15: 날짜 범위, 필터 조건 | J15: 출석 목록, 통계 | K15: 1) 출석 유형: 일반(키오스크/앱), PT, GX, 수동(관리자) 2) 이용권 만료 회원: 출입 차단 (센터 설정에 따라 경고만 가능) 3) 미납 회원: 센터 설정에 따라 허용/경고/차단 4) 타지점 출석: 전지점 이용권 보유 시 허용, 원지점에 알림 5) 실시간 팝업: 5초 자동 종료, 거부 시 빨간색 팝업 6) 일별/주별/월별 뷰 제공 7) 수동 출석: 관리자 권한, 사유 필수 입력 | L15: 이용권 만료 회원 체크인: '이용권이 만료되었습니다. 관리자에게 문의하세요' 미납 회원 체크인: '미납이 있습니다. 결제 후 이용 가능합니다' 타지점 전용 이용권: '이 지점은 이용 불가한 이용권입니다' 데이터 로드 실패: '출석 기록을 불러오지 못했습니다' 날짜 범위 초과: '조회 가능한 최대 기간은 1년입니다' | M15: TanStack Query – GET /api/v1/attendance WebSocket or SSE – 실시간 체크인 팝업 DataTable + 날짜 필터 (date-fns) 일별/주별/월별 뷰 탭 전환 유형별 색상 Badge (일반/PT/GX/수동) 수동 출석 등록 모달 (React Hook Form) | O15: API-013 | P15: 확정 | R15: 출석 기록 | S15: /api/v1/attendance | U15: 2
A16: ▼ SCR-021 | B16: 일정 (1개 기능)
A17: FN-009 | B17: 일정 관리 | C17: 출석관리 | D17: Web | E17: High | F17: PT/GX 일정 캘린더 관리 | G17: 1) 월/주/일 캘린더 뷰 전환 2) 드래그앤드롭 일정 이동 3) 트레이너별 색상 구분 4) 일정 충돌 감지 | H17: SCR-021 | I17: 일정 제목, 시간, 트레이너, 회원, 룸 | J17: 캘린더 일정 목록 | K17: 1) 일정 충돌: 동일 시간대 + 동일 트레이너 or 동일 룸 → 경고 2) 1:1 PT: 트레이너당 동시 1건만 등록 가능 3) GX: 룸 수용인원 초과 불가 4) 과거 일정 수정/삭제 불가 5) 당일 일정: 시작 2시간 전까지 수정 가능 6) 반복 일정: 개별/전체 수정 선택 7) PT 예약 취소: 24시간 전 무료, 당일 취소 1회 차감, 노쇼 1회 차감 + 패널티 8) 페널티 3회 누적 → 관리자 알림 | L17: 일정 충돌: '해당 시간에 이미 일정이 있습니다 (트레이너/룸 충돌)' 수용인원 초과: '룸 수용 인원을 초과했습니다' 과거 일정 수정 시도: '과거 일정은 수정할 수 없습니다' 당일 2시간 내 수정: '수업 2시간 전부터 수정이 불가합니다' 반복 일정 수정: '이 일정만 수정' / '이후 모든 일정 수정' 선택 모달 | M17: FullCalendar React (주/월/일 뷰) 드래그앤드롭 – @fullcalendar/interaction useMutation – POST/PATCH/DELETE /api/v1/schedules 충돌 감지 로직 (시간 겹침 계산) 반복 일정 처리 (rrule) 트레이너별 색상 구분 (CSS custom properties) | P17: 확정 | R17: 일정 관리 | S17: =IFERROR(VLOOKUP(O17,API명세서!A:D,4,FALSE()),"") | U17: 2
A18: ▼ SCR-030 | B18: 매출 (2개 기능)
A19: FN-010 | B19: 매출 조회/통계 | C19: 매출관리 | D19: Web | E19: Critical | F19: 매출 현황 조회 및 통계 요약 | G19: 1) 기간별 필터 (프리셋: 오늘/이번주/이번달/커스텀) 2) 유형별 필터 (이용권/PT/상품/기타) 3) 상태별 필터 (완료/환불/미납) 4) 통계 카드: 총매출/현금/카드/마일리지 5) 엑셀 다운로드 | H19: SCR-030 | I19: 기간, 유형, 상태, 페이지 | J19: 매출 목록, 통계 요약 | K19: 1) 총매출 = 현금 + 카드 + 마일리지 - 환불 2) 순매출 = 총매출 - 부가세 (10%) 3) 일/주/월/연 단위 집계, 지점별 독립 집계 4) 환불 정책: 7일 이내 전액, 7일 초과~이용 전 위약금 10%, 이용 후 잔여일 일할 계산 5) 미납 7일 경과 시 SMS 자동 발송 (설정 시) 6) 미납 30일 경과 시 장기미납 분류 7) 기간 프리셋: 오늘/이번주/이번달/커스텀 | L19: 날짜 범위 오류: '시작일이 종료일보다 클 수 없습니다' 데이터 없음: 해당 기간 매출 없음 Empty State 엑셀 다운로드 실패: '파일 생성에 실패했습니다' 권한 없음: 매출 데이터 접근 불가 (FC 이하) 네트워크 오류: 마지막 조회 데이터 캐시 유지 | M19: TanStack Query – GET /api/v1/sales Recharts – BarChart, PieChart (매출 분포) date-fns – 기간 프리셋, 날짜 포맷 xlsx 라이브러리 – 엑셀 다운로드 금액 포맷 – Intl.NumberFormat (천단위 콤마) DataTable (23개 컬럼, 가로 스크롤) | O19: API-015 | P19: 확정 | R19: 매출 조회 | S19: /api/v1/sales | U19: 7
A20: FN-011 | B20: POS 상품 선택/결제 | C20: 매출관리 | D20: Web | E20: Critical | F20: POS 상품 선택 및 장바구니 관리 | G20: 1) 카테고리별 상품 그리드 2) 상품 클릭 → 장바구니 추가 3) 수량 조절/삭제 4) 합계 자동 계산 | H20: SCR-030 | I20: 상품 선택, 수량 | J20: 장바구니 목록, 합계 | K20: 1) 상품 그리드: 카테고리 탭 + 검색으로 필터 2) 재고 0인 상품 자동 비활성화 표시 3) 재고 5개 이하 경고 표시 (노란 뱃지) 4) 비회원 결제 시 마일리지 적립/사용 불가 5) 장바구니 수량 변경 시 즉시 소계 재계산 6) 부가세 10% 자동 계산 (포함/별도 상품별 설정) 7) 회원 검색: 이름/전화번호 검색 | L20: 재고 없는 상품 추가: '재고가 없는 상품입니다' 장바구니 비어있음: '상품을 선택해주세요' 회원 검색 결과 없음: '검색된 회원이 없습니다' 수량 0 이하 입력: '수량은 1 이상이어야 합니다' 상품 판매 중지: '현재 판매 중지된 상품입니다' | M20: Zustand cartStore (장바구니 상태 관리) TanStack Query – GET /api/v1/products (카테고리별) 실시간 소계/합계 계산 (useMemo) 회원 검색 Combobox (debounce 300ms) 상품 이미지 lazy loading Badge 컴포넌트 – 재고 상태 표시 | O20: API-018 | P20: 확정 | R20: 매출 조회 | S20: /api/v1/products | U20: 7
A21: ▼ SCR-032 | B21: POS 결제 (1개 기능)
A22: FN-012 | B22: POS 결제 처리 | C22: 매출관리 | D22: Web | E22: Critical | F22: 결제 수단 선택 및 결제 실행 | G22: 1) 현금/카드/마일리지/복합결제 2) 회원 검색 → 마일리지 잔액 표시 3) 결제 확인 모달 4) 영수증 출력 옵션 | H22: SCR-032 | I22: 결제수단, 금액, 회원ID | J22: 결제 결과, 영수증 | K22: 1) 혼합결제: 각 수단 합계 = 총 결제금액 일치 필수 2) 마일리지: 잔액 초과 사용 불가, 최소 1,000원 3) 마일리지 최대 사용: 결제금액의 50% (센터 설정) 4) 현금 결제: 거스름돈 자동 계산 5) 당일 취소: 즉시 환불, 익일 이후: 환불 프로세스 6) 결제 완료 시 재고 자동 차감 7) 마일리지 자동 적립 (설정된 적립률 기준) 8) 영수증 자동 생성 + 프린트/문자 발송 | L22: 혼합결제 금액 불일치: '결제 수단 합계가 총 결제금액과 다릅니다' 마일리지 잔액 초과: '사용 가능한 마일리지가 부족합니다 (잔액: N원)' 결제 실패: '결제 처리에 실패했습니다. 다시 시도하세요' 카드 단말기 오류: '카드 단말기 연결을 확인하세요' 재고 부족: '결제 처리 중 재고가 부족해졌습니다' | M22: useMutation – POST /api/v1/sales/payment 결제 수단별 금액 입력 폼 (React Hook Form) 거스름돈 실시간 계산 (useMemo) 마일리지 잔액 조회 – GET /api/v1/members/:id/mileage 영수증 컴포넌트 – react-to-print 결제 성공 애니메이션 (Framer Motion) | O22: API-016 | P22: 확정 | R22: POS 결제 | S22: /api/v1/sales | U22: 4
A23: ▼ SCR-040 | B23: 상품 (2개 기능)
A24: FN-013 | B24: 상품 목록 조회 | C24: 상품관리 | D24: Web | E24: High | F24: 이용권/PT/GX/기타 상품 목록 조회 | G24: 1) 카테고리 필터 2) 상태(판매중/중지) 필터 3) 키오스크 노출 토글 | H24: SCR-040 | I24: 카테고리, 상태 | J24: 상품 목록 | K24: 1) 상품 카테고리: 시설이용권/수강권(PT)/수강권(GX)/대여/기타 2) 가격: 0원(무료) ~ 99,999,999원 3) 현금가 ≤ 카드가 권장 (강제 아님) 4) 판매 중지 상품: POS/키오스크 모두 비활성화 5) 키오스크 노출 ON/OFF 별도 관리 6) 상태별 탭: 전체/판매중/판매중지/재고소진 7) 검색: 상품명 부분일치 | L24: 검색 결과 없음: '검색된 상품이 없습니다' Empty State 데이터 로드 실패: '상품 목록을 불러오지 못했습니다' 권한 없음: 상품 등록/수정/삭제 버튼 비활성화 (FC 이하) 삭제 시도 (결제 이력 있음): '결제 이력이 있어 삭제할 수 없습니다' | M24: TanStack Query – GET /api/v1/products DataTable (정렬, 페이지네이션) 카테고리 탭 필터 (URL 쿼리 파라미터 동기화) xlsx 라이브러리 – 상품 목록 다운로드 상품 상태 Badge 색상 구분 Skeleton 로딩 UI | O24: API-018 | P24: 확정 | R24: 상품 목록 | S24: /api/v1/products | U24: 3
A25: FN-014 | B25: 상품 등록/수정 | C25: 상품관리 | D25: Web | E25: High | F25: 신규 상품 등록 및 기존 상품 수정 | G25: 1) 카테고리/이름/현금가/카드가/기간 입력 2) 키오스크 노출 설정 3) 상품명 중복 체크 | H25: SCR-040 | I25: 카테고리, 이름, 가격, 기간 | J25: 등록/수정된 상품 정보 | K25: 1) 상품명: 동일 카테고리 내 중복 불가 2) 가격: 0 이상 정수, 음수 불가 3) 홀딩 설정: 최대 N일, 최대 N회 (상품별 개별 설정) 4) 홀딩 시 잔여일 정지 (소진 아님) 5) 만료 후 재활성화 불가 (재구매 필요) 6) 이용 시간 설정: 요일별/시간대별 이용 가능 설정 7) 부가세 포함/별도 선택 8) 이미지: JPG/PNG, 5MB 이하 | L25: 상품명 중복: '동일 카테고리에 같은 이름의 상품이 있습니다' 가격 음수/문자 입력: '가격은 0 이상의 숫자만 입력 가능합니다' 이미지 형식 오류: 'JPG 또는 PNG 파일만 업로드 가능합니다' 이미지 크기 초과: '이미지 파일은 5MB 이하만 가능합니다' 저장 실패: '상품 저장에 실패했습니다' 취소 시: '변경사항이 있습니다. 나가시겠습니까?' | M25: React Hook Form + Zod (상품 유형별 동적 스키마) useMutation – POST/PATCH /api/v1/products 이미지 업로드 – FileReader + presigned URL 이용 시간 설정 – 요일별 체크박스 + 시간 범위 선택 상품 유형 선택 시 폼 필드 동적 변경 Tabs 컴포넌트 (기본/기간/추가설정) | O25: API-019 | P25: 확정 | R25: 상품 목록 | S25: /api/v1/products | U25: 3
A26: ▼ SCR-050 | B26: 락커 (2개 기능)
A27: FN-015 | B27: 락커 현황 조회 | C27: 시설관리 | D27: Web | E27: High | F27: 구역별 락커 배정 현황 조회 (색상 그리드) | G27: 1) 구역별 탭 2) 색상 상태 (사용중/빈/만료임박/고장) 3) 클릭 시 상세 모달 | H27: SCR-050 | I27: 구역 | J27: 락커 그리드 데이터 | K27: 1) 락커 상태: 사용중/빈/만료임박/고장 4가지 2) D-3 이내: 만료임박 (노란색), D-0: 만료 (빨간색) 3) D+3 초과: 자동 해제 여부 센터 설정에 따름 4) 고장 상태 락커: 배정 불가 5) 구역별 필터링, 그리드/리스트 뷰 전환 6) 통계: 전체/사용중/빈/만료임박/고장 카운트 | L27: 데이터 로드 실패: '락커 현황을 불러오지 못했습니다' 구역 없음: '등록된 구역이 없습니다. 구역을 먼저 설정하세요' 권한 없음: 배정/반납 버튼 비활성화 | M27: TanStack Query – GET /api/v1/lockers 그리드/리스트 뷰 전환 토글 상태별 색상 코딩 (CSS variables) 구역별 필터 Select 컴포넌트 Skeleton 로딩 (그리드 레이아웃) date-fns – D-day 계산 | O27: API-020 | P27: 확정 | R27: 락커 현황 | S27: /api/v1/lockers | U27: 4
A28: FN-016 | B28: 락커 배정/관리 | C28: 시설관리 | D28: Web | E28: High | F28: 락커 배정/해제/일괄 관리 | G28: 1) 회원 검색 → 빈 락커 선택 → 배정 2) 만료일 설정 3) 일괄 해제 (만료 락커) 4) 고장 등록 | H28: SCR-050 | I28: 회원ID, 락커번호, 만료일 | J28: 배정 결과 | K28: 1) 1회원 1락커 (동일 유형 내) 2) 배정 시 만료일 필수 (상품 기간 연동 or 수동 입력) 3) 이미 배정된 락커 재배정 불가 4) 배정 취소: 배정일 당일만 가능 5) 일괄 해제: 만료+N일 초과 건 일괄 처리 6) 고장 등록 시 해당 락커 배정 불가 7) 수리 완료 → 사용가능으로 복원 | L28: 이미 배정된 락커: '이미 사용 중인 락커입니다' 만료일 미입력: '만료일을 입력해주세요' 1인 1락커 초과: '해당 회원에게 이미 배정된 락커가 있습니다' 당일 이후 취소 시도: '배정일 당일만 취소 가능합니다' API 오류: '락커 배정 처리에 실패했습니다' | M28: useMutation – PATCH /api/v1/lockers/:id 회원 검색 Combobox (배정 시) DatePicker – 만료일 선택 (react-day-picker) 일괄 해제 – 체크박스 다중선택 + Confirm 모달 고장 등록/해제 AlertDialog 반납 처리 Confirm 다이얼로그 | O28: API-021 | P28: 확정 | R28: 락커 현황 | S28: /api/v1/lockers/:id | U28: 4
A29: ▼ SCR-052 | B29: RFID (1개 기능)
A30: FN-017 | B30: RFID 관리 | C30: 시설관리 | D30: Web | E30: Medium | F30: RFID 카드 등록/해제/이력 조회 | G30: 1) 카드 번호 스캔/수동 입력 2) 회원-카드 매핑 3) 분실 처리 4) 이력 조회 | H30: SCR-052 | I30: 카드 번호, 회원ID | J30: 매핑 결과, 이력 | K30: 1) 1회원 1카드 원칙 (활성 카드 기준) 2) 카드 번호: 10자리 영숫자 형식 3) 분실 신고 → 기존 카드 비활성화 → 신규 발급 4) 카드 반납 시 초기화 후 재사용 가능 5) RFID 태그 → 회원 조회 → 이용권 유효 확인 → 출입 허용/거부 6) 미등록 카드: '등록되지 않은 카드' 즉시 표시 7) 만료 회원: 센터 설정에 따라 허용/차단 | L30: 1인 1카드 초과: '해당 회원에게 이미 활성 카드가 등록되어 있습니다' 카드 번호 형식 오류: '카드 번호는 10자리 영숫자로 입력하세요' 중복 카드 번호: '이미 등록된 카드 번호입니다' 미등록 카드 태그: '등록되지 않은 카드입니다' 삭제 시 확인: '삭제하려면 카드 번호를 입력하세요' (확인 텍스트 입력) | M30: TanStack Query – GET/POST/PATCH/DELETE /api/v1/rfid RFID 시뮬레이션 – WebSocket 이벤트 삭제 확인 – 텍스트 입력 방식 (Confirmation Input) 사용 이력 모달 – 페이지네이션 테이블 카드 번호 자동 대문자 변환 상태 Badge (활성/분실/반납/비활성) | P30: 확정 | R30: RFID 관리 | S30: =IFERROR(VLOOKUP(O30,API명세서!A:D,4,FALSE()),"") | U30: 3
A31: ▼ SCR-053 | B31: 룸 (1개 기능)
A32: FN-018 | B32: 룸 관리 | C32: 시설관리 | D32: Web | E32: Medium | F32: GX룸/PT룸 등록/수정/삭제 | G32: 1) 룸 CRUD 2) 수용 인원 설정 3) 예약 가능 시간대 설정 | H32: SCR-053 | I32: 룸명, 유형, 수용인원, 시간대 | J32: 룸 정보 | K32: 1) 룸명: 고유값, 2~20자 2) 수용 인원: 1~100명 3) 유형: PT룸/GX룸/다목적 4) 예약 가능 시간: 요일별 개별 설정 5) 미래 예약 존재 시 삭제 불가 6) 삭제 시 관련 일정에서 룸 정보 자동 제거 7) 비활성화: 신규 예약 차단 (기존 예약 유지) | L32: 룸명 중복: '이미 사용 중인 룸 이름입니다' 수용 인원 범위 오류: '수용 인원은 1~100명으로 입력하세요' 예약 있는 룸 삭제 시도: '미래 예약이 있어 삭제할 수 없습니다' 저장 실패: '룸 정보 저장에 실패했습니다' | M32: TanStack Query – GET/POST/PATCH/DELETE /api/v1/rooms React Hook Form + Zod 룸 폼 검증 요일별 시간 설정 UI (요일 체크박스 + 시간 범위) 배치도 탭 – 드래그 배치 (react-dnd) 삭제 확인 AlertDialog 상태 토글 Switch 컴포넌트 | P32: 확정 | R32: 룸 관리 | S32: =IFERROR(VLOOKUP(O32,API명세서!A:D,4,FALSE()),"") | U32: 2
A33: ▼ SCR-060 | B33: 직원 (2개 기능)
A34: FN-019 | B34: 직원 목록 조회 | C34: 직원관리 | D34: Web | E34: High | F34: 직원 검색/필터/목록 조회 | G34: 1) 이름/연락처 검색 2) 역할/상태 필터 3) 테이블 정렬 | H34: SCR-060 | I34: 검색어, 필터 | J34: 직원 목록 | K34: 1) 역할 체계: 최고관리자/센터장/매니저/FC/스태프/조회전용 2) 역할별 기본 권한 자동 배정 3) 고용 유형: 정규직(월급)/계약직(월급+계약기간)/시간제(시급) 4) 퇴사 처리 시 관리자 계정 자동 비활성화 5) 담당 회원 재배정 알림 자동 발송 6) 검색: 이름 부분일치, debounce 300ms 7) 권한별 조회 범위 (FC: 본인 담당만) | L34: 검색 결과 없음: '검색된 직원이 없습니다' Empty State 권한 없음: 직원 등록/수정/삭제 버튼 비활성화 퇴사 처리 확인: '퇴사 처리하면 계정이 비활성화됩니다. 진행하시겠습니까?' 데이터 로드 실패: '직원 목록을 불러오지 못했습니다' | M34: TanStack Query – GET /api/v1/staff DataTable (정렬, 필터, 다중선택) 퇴사 처리 AlertDialog + useMutation useDebounce() (300ms) 검색 역할별 색상 Badge 근태/급여 탭 컴포넌트 분리 | O34: API-022 | P34: 확정 | R34: 직원 목록 | S34: /api/v1/staff | U34: 5
A35: FN-020 | B35: 직원 등록/수정 | C35: 직원관리 | D35: Web | E35: High | F35: 신규 직원 등록 및 기존 직원 수정 | G35: 1) 이름/역할/연락처/입사일 입력 2) 관리자 계정 자동 생성 3) 근무 유형 설정 | H35: SCR-060 | I35: 이름, 역할, 연락처, 입사일 | J35: 등록된 직원 정보 | K35: 1) 이메일 기반 관리자 계정 자동 생성 (등록 시) 2) 역할 선택 시 기본 권한 자동 배정 3) 연락처: 동일 지점 내 중복 불가 4) 계약직: 계약 종료일 필수 입력 5) 수정 시 변경 이력 자동 기록 6) 프로필 사진: JPG/PNG, 5MB 이하 7) 퇴사 후 데이터: 6개월 보관 후 삭제 or 영구 보관 (설정) | L35: 이메일 중복: '이미 사용 중인 이메일입니다' 연락처 중복: '이미 등록된 연락처입니다' 계약 종료일 미입력 (계약직): '계약직은 계약 종료일이 필수입니다' 저장 실패: '직원 정보 저장에 실패했습니다' 취소 시: '변경사항이 있습니다. 나가시겠습니까?' | M35: React Hook Form + Zod (고용유형별 동적 스키마) useMutation – POST/PATCH /api/v1/staff 이미지 업로드 – presigned URL 역할 선택 시 권한 미리보기 표시 4섹션 Accordion 폼 (인적사항/근무/급여/계정) useBlocker() – 미저장 이탈 방지 | O35: API-023 | P35: 확정 | R35: 직원 목록 | S35: /api/v1/staff | U35: 5
A36: ▼ SCR-062 | B36: 급여 (2개 기능)
A37: FN-021 | B37: 급여 관리 | C37: 직원관리 | D37: Web | E37: High | F37: 월별 급여 현황 조회 및 관리 | G37: 1) 월별 급여 테이블 2) 기본급/인센티브/공제 내역 3) 지급 상태 관리 4) 합계/평균 요약 | H37: SCR-062 | I37: 연월 | J37: 급여 목록, 합계 | K37: 1) 실지급액 = 기본급 + 인센티브 + 수당 - 4대보험 - 소득세 2) 인센티브: PT 건당 커미션 (예: 30%, 센터 설정) 3) 급여 상태 흐름: 미정산 → 임시저장 → 확정대기 → 확정완료 4) 확정완료 상태: 수정 불가 (최고관리자 해제 가능) 5) 마감: 매월 25일 (센터 설정 가능) 6) 이의제기: 직원 제출 → 관리자 재검토 7) 권한: 센터장 이상만 전체 조회, FC는 본인만 | L37: 확정완료 후 수정 시도: '확정된 급여는 수정할 수 없습니다 (관리자 해제 필요)' 계산 오류: '급여 계산 중 오류가 발생했습니다' 마감 후 수정: '마감 처리된 급여입니다' 권한 없음: 타인 급여 조회 불가 데이터 없음: '해당 월의 급여 데이터가 없습니다' | M37: TanStack Query – GET /api/v1/payroll 월 선택 DatePicker (year/month) 급여 계산 로직 (useMemo) 상태 흐름 표시 – Step Indicator 확정 처리 AlertDialog DataTable (97명, 가상화 – react-virtual) | P37: 확정 | R37: 급여 현황 | S37: =IFERROR(VLOOKUP(O37,API명세서!A:D,4,FALSE()),"") | U37: 3
A38: FN-022 | B38: 급여명세서 조회 | C38: 직원관리 | D38: Web | E38: Medium | F38: 직원별 급여명세서 상세 조회 및 PDF 다운로드 | G38: 1) 직원/월 선택 2) 상세 항목별 표시 3) PDF 다운로드 | H38: SCR-062 | I38: 직원ID, 연월 | J38: 급여명세서 상세 | K38: 1) 명세서 조회 권한: 본인 or 센터장 이상 2) 확정완료 후 자동 생성 3) PDF 다운로드 지원 4) 이메일 자동 발송 (설정 시) 5) 이의제기 기능 제공 6) 조회 이력 로깅 | L38: 본인 외 명세서 접근: '조회 권한이 없습니다' 미확정 명세서: '아직 확정되지 않은 급여입니다' PDF 생성 실패: '명세서 PDF 생성에 실패했습니다' 이메일 발송 실패: '이메일 발송에 실패했습니다. 직접 다운로드 해주세요' | M38: TanStack Query – GET /api/v1/payroll/statement html2pdf.js – PDF 다운로드 명세서 상세 모달 (Dialog) 이의제기 Textarea 폼 이메일 발송 – POST /api/v1/payroll/statement/send 인쇄 – react-to-print | P38: 확정 | R38: 급여 현황 | S38: =IFERROR(VLOOKUP(O38,API명세서!A:D,4,FALSE()),"") | U38: 3
A39: ▼ SCR-070 | B39: 메시지 (2개 기능)
A40: FN-023 | B40: 메시지 발송 | C40: 메시지/마케팅 | D40: Web | E40: High | F40: SMS/카카오톡 메시지 발송 | G40: 1) 수신자 선택 (개별/그룹/전체) 2) 메시지 유형(SMS/LMS/카카오) 3) 변수 삽입 (#{이름}) 4) 발송 이력 조회 | H40: SCR-070 | I40: 수신자, 유형, 본문 | J40: 발송 결과 | K40: 1) SMS: 최대 90자 (초과 시 LMS 자동 전환) 2) LMS: 최대 2,000자 3) 카카오 알림톡: 최대 1,000자 4) 예약 발송: 최소 5분 후 ~ 최대 30일 후 5) 발송 전 비용 사전 표시 (SMS 70원, LMS 30원, 카카오 8원) 6) 치환 변수 지원: {이름}, {만료일}, {잔여일} 등 7) 중복 발송 방지: 동일 수신자 + 동일 내용 5분 내 차단 | L40: 수신자 없음: '수신자를 선택해주세요' 내용 없음: '메시지 내용을 입력해주세요' 잔액 부족: '발송 잔액이 부족합니다. 충전 후 이용하세요' 예약 시간 오류: '예약 시간은 5분 후부터 설정 가능합니다' 발송 실패: '메시지 발송에 실패했습니다 (N건 실패)' | M40: React Hook Form – 발송 폼 useMutation – POST /api/v1/messages/send 회원 선택 Combobox (다중선택, 검색) 글자 수 카운터 + 자동 LMS 전환 표시 치환 변수 삽입 버튼 DateTimePicker – 예약 발송 sonner 토스트 – 발송 결과 | P40: 확정 | R40: 메시지 발송 | S40: =IFERROR(VLOOKUP(O40,API명세서!A:D,4,FALSE()),"") | U40: 5
...

Sheet API명세서
A1: API ID | B1: API명 | C1: Method | D1: 엔드포인트 | E1: 설명 | F1: Request Headers | G1: Request Body | H1: Response (성공) | I1: Response (실패) | J1: 인증 필요 | K1: 화면 ID | L1: 기능 ID | M1: 상태 | N1: 담당자 | O1: [자동] 화면명 | P1: [자동] 기능명 | Q1: 비고 | R1: [자동] 관련 UI 요소
A2: API-001 | B2: 로그인 | C2: POST | D2: /api/v1/auth/login | E2: 이메일/비밀번호 로그인 인증 | F2: Content-Type: application/json | G2: { "email": "string", "password": "string", "branch_id": "number" } | H2: { "token": "jwt_string", "user": { "id": 1, "name": "홍길동", "role": "manager", "branch_id": 1 } } | I2: { "error": "INVALID_CREDENTIALS", "message": "이메일 또는 비밀번호가 올바르지 않습니다" } | J2: N | K2: SCR-001 | L2: FN-001 | M2: 개발완료 | O2: 로그인 | P2: 로그인 | R2: 5
A3: API-002 | B3: 로그아웃 | C3: POST | D3: /api/v1/auth/logout | E3: 세션 종료 및 토큰 무효화 | F3: Authorization: Bearer {token} | H3: { "message": "로그아웃 되었습니다" } | I3: { "error": "UNAUTHORIZED", "message": "인증이 필요합니다" } | J3: Y | K3: SCR-002 | L3: FN-001 | M3: 개발완료 | O3: 대시보드 | P3: 로그인 | R3: 8
A4: API-003 | B4: 대시보드 통계 | C4: GET | D4: /api/v1/dashboard/stats | E4: 지점별 대시보드 핵심 KPI 조회 | F4: Authorization: Bearer {token} | H4: { "totalMembers": 450, "activeMembers": 320, "expiringMembers": 25, "expiredMembers": 105, "monthlySales": 15000000, "todayAttendance": 87 } | I4: { "error": "SERVER_ERROR", "message": "데이터를 불러올 수 없습니다" } | J4: Y | K4: SCR-002 | L4: FN-002 | M4: 개발완료 | O4: 대시보드 | P4: 대시보드 통계 조회 | R4: 8
A5: API-004 | B5: 생일 회원 조회 | C5: GET | D5: /api/v1/dashboard/birthday-members | E5: 오늘 생일인 회원 목록 조회 | F5: Authorization: Bearer {token} | H5: { "members": [ {"id": 1, "name": "김회원", "phone": "010-1234-5678"} ] } | I5: { "error": "SERVER_ERROR", "message": "데이터를 불러올 수 없습니다" } | J5: Y | K5: SCR-002 | L5: FN-002 | M5: 개발완료 | O5: 대시보드 | P5: 대시보드 통계 조회 | R5: 8
A6: API-005 | B6: 미납 회원 조회 | C6: GET | D6: /api/v1/dashboard/unpaid-members | E6: 미납 내역이 있는 회원 목록 조회 | F6: Authorization: Bearer {token} | H6: { "members": [ {"id": 2, "name": "이회원", "unpaidAmount": 150000} ] } | I6: { "error": "SERVER_ERROR", "message": "조회 실패" } | J6: Y | K6: SCR-002 | L6: FN-002 | M6: 개발완료 | O6: 대시보드 | P6: 대시보드 통계 조회 | R6: 8
A7: API-006 | B7: 만료예정 회원 조회 | C7: GET | D7: /api/v1/dashboard/expiring-members | E7: 7일 내 이용권 만료 예정 회원 조회 | F7: Authorization: Bearer {token} | H7: { "members": [ {"id": 3, "name": "박회원", "expiryDate": "2026-03-18", "dDay": -7} ] } | I7: { "error": "SERVER_ERROR", "message": "조회 실패" } | J7: Y | K7: SCR-002 | L7: FN-002 | M7: 개발완료 | O7: 대시보드 | P7: 대시보드 통계 조회 | R7: 8
A8: API-007 | B8: 회원 목록 조회 | C8: GET | D8: /api/v1/members | E8: 회원 목록 조회 (검색/필터/페이지네이션) | F8: Authorization: Bearer {token} | G8: Query: ?search=&status=&gender=&manager_id=&page=1&size=20&sort=name&order=asc | H8: { "data": [ {"id": 1, "name": "김회원", "phone": "010-1234-5678", "status": "active", "gender": "M"} ], "pagination": {"page": 1, "size": 20, "total": 450} } | I8: { "error": "FORBIDDEN", "message": "접근 권한이 없습니다" } | J8: Y | K8: SCR-010 | L8: FN-003 | M8: 개발완료 | O8: 회원 목록 | P8: 회원 목록 조회/검색/필터 | R8: 8
A9: API-008 | B9: 회원 상세 조회 | C9: GET | D9: /api/v1/members/:id | E9: 회원 상세 정보 조회 (프로필+이용권+출석+결제+체성분+메모) | F9: Authorization: Bearer {token} | H9: { "profile": {"id": 1, "name": "김회원", ...}, "tickets": [...], "attendance": [...], "payments": [...], "bodyComposition": [...], "memos": [...] } | I9: { "error": "NOT_FOUND", "message": "회원을 찾을 수 없습니다" } | J9: Y | K9: SCR-011 | L9: FN-006 | M9: 개발완료 | O9: 회원 상세 | P9: 회원 상세 조회 | R9: 6
A10: API-009 | B10: 회원 등록 | C10: POST | D10: /api/v1/members | E10: 신규 회원 등록 | F10: Authorization: Bearer {token} Content-Type: application/json | G10: { "name": "string", "gender": "M|F", "birthDate": "YYYY-MM-DD", "phone": "string", "email": "string", "address": "string", "memo": "string", "managerId": "number" } | H10: { "id": 1, "name": "김회원", "status": "active", "createdAt": "2026-03-11T00:00:00Z" } | I10: { "error": "DUPLICATE_PHONE", "message": "이미 등록된 연락처입니다" } | J10: Y | K10: SCR-012 | L10: FN-004 | M10: 개발완료 | O10: 회원 등록 | P10: 회원 등록 | R10: 10
A11: API-010 | B11: 회원 수정 | C11: PUT | D11: /api/v1/members/:id | E11: 기존 회원 정보 수정 | F11: Authorization: Bearer {token} Content-Type: application/json | G11: { "name": "string", "phone": "string", "email": "string", "address": "string", "memo": "string", "managerId": "number" } | H11: { "id": 1, "name": "김회원(수정)", "updatedAt": "2026-03-11T00:00:00Z" } | I11: { "error": "NOT_FOUND", "message": "회원을 찾을 수 없습니다" } | J11: Y | K11: SCR-013 | L11: FN-005 | M11: 개발완료 | O11: 회원 수정 | P11: 회원 정보 수정 | R11: 2
A12: API-011 | B12: 회원 삭제 | C12: DELETE | D12: /api/v1/members/:id | E12: 회원 삭제 (소프트 삭제) | F12: Authorization: Bearer {token} | H12: { "message": "회원이 삭제되었습니다" } | I12: { "error": "FORBIDDEN", "message": "삭제 권한이 없습니다" } | J12: Y | K12: SCR-011 | L12: FN-005 | M12: 개발완료 | O12: 회원 상세 | P12: 회원 정보 수정 | R12: 6
A13: API-012 | B13: 회원 통계 요약 | C13: GET | D13: /api/v1/members/stats/summary | E13: 회원 상태별 통계 요약 | F13: Authorization: Bearer {token} | H13: { "total": 450, "active": 320, "expired": 105, "suspended": 15, "withdrawn": 10 } | I13: { "error": "SERVER_ERROR", "message": "통계 조회 실패" } | J13: Y | K13: SCR-010 | L13: FN-003 | M13: 개발완료 | O13: 회원 목록 | P13: 회원 목록 조회/검색/필터 | R13: 8
A14: API-013 | B14: 출석 기록 조회 | C14: GET | D14: /api/v1/attendance | E14: 회원 출석 기록 조회 | F14: Authorization: Bearer {token} | G14: Query: ?startDate=&endDate=&type=&page=1&size=50 | H14: { "data": [ {"id": 1, "memberId": 1, "memberName": "김회원", "type": "normal", "inTime": "2026-03-11T09:00:00"} ], "pagination": {...} } | I14: { "error": "SERVER_ERROR", "message": "조회 실패" } | J14: Y | K14: SCR-020 | L14: FN-008 | M14: 개발완료 | O14: 출석 기록 | P14: 출석 기록 조회 | R14: 2
A15: API-014 | B15: 출석 등록 | C15: POST | D15: /api/v1/attendance | E15: 출석 체크인/체크아웃 등록 | F15: Authorization: Bearer {token} Content-Type: application/json | G15: { "memberId": "number", "type": "normal|pt|gx", "status": "checkIn|checkOut" } | H15: { "id": 1, "memberId": 1, "inTime": "2026-03-11T09:00:00", "visitCount": 45 } | I15: { "error": "ALREADY_CHECKED_IN", "message": "이미 출석 처리되었습니다" } | J15: Y | K15: SCR-020 | L15: FN-008 | M15: 개발완료 | O15: 출석 기록 | P15: 출석 기록 조회 | R15: 2
A16: API-015 | B16: 매출 조회 | C16: GET | D16: /api/v1/sales | E16: 매출 내역 조회 (기간/유형/상태 필터) | F16: Authorization: Bearer {token} | G16: Query: ?startDate=&endDate=&type=&status=&page=1&size=20 | H16: { "data": [ {"id": 1, "date": "2026-03-11", "productName": "3개월 이용권", "amount": 300000, "paymentMethod": "card"} ], "pagination": {...} } | I16: { "error": "FORBIDDEN", "message": "매출 조회 권한이 없습니다" } | J16: Y | K16: SCR-030 | L16: FN-010 | M16: 개발완료 | O16: 매출 조회 | P16: 매출 조회/통계 | R16: 7
A17: API-016 | B17: 매출 등록 (결제) | C17: POST | D17: /api/v1/sales | E17: POS 결제 처리 및 매출 등록 | F17: Authorization: Bearer {token} Content-Type: application/json | G17: { "memberId": "number", "items": [{"productId": 1, "quantity": 1}], "paymentMethod": "cash|card|mileage|mixed", "cashAmount": 0, "cardAmount": 300000, "mileageAmount": 0 } | H17: { "saleId": 1, "totalAmount": 300000, "receiptNo": "R20260311001" } | I17: { "error": "PAYMENT_FAILED", "message": "결제에 실패했습니다" } | J17: Y | K17: SCR-032 | L17: FN-012 | M17: 개발완료 | O17: POS 결제 | P17: POS 결제 처리 | R17: 4
A18: API-017 | B18: 매출 통계 요약 | C18: GET | D18: /api/v1/sales/stats/summary | E18: 매출 통계 요약 (총매출/현금/카드/마일리지) | F18: Authorization: Bearer {token} | G18: Query: ?startDate=&endDate= | H18: { "totalSales": 15000000, "cashSales": 3000000, "cardSales": 11000000, "mileageSales": 1000000, "refundTotal": 500000 } | I18: { "error": "SERVER_ERROR", "message": "통계 조회 실패" } | J18: Y | K18: SCR-030 | L18: FN-010 | M18: 개발완료 | O18: 매출 조회 | P18: 매출 조회/통계 | R18: 7
A19: API-018 | B19: 상품 목록 조회 | C19: GET | D19: /api/v1/products | E19: 상품 목록 조회 (카테고리/상태 필터) | F19: Authorization: Bearer {token} | G19: Query: ?category=&status= | H19: { "data": [ {"id": 1, "name": "3개월 이용권", "category": "membership", "cashPrice": 280000, "cardPrice": 300000, "status": "active"} ] } | I19: { "error": "SERVER_ERROR", "message": "조회 실패" } | J19: Y | K19: SCR-040 | L19: FN-013 | M19: 개발완료 | O19: 상품 목록 | P19: 상품 목록 조회 | R19: 3
A20: API-019 | B20: 상품 등록 | C20: POST | D20: /api/v1/products | E20: 신규 상품 등록 | F20: Authorization: Bearer {token} Content-Type: application/json | G20: { "category": "membership|pt|gx|etc", "name": "string", "cashPrice": "number", "cardPrice": "number", "period": "number (days)", "kioskExposure": "boolean" } | H20: { "id": 1, "name": "3개월 이용권", "createdAt": "2026-03-11" } | I20: { "error": "DUPLICATE_NAME", "message": "동일 카테고리에 같은 상품명이 있습니다" } | J20: Y | K20: SCR-041 | L20: FN-014 | M20: 개발완료 | O20: 상품 등록 | P20: 상품 등록/수정 | R20: 4
A21: API-020 | B21: 락커 목록 조회 | C21: GET | D21: /api/v1/lockers | E21: 구역별 락커 현황 조회 | F21: Authorization: Bearer {token} | G21: Query: ?area=A | H21: { "data": [ {"id": 1, "number": "A-001", "area": "A", "status": "available", "memberId": null} ] } | I21: { "error": "SERVER_ERROR", "message": "조회 실패" } | J21: Y | K21: SCR-050 | L21: FN-015 | M21: 개발완료 | O21: 락커 현황 | P21: 락커 현황 조회 | R21: 4
A22: API-021 | B22: 락커 배정/해제 | C22: PATCH | D22: /api/v1/lockers/:id | E22: 락커 배정 또는 해제 | F22: Authorization: Bearer {token} Content-Type: application/json | G22: { "action": "assign|release", "memberId": "number", "expiryDate": "YYYY-MM-DD" } | H22: { "id": 1, "number": "A-001", "status": "occupied", "memberId": 1 } | I22: { "error": "ALREADY_ASSIGNED", "message": "이미 사용중인 락커입니다" } | J22: Y | K22: SCR-051 | L22: FN-016 | M22: 개발완료 | O22: 락커 관리 | P22: 락커 배정/관리 | R22: 4
A23: API-022 | B23: 직원 목록 조회 | C23: GET | D23: /api/v1/staff | E23: 직원 목록 조회 (역할/상태 필터) | F23: Authorization: Bearer {token} | G23: Query: ?search=&role=&status= | H23: { "data": [ {"id": 1, "name": "박트레이너", "role": "fc", "status": "active", "contact": "010-9999-8888"} ] } | I23: { "error": "FORBIDDEN", "message": "직원 조회 권한이 없습니다" } | J23: Y | K23: SCR-060 | L23: FN-019 | M23: 개발완료 | O23: 직원 목록 | P23: 직원 목록 조회 | R23: 5
A24: API-023 | B24: 직원 등록 | C24: POST | D24: /api/v1/staff | E24: 신규 직원 등록 | F24: Authorization: Bearer {token} Content-Type: application/json | G24: { "name": "string", "gender": "M|F", "contact": "string", "role": "center_manager|manager|fc|staff", "joinDate": "YYYY-MM-DD", "workType": "full|part" } | H24: { "id": 1, "name": "박트레이너", "adminId": "auto_generated_id" } | I24: { "error": "DUPLICATE_EMAIL", "message": "이미 등록된 이메일입니다" } | J24: Y | K24: SCR-061 | L24: FN-020 | M24: 개발완료 | O24: 직원 등록 | P24: 직원 등록/수정 | R24: 5
A25: API-024 | B25: 직원 수정 | C25: PUT | D25: /api/v1/staff/:id | E25: 직원 정보 수정 | F25: Authorization: Bearer {token} Content-Type: application/json | G25: { "name": "string", "contact": "string", "role": "string", "status": "active|leave|resigned" } | H25: { "id": 1, "name": "박트레이너(수정)", "updatedAt": "2026-03-11" } | I25: { "error": "NOT_FOUND", "message": "직원을 찾을 수 없습니다" } | J25: Y | K25: SCR-060 | L25: FN-020 | M25: 개발완료 | O25: 직원 목록 | P25: 직원 등록/수정 | R25: 5
A26: API-025 | B26: 직원 삭제 | C26: DELETE | D26: /api/v1/staff/:id | E26: 직원 삭제 (소프트 삭제) | F26: Authorization: Bearer {token} | H26: { "message": "직원이 삭제되었습니다" } | I26: { "error": "FORBIDDEN", "message": "삭제 권한이 없습니다" } | J26: Y | K26: SCR-060 | L26: FN-020 | M26: 개발완료 | O26: 직원 목록 | P26: 직원 등록/수정 | R26: 5
A27: API-026 | B27: 직원 출근부 조회 | C27: GET | D27: /api/v1/staff/attendance | E27: 직원 출퇴근 기록 조회 | F27: Authorization: Bearer {token} | G27: Query: ?staffId=&yearMonth=2026-03 | H27: { "data": [ {"date": "2026-03-11", "staffId": 1, "checkIn": "09:00", "checkOut": "18:00", "status": "present"} ] } | I27: { "error": "SERVER_ERROR", "message": "조회 실패" } | J27: Y | K27: SCR-062 | L27: FN-021 | M27: 개발완료 | O27: 급여 현황 | P27: 급여 관리 | R27: 3
A28: API-027 | B28: 시스템 초기화 | C28: POST | D28: /api/v1/system/reset | E28: 지점 데이터 초기화 (개발/테스트용) | F28: Authorization: Bearer {token} Content-Type: application/json | G28: { "branchId": "number", "confirmPassword": "string", "targets": ["members","sales","attendance"] } | H28: { "message": "데이터가 초기화되었습니다", "resetTargets": ["members","sales","attendance"] } | I28: { "error": "INVALID_PASSWORD", "message": "비밀번호가 올바르지 않습니다" } | J28: Y | K28: SCR-094 | L28: FN-033 | M28: 개발완료 | O28: 지점 관리 | P28: 지점 관리 | R28: 3

Sheet 데이터 정의서
A1: 테이블명 | B1: 컬럼명 | C1: 데이터 타입 | D1: 길이 | E1: NULL 허용 | F1: 기본값 | G1: PK | H1: FK | I1: 인덱스 | J1: 설명 | K1: 관련 API ID | L1: 상태 | M1: 비고
A2: tenants | B2: id | C2: BIGINT | E2: N | G2: Y | I2: Y | J2: 테넌트 고유 ID (auto increment) | K2: API-003 | L2: 확정
A3: tenants | B3: name | C3: VARCHAR | D3: 100 | E3: N | G3: N | I3: N | J3: 테넌트(본사) 이름 | K3: API-001 | L3: 확정
A4: tenants | B4: code | C4: VARCHAR | D4: 20 | E4: N | G4: N | I4: UNIQUE | J4: 테넌트 코드 (고유) | K4: API-001 | L4: 확정
A5: tenants | B5: plan | C5: ENUM | E5: N | F5: basic | G5: N | I5: N | J5: 요금제 (basic/standard/premium) | K5: API-001 | L5: 확정
A6: tenants | B6: status | C6: ENUM | E6: N | F6: active | G6: N | I6: Y | J6: 상태 (active/inactive/suspended) | K6: API-001 | L6: 확정
A7: tenants | B7: created_at | C7: DATETIME | E7: N | F7: NOW() | G7: N | I7: N | J7: 생성일시 | K7: API-001 | L7: 확정
A8: tenants | B8: updated_at | C8: DATETIME | E8: Y | F8: CURRENT_TIMESTAMP | G8: N | I8: N | J8: 수정일시 | K8: API-001 | L8: 확정
A9: branches | B9: id | C9: BIGINT | E9: N | G9: Y | I9: Y | J9: 지점 고유 ID | K9: API-027 | L9: 확정
A10: branches | B10: tenant_id | C10: BIGINT | E10: N | G10: N | H10: tenants.id | I10: Y | J10: 소속 테넌트 FK | K10: API-027, API-028, API-029 | L10: 확정
A11: branches | B11: name | C11: VARCHAR | D11: 100 | E11: N | G11: N | I11: N | J11: 지점명 | K11: API-027, API-028, API-029 | L11: 확정
A12: branches | B12: code | C12: VARCHAR | D12: 20 | E12: N | G12: N | I12: UNIQUE | J12: 지점 코드 (고유) | K12: API-027, API-028, API-029 | L12: 확정
A13: branches | B13: address | C13: VARCHAR | D13: 255 | E13: Y | G13: N | I13: N | J13: 지점 주소 | K13: API-027, API-028, API-029 | L13: 확정
A14: branches | B14: phone | C14: VARCHAR | D14: 20 | E14: Y | G14: N | I14: N | J14: 지점 연락처 | K14: API-027, API-028, API-029 | L14: 확정
A15: branches | B15: status | C15: ENUM | E15: N | F15: active | G15: N | I15: Y | J15: 상태 (active/inactive) | K15: API-027, API-028, API-029 | L15: 확정
A16: branches | B16: created_at | C16: DATETIME | E16: N | F16: NOW() | G16: N | I16: N | J16: 생성일시 | K16: API-027, API-028, API-029 | L16: 확정
A17: users | B17: id | C17: BIGINT | E17: N | G17: Y | I17: Y | J17: 사용자 고유 ID | K17: API-001 | L17: 확정
A18: users | B18: branch_id | C18: BIGINT | E18: N | G18: N | H18: branches.id | I18: Y | J18: 소속 지점 FK | K18: API-002, API-003 | L18: 확정
A19: users | B19: email | C19: VARCHAR | D19: 100 | E19: N | G19: N | I19: UNIQUE | J19: 로그인 이메일 | K19: API-002, API-003 | L19: 확정
A20: users | B20: password_hash | C20: VARCHAR | D20: 255 | E20: N | G20: N | I20: N | J20: 비밀번호 해시 | K20: API-002, API-003 | L20: 확정
A21: users | B21: name | C21: VARCHAR | D21: 50 | E21: N | G21: N | I21: Y | J21: 사용자 이름 | K21: API-002, API-003 | L21: 확정
A22: users | B22: role | C22: ENUM | E22: N | G22: N | I22: Y | J22: 역할 (super_admin/center_manager/manager/fc/staff/viewer) | K22: API-002, API-003 | L22: 확정
A23: users | B23: status | C23: ENUM | E23: N | F23: active | G23: N | I23: Y | J23: 상태 (active/inactive/locked) | K23: API-002, API-003 | L23: 확정
A24: users | B24: last_login | C24: DATETIME | E24: Y | F24: NULL | G24: N | I24: N | J24: 마지막 로그인 일시 | K24: API-002, API-003 | L24: 확정
A25: users | B25: login_fail_count | C25: INT | E25: N | F25: 0 | G25: N | I25: N | J25: 연속 로그인 실패 횟수 | K25: API-002, API-003 | L25: 확정
A26: users | B26: created_at | C26: DATETIME | E26: N | F26: NOW() | G26: N | I26: N | J26: 생성일시 | K26: API-002, API-003 | L26: 확정
A27: members | B27: id | C27: BIGINT | E27: N | G27: Y | I27: Y | J27: 회원 고유 ID | K27: API-007 | L27: 확정
A28: members | B28: branch_id | C28: BIGINT | E28: N | G28: N | H28: branches.id | I28: Y | J28: 소속 지점 FK (데이터 격리) | K28: API-004, API-005, API-006, API-007 | L28: 확정
A29: members | B29: name | C29: VARCHAR | D29: 50 | E29: N | G29: N | I29: Y | J29: 회원 이름 | K29: API-004, API-005, API-006, API-007 | L29: 확정
A30: members | B30: gender | C30: ENUM | E30: N | G30: N | I30: Y | J30: 성별 (M/F) | K30: API-004, API-005, API-006, API-007 | L30: 확정
A31: members | B31: birth_date | C31: VARCHAR | D31: 10 | E31: Y | G31: N | I31: N | J31: 생년월일 (YYYY-MM-DD) | K31: API-004, API-005, API-006, API-007 | L31: 확정
A32: members | B32: phone | C32: VARCHAR | D32: 20 | E32: N | G32: N | I32: Y | J32: 연락처 | K32: API-004, API-005, API-006, API-007 | L32: 확정 | M32: 지점 내 중복 불가
A33: members | B33: email | C33: VARCHAR | D33: 100 | E33: Y | G33: N | I33: N | J33: 이메일 | K33: API-004, API-005, API-006, API-007 | L33: 확정
A34: members | B34: address | C34: VARCHAR | D34: 255 | E34: Y | G34: N | I34: N | J34: 주소 | K34: API-004, API-005, API-006, API-007 | L34: 확정
A35: members | B35: status | C35: ENUM | E35: N | F35: active | G35: N | I35: Y | J35: 상태 (active/expired/suspended/withdrawn) | K35: API-004, API-005, API-006, API-007 | L35: 확정
A36: members | B36: manager_id | C36: BIGINT | E36: Y | F36: NULL | G36: N | H36: users.id | I36: Y | J36: 담당 FC ID | K36: API-004, API-005, API-006, API-007 | L36: 확정
A37: members | B37: attendance_no | C37: VARCHAR | D37: 20 | E37: Y | G37: N | I37: UNIQUE | J37: 출석 번호 | K37: API-004, API-005, API-006, API-007 | L37: 확정
A38: members | B38: company | C38: VARCHAR | D38: 100 | E38: Y | G38: N | I38: N | J38: 직장명 | K38: API-004, API-005, API-006, API-007 | L38: 확정
A39: members | B39: memo | C39: TEXT | E39: Y | G39: N | I39: N | J39: 관리자 메모 | K39: API-004, API-005, API-006, API-007 | L39: 확정
A40: members | B40: first_reg_date | C40: DATETIME | E40: N | F40: NOW() | G40: N | I40: N | J40: 최초 등록일 | K40: API-004, API-005, API-006, API-007 | L40: 확정
...

Sheet QA테스트케이스
A1: TC-ID | B1: 플랫폼 | C1: 테스트 영역 | D1: 하위 영역 | E1: 테스트 유형 | F1: 테스트 시나리오 | G1: 사전 조건 | H1: 테스트 절차 | I1: 기대 결과 | J1: 실제 결과 | K1: 테스트 상태 | L1: 우선순위 | M1: 심각도 | N1: 담당자 | O1: 테스트 환경 | P1: 브라우저/앱 | Q1: 디바이스 | R1: OS | S1: 테스트 사이클 | T1: 자동화 여부 | U1: 화면 ID | V1: 기능 ID | W1: API ID | X1: 버그 티켓 | Y1: 스크린샷 | Z1: [자동] 화면명 | AA1: [자동] 기능명 | AB1: [자동] API 엔드포인트 | AC1: 비고
A2: TC-001 | B2: Web | C2: 인증 | D2: 로그인 | E2: 기능 테스트 | F2: 정상 로그인 - 올바른 이메일/비밀번호로 로그인 | G2: 등록된 계정 존재, 활성 상태 | H2: 1) 로그인 페이지 접속 2) 이메일 입력 3) 비밀번호 입력 4) 지점 선택 5) 로그인 버튼 클릭 | I2: 대시보드(SCR-002)로 이동, JWT 토큰 저장, 사용자 정보 표시 | K2: 미실행 | L2: Critical | M2: Critical | N2: QA담당자1 | O2: Staging | P2: Chrome | Q2: Desktop | R2: Windows 11 | S2: 1차 | T2: 수동 | U2: SCR-001 | V2: FN-001 | W2: API-001 | Z2: 로그인 | AA2: 로그인 | AB2: /api/v1/auth/login
A3: TC-002 | B3: Web | C3: 인증 | D3: 로그인 | E3: 기능 테스트 | F3: 로그인 실패 - 잘못된 비밀번호 | G3: 등록된 계정 존재 | H3: 1) 로그인 페이지 접속 2) 올바른 이메일 입력 3) 잘못된 비밀번호 입력 4) 로그인 버튼 클릭 | I3: '비밀번호가 올바르지 않습니다' 에러 메시지 표시, 로그인 실패 횟수 +1 | K3: 미실행 | L3: Critical | M3: Critical | N3: QA담당자1 | O3: Staging | P3: Chrome | Q3: Desktop | R3: Windows 11 | S3: 1차 | T3: 수동 | U3: SCR-001 | V3: FN-001 | W3: API-001 | Z3: 로그인 | AA3: 로그인 | AB3: /api/v1/auth/login
A4: TC-003 | B4: Web | C4: 인증 | D4: 로그인 | E4: 기능 테스트 | F4: 계정 잠금 - 5회 연속 실패 | G4: 등록된 계정 존재, 실패 횟수 4회 | H4: 1) 잘못된 비밀번호로 5번째 로그인 시도 | I4: '5회 실패로 계정이 잠겼습니다. 30분 후 다시 시도하세요' 메시지 표시 | K4: 미실행 | L4: Critical | M4: Blocker | N4: QA담당자1 | O4: Staging | P4: Chrome | Q4: Desktop | R4: Windows 11 | S4: 1차 | T4: 수동 | U4: SCR-001 | V4: FN-001 | W4: API-001 | Z4: 로그인 | AA4: 로그인 | AB4: /api/v1/auth/login
A5: TC-004 | B5: Web | C5: 인증 | D5: 로그인 | E5: UI/UX 테스트 | F5: 비밀번호 마스킹 토글 | G5: 로그인 페이지 접속 | H5: 1) 비밀번호 입력 2) 눈 아이콘 클릭 3) 비밀번호 표시 확인 4) 다시 클릭하여 마스킹 | I5: 토글에 따라 비밀번호 표시/마스킹 전환 | K5: 미실행 | L5: Medium | M5: Minor | N5: QA담당자1 | O5: Staging | P5: Chrome | Q5: Desktop | R5: Windows 11 | S5: 1차 | T5: 수동 | U5: SCR-001 | V5: FN-001 | Z5: 로그인 | AA5: 로그인
A6: TC-005 | B6: Web | C6: 대시보드 | D6: 통계 | E6: 기능 테스트 | F6: 대시보드 KPI 카드 정확성 | G6: 로그인 완료, 테스트 데이터 존재 | H6: 1) 대시보드 접속 2) 총회원/활성/만료임박/만료 카드 수치 확인 3) DB 데이터와 대조 | I6: 카드 수치가 DB 실제 데이터와 일치 | K6: 미실행 | L6: Critical | M6: Critical | N6: QA담당자1 | O6: Staging | P6: Chrome | Q6: Desktop | R6: Windows 11 | S6: 1차 | T6: 자동화 예정 | U6: SCR-002 | V6: FN-002 | W6: API-003 | Z6: 대시보드 | AA6: 대시보드 통계 조회 | AB6: /api/v1/dashboard/stats
