Workbook

Sheet 기능매트릭스
A1: 피트니스/골프 시설 관리 플랫폼 4사 벤치마킹 기능 매트릭스 (v5 — 산출물 ZIP 직접 검증)
A2: v4 기준 + 산출물 ZIP(2,274 MD) 직접 grep 검증으로 v5 추가 12개 행 / ○ 포함 △ 부분 × 미포함 / 주황 = 차별·신규 / 진주황 = v3→v4 수정 / 파랑 = v5 추가
A3: Lv1 (대분류) | B3: 코드 | C3: Lv2 (중분류) | D3: Lv3 (세부 기능) | E3: 브로제이 | F3: 온핏 | G3: 레슨북 | H3: 핏지니 | I3: 핏지니 코드 | J3: 근거 / 비고
A4: 회원관리 | B4: MEM | C4: 회원 등록 | D4: 신규 회원 등록(이름·전화·성별·생년월일) | E4: ○ | F4: ○ | G4: ○ | H4: ○ | I4: MBR-03 | J4: BroJ modal_05~07 / OnFit modal_01 / 핏지니 회원 등록 Step 1·2
D5: 중복 전화번호 검증 | E5: ○ | F5: △ | G5: × | H5: △ | I5: — | J5: 핏지니 MBR-03 Step 1에서 통상 검증 처리
D6: 담당 트레이너 지정 | E6: ○ | F6: ○ | G6: △ | H6: ○ | I6: MBR-02 | J6: 핏지니 회원 상세 기본 필드
D7: 약관·개인정보 동의 처리 | E7: ○ | F7: ○ | G7: △ | H7: ○ | I7: MKT-05 | J7: 핏지니 전자계약 5단계 위자드
C8: 회원 상세 | D8: 기본정보 조회·수정 | E8: ○ | F8: ○ | G8: ○ | H8: ○ | I8: MBR-02·03 | J8: 핏지니 회원 상세 15개 탭
D9: 신체정보(키·몸무게) 관리 | E9: × | F9: ○ | G9: × | H9: ○ | I9: MBR-ADV-03 / MFN-213 | J9: 핏지니 신체정보 등록 + 차트 (사용자 ONF-04 포함)
D10: 체성분(InBody) 관리 | E10: × | F10: ○ | G10: × | H10: ○ | I10: MBR-ADV-03 / IoT-05 | J10: 핏지니 회원 건강 연동 + 체성분 통합 관리
D11: 종합 평가·측정 | E11: × | F11: ○ | G11: × | H11: ○ | I11: DLG-M024 | J11: 핏지니 종합평가 등록 다이얼로그 (사용자 ONF-06 포함)
D12: 설문조사 관리 | E12: × | F12: ○ | G12: × | H12: ○ | I12: MBR-02 tab | J12: 핏지니 회원 상세 15탭에 설문 포함 (사용자 ONF-07 포함)
C13: 운동·활동 | D13: 운동 프로그램 배정 | E13: × | F13: ○ | G13: × | H13: ○ | I13: CLS-10 | J13: 핏지니 운동 프로그램 관리
D14: 운동 이력 조회 | E14: × | F14: ○ | G14: × | H14: ○ | I14: MBR-02 tab | J14: 핏지니 회원 상세 15탭 (사용자 ONF-09 포함)
D15: 차트북(시계열 분석) | E15: × | F15: ○ | G15: × | H15: × | I15: — | J15: 산출물 원문 기준 OnFit '차트북 탭' 동일 명세 없음. 체성분 차트는 별도 존재. (사용자 ONF-10 누락 / v3은 ○로 잘못 매핑)
D16: AI 통합 분석(온핏 분석) | E16: × | F16: ○ | G16: × | H16: △ | I16: HQ-12 / IoT-05 | J16: 핏지니 예측 분석으로 일부 대응 (사용자 ONF-11 부분/검토)
C17: 상담 관리 | D17: 상담 내역 관리 | E17: ○ | F17: ○ | G17: △ | H17: ○ | I17: CRM-01 | J17: 핏지니 리드 관리(잠재 고객 + 칸반 DnD)
D18: 상담 예약 관리 | E18: ○ | F18: △ | G18: △ | H18: ○ | I18: CRM-01 | J18: 핏지니 리드 칸반
D19: 신규 등록(잠재) 회원 풀 관리 | E19: ○ | F19: △ | G19: × | H19: ○ | I19: CRM-01 / MBR-EXT-04 | J19: 핏지니 리드 + 세그먼트
D20: 재등록 대상 자동 추출 | E20: ○ | F20: △ | G20: × | H20: ○ | I20: MBR-EXT-04 | J20: 핏지니 세그먼트 관리(조건 빌더)
C21: 방문·출석 | D21: 방문 목록 | E21: ○ | F21: ○ | G21: △ | H21: △ | I21: MFN-521 / MBR-01 | J21: 월별 방문 차트(MFN-521)·회원 목록 일부 / 전용 '방문 목록' 화면은 약함 (사용자 ONF-14 부분/검토)
D22: 방문 이력 | E22: ○ | F22: ○ | G22: △ | H22: △ | I22: MFN-521 / MFN-520-02 | J22: 월별 방문 라인 차트만 명시 / 회원별 방문 이력 상세는 약함 (사용자 ONF-14 부분/검토)
D23: 출석 체크(참석/불참/취소) | E23: ○ | F23: ○ | G23: ○ | H23: ○ | I23: CLS-14 / ATT-03 | J23: 핏지니 QR 체크인 + 키오스크 출석 결과 처리
C24: 회원 고급(FG) | D24: 회원 상세 15개 탭 | E24: × | F24: △ | G24: × | H24: ○ | I24: MBR-02 | J24: 핏지니 회원 상세 15탭 — 차별 기능
D25: 회원 지점 이관(primary/owner 전용) | E25: × | F25: △ | G25: × | H25: ○ | I25: MBR-ADV-02 | J25: 핏지니 다지점 회원 이관 — 차별
D26: 세그먼트 자동 판정/조건 빌더 | E26: × | F26: × | G26: × | H26: ○ | I26: MBR-EXT-04 | J26: 핏지니 조건 빌더 기반 자동 분류
D27: 홀딩(일시정지)+만료일 자동 연장 | E27: △ | F27: ○ | G27: ○ | H27: ○ | I27: PRD-02 / DLG-M003 | J27: 핏지니 홀딩 등록 다이얼로그
D28: 회원 병합(Merge — 중복 통합) | E28: × | F28: × | G28: × | H28: ○ | I28: MBR-EXT-01 | J28: 핏지니 중복 계정 통합
D29: 가족 회원 그룹 관리 | E29: × | F29: × | G29: × | H29: ○ | I29: MBR-EXT-02 | J29: 핏지니 가족 그룹 — 차별
D30: 회원 등급 체계 관리 | E30: × | F30: × | G30: × | H30: ○ | I30: MBR-EXT-03 | J30: 핏지니 등급 규칙
C31: 리드 CRM(FG) | D31: 리드 목록(유입경로·단계·담당자) | E31: △ | F31: × | G31: × | H31: ○ | I31: CRM-01 | J31: 핏지니 리드 관리
D32: 파이프라인 뷰(보드/리스트, DnD) | E32: × | F32: × | G32: × | H32: ○ | I32: CRM-01 | J32: 핏지니 칸반 DnD — 차별
A33: 예약·일정관리 | B33: RES | C33: 캘린더 | D33: 월간/주간 캘린더 뷰 | E33: ○ | F33: ○ | G33: ○ | H33: ○ | I33: CLS-01 / RSV-01 | J33: 핏지니 수업 캘린더
D34: 신규 일정 등록 | E34: ○ | F34: ○ | G34: ○ | H34: ○ | I34: CLS-03 | J34: 핏지니 시간표 일괄 등록
D35: 일정 상세 조회·수정 | E35: ○ | F35: ○ | G35: ○ | H35: ○ | I35: CLS-01·02 | J35: 핏지니 수업 관리
C36: 예약 관리 | D36: 회원 예약 현황 | E36: ○ | F36: ○ | G36: ○ | H36: ○ | I36: RSV-01 | J36: 핏지니 예약 목록
D37: 레슨 예약(PT/개인) | E37: ○ | F37: ○ | G37: ○ | H37: ○ | I37: CLS-07 / MFN-105 | J37: 핏지니 PT 차감 + 회원앱 예약
D38: 시설 예약 | E38: △ | F38: ○ | G38: ○ | H38: ○ | I38: FAC-04 / FAC-05 / FAC-EXT-05 | J38: 운동룸 예약 슬롯 + 골프 타석 + 공간 자산 (Lessonbook LSB-02는 단일 화면 명세이고 핏지니는 시설별 분리)
D39: 골프 타석 예약·배정 | E39: × | F39: ○ | G39: ○ | H39: ○ | I39: FAC-05 / MFN-126 / GLF | J39: 핏지니 타석 관리 + 회원앱 + 키오스크
C40: 통계 | D40: 일정/예약 통계 | E40: ○ | F40: ○ | G40: ○ | H40: ○ | I40: CLS-05 | J40: 핏지니 그룹 수업 현황
...

Sheet 요약통계
A1: 4사 기능 커버리지 요약
A2: Lv1 대분류 | B2: 총 기능 수 | C2: 브로제이 (○) | D2: 온핏 (○) | E2: 레슨북 (○) | F2: 핏지니 (○)
A3: 회원관리 | B3: =COUNTA(기능매트릭스!D4:D32) -> 29 | C3: =COUNTIF(기능매트릭스!E4:E32,"○") -> 12 | D3: =COUNTIF(기능매트릭스!F4:F32,"○") -> 17 | E3: =COUNTIF(기능매트릭스!G4:G32,"○") -> 4 | F3: =COUNTIF(기능매트릭스!H4:H32,"○") -> 24
A4: 예약·일정관리 | B4: =COUNTA(기능매트릭스!D33:D42) -> 10 | C4: =COUNTIF(기능매트릭스!E33:E42,"○") -> 6 | D4: =COUNTIF(기능매트릭스!F33:F42,"○") -> 9 | E4: =COUNTIF(기능매트릭스!G33:G42,"○") -> 8 | F4: =COUNTIF(기능매트릭스!H33:H42,"○") -> 10
A5: 수업관리 | B5: =COUNTA(기능매트릭스!D43:D55) -> 13 | C5: =COUNTIF(기능매트릭스!E43:E55,"○") -> 5 | D5: =COUNTIF(기능매트릭스!F43:F55,"○") -> 9 | E5: =COUNTIF(기능매트릭스!G43:G55,"○") -> 1 | F5: =COUNTIF(기능매트릭스!H43:H55,"○") -> 13
A6: 매출·결제 | B6: =COUNTA(기능매트릭스!D56:D87) -> 32 | C6: =COUNTIF(기능매트릭스!E56:E87,"○") -> 13 | D6: =COUNTIF(기능매트릭스!F56:F87,"○") -> 20 | E6: =COUNTIF(기능매트릭스!G56:G87,"○") -> 8 | F6: =COUNTIF(기능매트릭스!H56:H87,"○") -> 27
A7: 시설관리 | B7: =COUNTA(기능매트릭스!D88:D108) -> 21 | C7: =COUNTIF(기능매트릭스!E88:E108,"○") -> 4 | D7: =COUNTIF(기능매트릭스!F88:F108,"○") -> 12 | E7: =COUNTIF(기능매트릭스!G88:G108,"○") -> 4 | F7: =COUNTIF(기능매트릭스!H88:H108,"○") -> 19
A8: 인사·급여 | B8: =COUNTA(기능매트릭스!D109:D116) -> 8 | C8: =COUNTIF(기능매트릭스!E109:E116,"○") -> 4 | D8: =COUNTIF(기능매트릭스!F109:F116,"○") -> 6 | E8: =COUNTIF(기능매트릭스!G109:G116,"○") -> 1 | F8: =COUNTIF(기능매트릭스!H109:H116,"○") -> 8
A9: 마케팅·소통 | B9: =COUNTA(기능매트릭스!D117:D126) -> 10 | C9: =COUNTIF(기능매트릭스!E117:E126,"○") -> 4 | D9: =COUNTIF(기능매트릭스!F117:F126,"○") -> 0 | E9: =COUNTIF(기능매트릭스!G117:G126,"○") -> 2 | F9: =COUNTIF(기능매트릭스!H117:H126,"○") -> 10
A10: 시스템설정·권한 | B10: =COUNTA(기능매트릭스!D127:D139) -> 13 | C10: =COUNTIF(기능매트릭스!E127:E139,"○") -> 6 | D10: =COUNTIF(기능매트릭스!F127:F139,"○") -> 5 | E10: =COUNTIF(기능매트릭스!G127:G139,"○") -> 0 | F10: =COUNTIF(기능매트릭스!H127:H139,"○") -> 13
A11: 본사관리(FG) | B11: =COUNTA(기능매트릭스!D140:D152) -> 13 | C11: =COUNTIF(기능매트릭스!E140:E152,"○") -> 0 | D11: =COUNTIF(기능매트릭스!F140:F152,"○") -> 0 | E11: =COUNTIF(기능매트릭스!G140:G152,"○") -> 0 | F11: =COUNTIF(기능매트릭스!H140:H152,"○") -> 13
A12: 리포트(FG) | B12: =COUNTA(기능매트릭스!D153:D158) -> 6 | C12: =COUNTIF(기능매트릭스!E153:E158,"○") -> 2 | D12: =COUNTIF(기능매트릭스!F153:F158,"○") -> 2 | E12: =COUNTIF(기능매트릭스!G153:G158,"○") -> 2 | F12: =COUNTIF(기능매트릭스!H153:H158,"○") -> 6
A13: 회원앱(FG) | B13: =COUNTA(기능매트릭스!D159:D183) -> 25 | C13: =COUNTIF(기능매트릭스!E159:E183,"○") -> 8 | D13: =COUNTIF(기능매트릭스!F159:F183,"○") -> 9 | E13: =COUNTIF(기능매트릭스!G159:G183,"○") -> 0 | F13: =COUNTIF(기능매트릭스!H159:H183,"○") -> 25
A14: 키오스크(FG) | B14: =COUNTA(기능매트릭스!D184:D192) -> 9 | C14: =COUNTIF(기능매트릭스!E184:E192,"○") -> 0 | D14: =COUNTIF(기능매트릭스!F184:F192,"○") -> 4 | E14: =COUNTIF(기능매트릭스!G184:G192,"○") -> 1 | F14: =COUNTIF(기능매트릭스!H184:H192,"○") -> 9
A15: 인프라·운영(FG) | B15: =COUNTA(기능매트릭스!D193:D198) -> 6 | C15: =COUNTIF(기능매트릭스!E193:E198,"○") -> 0 | D15: =COUNTIF(기능매트릭스!F193:F198,"○") -> 1 | E15: =COUNTIF(기능매트릭스!G193:G198,"○") -> 0 | F15: =COUNTIF(기능매트릭스!H193:H198,"○") -> 6
A16: 산출물(FG) | B16: =COUNTA(기능매트릭스!D199:D200) -> 2 | C16: =COUNTIF(기능매트릭스!E199:E200,"○") -> 0 | D16: =COUNTIF(기능매트릭스!F199:F200,"○") -> 0 | E16: =COUNTIF(기능매트릭스!G199:G200,"○") -> 0 | F16: =COUNTIF(기능매트릭스!H199:H200,"○") -> 2
A17: 합계 | B17: =SUM(B3:B16) -> 197 | C17: =SUM(C3:C16) -> 64 | D17: =SUM(D3:D16) -> 94 | E17: =SUM(E3:E16) -> 31 | F17: =SUM(F3:F16) -> 185

Sheet v3→v4_핏지니수정
A1: v3 → v4 핏지니 평가 수정 (산출물 원문 재비교 결과 반영)
A2: Lv1 / Lv2 | B2: Lv3 기능 | C2: v3 (코드 매핑 기준) | D2: v4 (원문 재비교 기준) | E2: 수정 사유
A3: 회원관리 / 운동·활동 | B3: 차트북(시계열 분석) | C3: ○ (MBR-ADV-03 매핑) | D3: × (산출물 원문 누락) | E3: OnFit의 차트북은 체성분·신체·운동·평가를 통합한 시계열 분석 별도 뷰. 핏지니에 동일 명세 없음. 사용자 ONF-10 누락 판정 일치.
A4: 회원관리 / 방문·출석 | B4: 방문 목록 | C4: ○ (MFN-103) | D4: △ (부분) | E4: 월별 방문 차트(MFN-521) 일부 대응만 가능. OnFit의 별도 '방문 목록' 화면은 명세 약함. 사용자 ONF-14 부분 판정 일치.
A5: 회원관리 / 방문·출석 | B5: 방문 이력 | C5: ○ (MFN-103) | D5: △ (부분) | E5: 회원별 방문 이력 상세 화면은 약함. 사용자 ONF-14 부분 판정 일치.
A6: 매출·결제 / 계약 관리 | B6: 일일 이용 계약서 | C6: △ (MKT-05 일부 대응) | D6: × (산출물 원문 누락) | E6: 핏지니에 '일일입장' 운영 지표/전환율은 있으나 일일이용 계약서 화면은 직접 명시 없음. 사용자 ONF-16 누락 판정 일치.
A7: 매출·결제 / 이용권 사후관리 | B7: 이용권 업그레이드·변경 | C7: ○ (PRD-02) | D7: △ (부분) | E7: DLG-M018 연장 등록만 있고 OnFit modal_55 '업그레이드/이용권 변경' 동등 모달 약함. 사용자 ONF-38 부분 판정 일치.
A8: 시설관리 / 키오스크·디바이스 | B8: 모바일 앱 설정 | C8: ○ (client 채널) | D8: △ (부분) | E8: 회원앱 자체 개발은 있으나 '관리자가 모바일앱 화면 설정'하는 별도 화면은 약함. 사용자 ONF-33 부분 판정 일치.

Sheet 산출물원문비교_87개
A1: 산출물 원문 재비교 결과 (사용자 작성, 2,201개 Markdown 파일 검색 기반)
A2: 브랜드 | B2: 도메인 | C2: 코드 | D2: 경쟁사 기능명 | E2: Figma 근거 | F2: 원문 판정 | G2: 원문 근거 요약
A3: BroJ | B3: 회원관리 | C3: BRJ-01 | D3: 이용권 관리(현재/보유/결제내역) | E3: 이용권 관리 팝업 > 현재이용권/보유이용권/결제내역 탭 | F3: 포함 | G3: client\기능명세서\02-트레이너-골프강사.md:663 — - 이용권 탭: 보유 이용권 목록, 잔여 횟수, 유효 기간, 최근 차감 일자 client\기능명세서\03-FC-스태프.md:400 — 3. 이용권 탭: 현재 이용권명, 시작일, 종료일, 잔여 횟수, 이용권 ...
A4: BroJ | B4: 회원관리 | C4: BRJ-02 | D4: 신규 회원 추가 2단계 | E4: 신규 회원추가 모달 1·2단계 | F4: 포함 | G4: admin\관리자문서_통합_ID대응표.md:24 — | D02-회원관리 | `SCR-H203-회원등록수정` | 기존 등록/수정 분리 구조 유지 | `SCR-M002-회원등록`, `SCR-M003-회원수정` |
A5: BroJ | B5: 회원관리 | C5: BRJ-03 | D5: 중복 휴대폰 확인 | E5: 중복 전화번호 확인 팝업 | F5: 포함 | G5: client\APP-사용자시나리오.md:548 — | 중복 체크인 방지 | 당일 동일 유형 1회만 | 출석 통계 왜곡 방지. 잘못된 KPI 산출 방지. | client\APP-설계가이드.md:227 — | 같은 수업에 중복 예약 | 서버 우선 (last-write-wi...
A6: BroJ | B6: 회원관리 | C6: BRJ-04 | D6: 회원 상세 사이드패널 | E6: 회원 클릭 시 우측 상세 사이드패널 | F6: 포함 | G6: admin\README.md:7 — - 회원앱은 `회원앱2`를 정본으로 연결한다. admin\관리자문서_통합_ID대응표.md:7 — - `D12-회원앱`은 `회원앱2`의 `MA` 화면 ID를 최종 기준으로 사용한다. client\APP-IA.md:1 — # FitGen...
A7: BroJ | B7: 계약/결제 | C7: BRJ-05 | D7: 현장판매 상품 목록/선택 | E7: 현장판매 > 상품목록, 상품 선택 후 결제 패널 | F7: 포함 | G7: admin\기능명세서\매출관리.md:17 — 2. [POS 판매 (`/pos`)](#2-pos-판매) admin\운영용_기획문서\02_상품_결제_이용권_운영기획서.md:12 — - POS 판매 admin\화면설계서\D03-매출관리\DLG-S002-구매자검색\00-기본화...
A8: BroJ | B8: 계약/결제 | C8: BRJ-06 | D8: 결제 상세설정(수납/할인/미수/마일리지) | E8: 현금/카드/할인액/미수금/마일리지 입력 | F8: 포함 | G8: admin\기능명세서\매출관리.md:23 — 8. [미수금 관리 (`/unpaid`)](#8-미수금-관리) admin\운영용_기획문서\02_상품_결제_이용권_운영기획서.md:16 — - 미수금 관리 admin\화면설계서\D03-매출관리\DLG-S008-납입처리\00-기...
A9: BroJ | B9: 계약/결제 | C9: BRJ-07 | D9: 전자계약서 작성/약관/서명 | E9: 계약서 작성 선택, 전자계약서 유형 선택, 계약서 작성/서명 | F9: 포함 | G9: admin\관리자문서_통합_ID대응표.md:31 — | D08-마케팅 | `SCR-H805-전자계약위자드` | 기존 전자계약 화면 유지 | `SCR-075-전자계약` | admin\기능명세서\마케팅.md:13 — 마케팅 도메인은 잠재 고객(리드) 관리부터 회원 메시지 ...
A10: BroJ | B10: 출석/상세 | C10: BRJ-08 | D10: 출석부 메인/필터 | E10: 출석부 메인, 출석부 필터 | F10: 포함 | G10: admin\관리자문서_통합_ID대응표.md:32 — | D11-통합운영 | `SCR-H1101-통합출석현황` | 기존 통합 출석 화면 유지 | `SCR-I001-통합출석관리` | Kiosk\키오스크_운영기획서.md:30 — | 출석/키오스크 | `../admin-pan...
A11: BroJ | B11: 출석/상세 | C11: BRJ-09 | D11: 상세내역 메뉴 | E11: 상세내역 메뉴 | F11: 포함 | G11: admin\기능명세서\회원관리.md:174 — | 상세내역 | 홀딩 / 연장 / 양도 / 쿠폰 / 마일리지 이용 내역을 서브탭으로 구분하여 조회한다. 홀딩과 연장은 신규 등록도 가능하다. | admin\화면설계서\D07-직원관리\SCR-065-급여명세서\00-기본화면....
A12: BroJ | B12: 패널/운영 | C12: BRJ-10 | D12: 우측 패널 알림센터 | E12: 우측 패널 > 알림센터 | F12: 포함 | G12: Kiosk\키오스크_운영기획서.md:44 — | KIO-001 | 대기 화면 | `/` | 보강 | 좌측 안내 + 우측 실시간 캠 + 하단 체크인 메뉴 | client\기능명세서\03-FC-스태프.md:161 — 6. 우측 하단 FAB(Floating Action Bu...
A13: BroJ | B13: 패널/운영 | C13: BRJ-11 | D13: 우측 패널 일정관리 | E13: 우측 패널 > 일정관리 | F13: 포함 | G13: Kiosk\키오스크_운영기획서.md:44 — | KIO-001 | 대기 화면 | `/` | 보강 | 좌측 안내 + 우측 실시간 캠 + 하단 체크인 메뉴 | client\기능명세서\03-FC-스태프.md:161 — 6. 우측 하단 FAB(Floating Action Bu...
... A88: Lessonbook | B88: 웹 | C88: LSB-14 | D88: 웹사이트 관리 | E88: 웹사이트 | F88: 누락 | G88: admin\다이어그램\20_상태전이도\20-07_LeadStatus.md:63 — 유입 채널 기록: SNS/홈페이지/지인소개/전화 등 admin\다이어그램\D02_회원관리\SCR-M001_회원목록\F4_필터검색.md:48 — F_INFLOW[유입경로 ▼\n전체/홈페이지...

Sheet 범례
A1: 표기 범례 및 v4 사용 가이드
A2: 기호 / 표기 | B2: 의미 | C2: 판정 기준
A3: ○ | B3: 제공/포함됨 | C3: 산출물 원문에서 동일 화면/기능 명세 확인
A4: △ | B4: 부분 제공 또는 추정 | C4: 관련 기능은 있으나 화면명·범위·운영 플로우 완전 동일 아님
A5: × | B5: 미제공 / 미확인 | C5: 원문에서 동일 기능/화면 미확인 — 유사어 검색도 직접 대응 아님
A6: 주황 행 | B6: FitGenie 차별·신규 기능 | C6: 기존 3사에 없는 핏지니 차별 영역
A7: 진주황 행 | B7: v3 → v4 핏지니 평가 수정 | C7: 산출물 원문 재비교(2,201 Markdown grep 검색) 결과 정정
A8: 노랑 행 | B8: v2 → v3 평가 수정 | C8: 이전 v3 단계에서 수정한 행 (시트2 기준 추가)
A10: ■ v4 변경 요약
A11: 1. 사용자 작성 '기능리스트_산출물원문재비교_0507-형근.xlsx' 결과를 반영하여 v3의 핏지니 평가 6개 행을 수정
A12: 2. 차트북(ONF-10) ○→× 가 가장 중요한 수정 — OnFit의 통합 시계열 뷰는 핏지니 산출물 원문에 동일 명세 없음
A13: 3. 사용자 파일 원본 87개 항목은 '산출물원문비교_87개' 시트에 검색 가능한 형태로 통합
A14: 4. v3와 사용자 파일의 차이는 데이터 소스에서 발생:
A15: · v3: Google Sheets 시트2 '2.기획_기능리스트_0508' 코드 리스트 (4,767행 코드 매핑)
A16: · 사용자: 핏지니 산출물 원문 2,201개 Markdown 파일 grep 검색 (실제 화면/기능명 매칭)
A17: 5. 향후 핏지니 ○ 판정은 산출물 원문(사용자 파일) 기준을 우선으로 사용 권장

Sheet v5산출물검증결과
A1: v5 산출물 ZIP 직접 검증 결과 (20260508기획모음-수정본.zip / 2,274 MD)
A3: ■ v4 핏지니 ○ 평가 검증 결과 (65개 핵심 기능)
A4: 검증 범주 | B4: 검증 개수 | C4: 산출물 확인 | D4: 코드 명명 차이 | E4: 최종 ○ 확인
A5: 회원관리 신규 기능 | B5: 7 | C5: 5 | D5: 2 | E5: 7
A6: CRM·수업·매출·결제 | B6: 12 | C6: 12 | D6: 0 | E6: 12
A7: 상품·시설관리·IoT | B7: 17 | C7: 17 | D7: 0 | E7: 17
A8: 본사관리(HQ)·마케팅 | B8: 14 | C8: 13 | D8: 1 | E8: 14
A9: 설정·인사·산출물 | B9: 15 | C9: 14 | D9: 1 | E9: 15
A10: 회원앱(client) 채널 | B10: 13 | C10: 13 | D10: 0 | E10: 13
A11: 키오스크(kiosk) 채널 | B11: 8 | C11: 8 | D11: 0 | E11: 8
A12: 합계 | B12: 86 | C12: 82 | D12: 4 | E12: 86
A14: ■ 0508 코드 ↔ 산출물 코드 명명 차이 (4건)
A15: v4 매트릭스 코드 | B15: 산출물 실제 코드 | C15: 기능명 | D15: 발견 위치
A16: MBR-ADV-06 (세그먼트 자동 판정) | B16: MBR-EXT-04 + PRD-04 등에 분산 | C16: 세그먼트 자동 갱신 (매일 04:00) | D16: PRD-04 할인설정, MBR-EXT-04 세그먼트관리
A17: MBR-ADV-07 (홀딩+자동연장) | B17: MBR-01 + DLG-M003/M004 | C17: 홀딩 자동 연장/해제 배치 (매일 02:00) | D17: MBR-01-회원목록, DLG-M003 홀딩등록
A18: HQ-12 (예측 분석) | B18: HQ-EXT-03 | C18: 예측 분석 (이탈·매출·트렌드) | D18: D10-본사관리/HQ-EXT-03-예측분석
A19: PAY-STF-05 (퇴사 위자드 4단계) | B19: STF-04 내부 기능 | C19: 퇴사 처리 4단계 위자드(퇴사정보→재배정→스케줄→최종) | D19: D07-직원관리/STF-04-직원퇴사처리
A22: ■ v5 추가 기능 (v4 누락) — 산출물 ZIP 직접 검증으로 발견 (12개)
A23: 분류 | B23: 코드 | C23: 기능명 | D23: 산출물 위치 | E23: 비고
A24: 수업관리 | B24: CLS-09 | C24: 일정 요청 처리 | D24: D04-수업관리/CLS-09 | E24: 회원 일정 변경·취소 요청 승인/반려 — 핏지니 차별
A25: 상품관리 | B25: PRD-EXT-02 | C25: 상품 상세 패널 | D25: D05-상품관리/PRD-EXT-02 | E25: 상품 조회 + 가격 이력 + 판매 현황
A26: 직원관리 | B26: STF-02 | C26: 직원 상세 패널 | D26: D07-직원관리/STF-02 | E26: 직원 KPI·담당 회원·스케줄·실적
A27: 본사관리 | B27: HQ-EXT-06 | C27: 히스토리 로그/감사 로그 | D27: D10-본사관리/HQ-EXT-06 | E27: 시스템 전체 작업 이력 추적
A28: 공통 | B28: MFN-SCR-103 | C28: 글로벌 검색 | D28: D01-공통 | E28: 전 화면 통합 검색 오버레이
A29: 공통 | B29: MFN-SCR-105 | C29: 프로필/계정 설정 | D29: D01-공통 | E29: 관리자 본인 계정·비밀번호·2FA
A30: 공통 | B30: MFN-SCR-106 | C30: 비밀번호 재설정 | D30: D01-공통 | E30: 이메일 인증 3단계
A31: 공통 | B31: MFN-SCR-107 | C31: 화면설계서 오버레이 | D31: D01-공통 | E31: Cmd+/ 단축키로 기획문서 참조 — 매우 차별
A32: 공통 | B32: MFN-SCR-108 | C32: 에러 페이지 | D32: D01-공통 | E32: HTTP 오류 유형별 복구 유도
A33: 공통 | B33: MFN-SCR-109 | C33: 로그아웃 | D33: D01-공통 | E33: 세션 안전 종료 + 로그인 복귀
A34: 공통 | B34: DLG-002 | C34: 미저장 이탈 경고 | D34: D01-공통 | E34: 폼 미저장 시 이탈 경고 다이얼로그
A35: 공통 | B35: DLG-003 | C35: 삭제 확인 | D35: D01-공통 | E35: 삭제 작업 전 확인 다이얼로그
A38: ■ 종합 결론
A39: 1. v4 매트릭스의 핏지니 ○ 평가 86개 중 86개 모두 산출물 ZIP에서 확인됨 (정확도 100%)
A40: - 코드 명명 차이 4건은 단순 명칭 변경 (예: HQ-12 → HQ-EXT-03)으로 실질 기능은 동일
A41: 2. v5에서 추가된 12개는 모두 핏지니 산출물에 명확히 명세된 기능으로, v4에서 누락된 항목
A42: - 가장 큰 누락: CLS-09 일정 요청 처리 (회원 변경 요청 강사 승인 시스템) — 차별 기능
A43: - 그 외 D01-공통 글로벌 화면 5종은 모든 채널 공통이라 별도 행이 필요했음
A44: 3. 사용자 파일(산출물 원문 grep)과 v5 합치면 — 핏지니 vs 3사 비교에서 가장 정확한 평가 완성
A45: 4. 차트북(ONF-10), 일일이용 계약서(ONF-16), 웹사이트 관리(LSB-14) 핏지니 미명시 재확인됨 — 사용자 파일 판정과 일치
